Workbook

Sheet Reliance Industries
A1: Date | B1: Daily Closing Price | C1: Daily Return | D1: Total Return | F1: 20 SMA | G1: 50 SMA | H1: 200 SMA | I1: Stand Dev
A2: 44221 | B2: 880.11005 | C2: =(Table5[[#This Row],[Daily Closing Price]]-B1)/B1*100 -> #VALUE! | D2: =(B1240-B2)/B1240 -> 0.36504577 | I2: =STDEV(C3:C1240)% -> 0.014213704
A3: 44223 | B3: 859.25226 | C3: =(Table5[[#This Row],[Daily Closing Price]]-B2)/B2*100 -> -2.3699068 | D3: CAGR | F3: Ann Stand Dev
A4: 44224 | B4: 850.88647 | C4: =(Table5[[#This Row],[Daily Closing Price]]-B3)/B3*100 -> -0.97361207 | D4: =(B1240/B2)^(1/5)-1 -> 0.095094293 | F4: =I2*SQRT(252) -> 0.22563555
A5: 44225 | B5: 835.19769 | C5: =(Table5[[#This Row],[Daily Closing Price]]-B4)/B4*100 -> -1.8438161
A6: 44228 | B6: 859.38831 | C6: =(Table5[[#This Row],[Daily Closing Price]]-B5)/B5*100 -> 2.8963936
A7: 44229 | B7: 873.21796 | C7: =(Table5[[#This Row],[Daily Closing Price]]-B6)/B6*100 -> 1.6092436
A8: 44230 | B8: 875.41711 | C8: =(Table5[[#This Row],[Daily Closing Price]]-B7)/B7*100 -> 0.25184522
A9: 44231 | B9: 872.53778 | C9: =(Table5[[#This Row],[Daily Closing Price]]-B8)/B8*100 -> -0.32890989
A10: 44232 | B10: 872.28833 | C10: =(Table5[[#This Row],[Daily Closing Price]]-B9)/B9*100 -> -0.028589098
A11: 44235 | B11: 884.84839 | C11: =(Table5[[#This Row],[Daily Closing Price]]-B10)/B10*100 -> 1.4398976
A12: 44236 | B12: 886.97949 | C12: =(Table5[[#This Row],[Daily Closing Price]]-B11)/B11*100 -> 0.24084392
A13: 44237 | B13: 895.20929 | C13: =(Table5[[#This Row],[Daily Closing Price]]-B12)/B12*100 -> 0.92784528
A14: 44238 | B14: 932.11859 | C14: =(Table5[[#This Row],[Daily Closing Price]]-B13)/B13*100 -> 4.1229802
A15: 44239 | B15: 925.72522 | C15: =(Table5[[#This Row],[Daily Closing Price]]-B14)/B14*100 -> -0.6858968
A16: 44242 | B16: 921.64435 | C16: =(Table5[[#This Row],[Daily Closing Price]]-B15)/B15*100 -> -0.44082969
... A22: 44250 | B22: 917.49542 | C22: =(Table5[[#This Row],[Daily Closing Price]]-B21)/B21*100 -> 0.76440811
A23: 44251 | B23: 934.52185 | C23: =(Table5[[#This Row],[Daily Closing Price]]-B22)/B22*100 -> 1.8557508 | F23: =AVERAGE(B2:B23) -> 897.57541
A24: 44252 | B24: 972.31537 | C24: =(Table5[[#This Row],[Daily Closing Price]]-B23)/B23*100 -> 4.0441556 | F24: =AVERAGE(B3:B24) -> 901.76656
A25: 44253 | B25: 945.76691 | C25: =(Table5[[#This Row],[Daily Closing Price]]-B24)/B24*100 -> -2.7304373 | F25: =AVERAGE(B4:B25) -> 905.69904
A26: 44256 | B26: 952.97656 | C26: =(Table5[[#This Row],[Daily Closing Price]]-B25)/B25*100 -> 0.76230789 | F26: =AVERAGE(B5:B26) -> 910.3395
A27: 44257 | B27: 954.92621 | C27: =(Table5[[#This Row],[Daily Closing Price]]-B26)/B26*100 -> 0.20458488 | F27: =AVERAGE(B6:B27) -> 915.78171
A28: 44258 | B28: 998.50098 | C28: =(Table5[[#This Row],[Daily Closing Price]]-B27)/B27*100 -> 4.5631555 | F28: =AVERAGE(B7:B28) -> 922.10501
A29: 44259 | B29: 986.59845 | C29: =(Table5[[#This Row],[Daily Closing Price]]-B28)/B28*100 -> -1.1920396 | F29: =AVERAGE(B8:B29) -> 927.25867
A30: 44260 | B30: 987.89069 | C30: =(Table5[[#This Row],[Daily Closing Price]]-B29)/B29*100 -> 0.13097895 | F30: =AVERAGE(B9:B30) -> 932.3711
A31: 44263 | B31: 993.51331 | C31: =(Table5[[#This Row],[Daily Closing Price]]-B30)/B30*100 -> 0.56915403 | F31: =AVERAGE(B10:B31) -> 937.86999
A32: 44264 | B32: 993.49048 | C32: =(Table5[[#This Row],[Daily Closing Price]]-B31)/B31*100 -> -0.0022976188 | F32: =AVERAGE(B11:B32) -> 943.37918
A33: 44265 | B33: 989.36426 | C33: =(Table5[[#This Row],[Daily Closing Price]]-B32)/B32*100 -> -0.41532564 | F33: =AVERAGE(B12:B33) -> 948.1299
A34: 44267 | B34: 969.25476 | C34: =(Table5[[#This Row],[Daily Closing Price]]-B33)/B33*100 -> -2.0325676 | F34: =AVERAGE(B13:B34) -> 951.86969
... A51: 44294 | B51: 909.28833 | C51: =(Table5[[#This Row],[Daily Closing Price]]-B50)/B50*100 -> 0.12481174 | F51: =AVERAGE(B30:B51) -> 936.93325
A52: 44295 | B52: 898.72345 | C52: =(Table5[[#This Row],[Daily Closing Price]]-B51)/B51*100 -> -1.1618845 | F52: =AVERAGE(B31:B52) -> 932.88019 | G52: =AVERAGE(B2:B52) -> 922.92154
A53: 44298 | B53: 866.5752 | C53: =(Table5[[#This Row],[Daily Closing Price]]-B52)/B52*100 -> -3.577102 | F53: =AVERAGE(B32:B53) -> 927.11028 | G53: =AVERAGE(B3:B53) -> 922.65615
A54: 44299 | B54: 875.93854 | C54: =(Table5[[#This Row],[Daily Closing Price]]-B53)/B53*100 -> 1.0804997 | F54: =AVERAGE(B33:B54) -> 921.76701 | G54: =AVERAGE(B4:B54) -> 922.98333
A55: 44301 | B55: 881.60638 | C55: =(Table5[[#This Row],[Daily Closing Price]]-B54)/B54*100 -> 0.64705986 | F55: =AVERAGE(B34:B55) -> 916.86892 | G55: =AVERAGE(B5:B55) -> 923.58568
A56: 44302 | B56: 876.07452 | C56: =(Table5[[#This Row],[Daily Closing Price]]-B55)/B55*100 -> -0.62747508 | F56: =AVERAGE(B35:B56) -> 912.63346 | G56: =AVERAGE(B6:B56) -> 924.38719
A57: 44305 | B57: 862.2901 | C57: =(Table5[[#This Row],[Daily Closing Price]]-B56)/B56*100 -> -1.5734305 | F57: =AVERAGE(B36:B57) -> 908.36295 | G57: =AVERAGE(B7:B57) -> 924.44408
A58: 44306 | B58: 862.04089 | C58: =(Table5[[#This Row],[Daily Closing Price]]-B57)/B57*100 -> -0.028900546 | F58: =AVERAGE(B37:B58) -> 904.25219 | G58: =AVERAGE(B8:B58) -> 924.22493
A59: 44308 | B59: 864.42133 | C59: =(Table5[[#This Row],[Daily Closing Price]]-B58)/B58*100 -> 0.27613912 | F59: =AVERAGE(B38:B59) -> 901.18225 | G59: =AVERAGE(B9:B59) -> 924.00932
A60: 44309 | B60: 863.49188 | C60: =(Table5[[#This Row],[Daily Closing Price]]-B59)/B59*100 -> -0.10752203 | F60: =AVERAGE(B39:B60) -> 899.0233 | G60: =AVERAGE(B10:B60) -> 923.83195
A61: 44312 | B61: 878.68176 | C61: =(Table5[[#This Row],[Daily Closing Price]]-B60)/B60*100 -> 1.7591225 | F61: =AVERAGE(B40:B61) -> 896.0523 | G61: =AVERAGE(B11:B61) -> 923.95731
...

Sheet Adani Energy Sol.
A1: Date | B1: Daily Closing Price | C1: Daily Return | D1: Total Return | E1: 20 SMA | F1: 50 SMA | G1: 200 SMA | I1: Stand Dev
A2: 45154 | B2: 818.09998 | D2: =(B600-B2)/B600 -> -0.0066444731 | I2: =STDEV(C3:C1240)% -> 0.031893049
A3: 45155 | B3: 822.20001 | C3: =(Table5[[#This Row],[Daily Closing Price]]-B2)/B2*100 -> 5.0302266 | D3: CAGR | F3: Annual Standev
A4: 45156 | B4: 871.90002 | C4: 6.0447594 | D4: =(B600/B2)^(1/5)-1 -> -0.0013236224 | F4: =I2*SQRT(252) -> 0.50628646
A5: 45159 | B5: 923.54999 | C5: 5.9238401
A6: 45160 | B6: 960.15002 | C6: 3.962973
A7: 45161 | B7: 890.40002 | C7: -7.2644897
A8: 45162 | B8: 895.15002 | C8: 0.53346809
A9: 45163 | B9: 874.54999 | C9: -2.3012943
A10: 45166 | B10: 864.95001 | C10: -1.0977046
A11: 45167 | B11: 857.15002 | C11: -0.90178481
A12: 45168 | B12: 841.70001 | C12: -1.8024864
A13: 45169 | B13: 811.95001 | C13: -3.5345134
A14: 45170 | B14: 824.90002 | C14: 1.5949273
A15: 45173 | B15: 817.59998 | C15: -0.88496165
A16: 45174 | B16: 813.45001 | C16: -0.50757871
... A21: 45181 | B21: 852.29999 | C21: -2.5831565
A22: 45182 | B22: 836.90002 | C22: -1.8068712 | E22: =AVERAGE(B2:B21) -> 857.16251
A23: 45183 | B23: 851.75 | C23: 1.7744026 | E23: =AVERAGE(B3:B22) -> 858.10251
A24: 45184 | B24: 846.09998 | C24: -0.66334305 | E24: =AVERAGE(B4:B23) -> 859.58001
A25: 45187 | B25: 855.09998 | C25: 1.0637041 | E25: =AVERAGE(B5:B24) -> 858.29001
A26: 45189 | B26: 855.20001 | C26: 0.011698822 | E26: =AVERAGE(B6:B25) -> 854.86751
A27: 45190 | B27: 847.34998 | C27: -0.91791821 | E27: =AVERAGE(B7:B26) -> 849.62001
A28: 45191 | B28: 839.09998 | C28: -0.97362368 | E28: =AVERAGE(B8:B27) -> 847.4675
A29: 45194 | B29: 830.40002 | C29: -1.0368194 | E29: =AVERAGE(B9:B28) -> 844.665
A30: 45195 | B30: 817.84998 | C30: -1.5113257 | E30: =AVERAGE(B10:B29) -> 842.4575
A31: 45196 | B31: 816.20001 | C31: -0.20174402 | E31: =AVERAGE(B11:B30) -> 840.1025
A32: 45197 | B32: 830.5 | C32: 1.75202 | E32: =AVERAGE(B12:B31) -> 838.055
A33: 45198 | B33: 810.25 | C33: -2.4382902 | E33: =AVERAGE(B13:B32) -> 837.495
... A51: 45226 | B51: 764.5 | C51: 3.4366155 | E51: =AVERAGE(B31:B50) -> 783.03
A52: 45229 | B52: 759.25 | C52: -0.68672335 | E52: =AVERAGE(B32:B51) -> 780.445 | F52: =AVERAGE(B2:B51) -> 822.962
A53: 45230 | B53: 769.79999 | C53: 1.3895275 | E53: =AVERAGE(B33:B52) -> 776.8825 | F53: =AVERAGE(B3:B52) -> 821.785
A54: 45231 | B54: 749.95001 | C54: -2.5785887 | E54: =AVERAGE(B34:B53) -> 774.86 | F54: =AVERAGE(B4:B53) -> 820.737
A55: 45232 | B55: 752.25 | C55: 0.30668548 | E55: =AVERAGE(B35:B54) -> 771.97 | F55: =AVERAGE(B5:B54) -> 818.298
A56: 45233 | B56: 765.5 | C56: 1.7613825 | E56: =AVERAGE(B36:B55) -> 769.17751 | F56: =AVERAGE(B6:B55) -> 814.872
A57: 45236 | B57: 771.84998 | C57: 0.82952 | E57: =AVERAGE(B37:B56) -> 767.0675 | F57: =AVERAGE(B7:B56) -> 810.979
A58: 45237 | B58: 762.04999 | C58: -1.2696752 | E58: =AVERAGE(B38:B57) -> 765.36 | F58: =AVERAGE(B8:B57) -> 808.608
A59: 45238 | B59: 757.95001 | C59: -0.53801924 | E59: =AVERAGE(B39:B58) -> 764.5175 | F59: =AVERAGE(B9:B58) -> 805.946
A60: 45239 | B60: 750.20001 | C60: -1.0224949 | E60: =AVERAGE(B40:B59) -> 763.115 | F60: =AVERAGE(B10:B59) -> 803.614
A61: 45240 | B61: 760.45001 | C61: 1.3663023 | E61: =AVERAGE(B41:B60) -> 760.715 | F61: =AVERAGE(B11:B60) -> 801.319
...

Sheet TCS
A1: Date | B1: Daily Closing Price | C1: Daily Return | D1: Total Return | E1: 20 SMA | F1: 50SMA | G1: 200SMA | I1: Stand Dev
A2: 44221 | B2: 2893.3054 | D2: =(B1240-B2)/B1240 -> 0.085120816 | I2: =STDEV(C3:C1240)% -> 0.023847215
A3: 44223 | B3: 2866.7141 | C3: =(Table5[[#This Row],[Daily Closing Price]]-B2)/B2*100 -> -70.302055 | D3: CAGR | F3: Annual Standev
A4: 44224 | B4: 2810.0132 | C4: -1.9779066 | D4: =(B1240/B2)^(1/5)-1 -> 0.017951885 | F4: =I2*SQRT(252) -> 0.3785628
A5: 44225 | B5: 2735.1162 | C5: -2.6653602
A6: 44228 | B6: 2759.7302 | C6: 0.8999257
A7: 44229 | B7: 2816.0786 | C7: 2.0418079
A8: 44230 | B8: 2813.0903 | C8: -0.10611498
A9: 44231 | B9: 2802.8926 | C9: -0.36251072
A10: 44232 | B10: 2776.0808 | C10: -0.95657493
A11: 44235 | B11: 2825.4409 | C11: 1.7780501
A12: 44236 | B12: 2792.7393 | C12: -1.1574002
A13: 44237 | B13: 2824.7383 | C13: 1.1457934
A14: 44238 | B14: 2818.3206 | C14: -0.22719714
A15: 44239 | B15: 2804.9595 | C15: -0.47407964
A16: 44242 | B16: 2760.1697 | C16: -1.5968072
... A20: 44246 | B20: 2700.3923 | C20: 0.4742657
A21: 44249 | B21: 2600.7053 | C21: -3.6915751 | E21: =AVERAGE(B2:B21) -> 2776.125
A22: 44250 | B22: 2619.825 | C22: 0.73517091 | E22: =AVERAGE(B3:B22) -> 2762.4509
A23: 44251 | B23: 2591.6072 | C23: -1.0770862 | E23: =AVERAGE(B4:B23) -> 2748.6956
A24: 44252 | B24: 2633.0996 | C24: 1.6010309 | E24: =AVERAGE(B5:B24) -> 2739.8499
A25: 44253 | B25: 2544.3125 | C25: -3.3719617 | E25: =AVERAGE(B6:B25) -> 2730.3097
A26: 44256 | B26: 2570.5964 | C26: 1.0330467 | E26: =AVERAGE(B7:B26) -> 2720.853
A27: 44257 | B27: 2642.813 | C27: 2.8093306 | E27: =AVERAGE(B8:B27) -> 2712.1898
A28: 44258 | B28: 2689.1851 | C28: 1.7546482 | E28: =AVERAGE(B9:B28) -> 2705.9945
A29: 44259 | B29: 2680.9211 | C29: -0.30730187 | E29: =AVERAGE(B10:B29) -> 2699.8959
A30: 44260 | B30: 2644.3074 | C30: -1.365716 | E30: =AVERAGE(B11:B30) -> 2693.3073
A31: 44263 | B31: 2643.3406 | C31: -0.036561441 | E31: =AVERAGE(B12:B31) -> 2684.2022
A32: 44264 | B32: 2682.0198 | C32: 1.4632696 | E32: =AVERAGE(B13:B32) -> 2678.6663
... A50: 44293 | B50: 2875.8125 | C50: 0.2052368 | E50: =AVERAGE(B31:B50) -> 2741.14
A51: 44294 | B51: 2916.2063 | C51: 1.4046047 | E51: =AVERAGE(B32:B51) -> 2754.7833 | F51: =AVERAGE(B2:B51) -> 2737.5634
A52: 44295 | B52: 2920.5127 | C52: 0.14767119 | E52: =AVERAGE(B33:B52) -> 2766.7079 | F52: =AVERAGE(B3:B52) -> 2738.1076
A53: 44298 | B53: 2853.9668 | C53: -2.2785691 | E53: =AVERAGE(B34:B53) -> 2774.4262 | F53: =AVERAGE(B4:B53) -> 2737.8526
A54: 44299 | B54: 2728.6992 | C54: -4.3892444 | E54: =AVERAGE(B35:B54) -> 2776.4525 | F54: =AVERAGE(B5:B54) -> 2736.2264
A55: 44301 | B55: 2829.7048 | C55: 3.7016031 | E55: =AVERAGE(B36:B55) -> 2783.1686 | F55: =AVERAGE(B6:B55) -> 2738.1181
A56: 44302 | B56: 2808.7832 | C56: -0.73935736 | E56: =AVERAGE(B37:B56) -> 2786.9091 | F56: =AVERAGE(B7:B56) -> 2739.0992
A57: 44305 | B57: 2779.4653 | C57: -1.0437926 | E57: =AVERAGE(B38:B57) -> 2789.0563 | F57: =AVERAGE(B8:B57) -> 2738.3669
A58: 44306 | B58: 2764.3013 | C58: -0.5455748 | E58: =AVERAGE(B39:B58) -> 2793.8055 | F58: =AVERAGE(B9:B58) -> 2737.3912
A59: 44308 | B59: 2741.665 | C59: -0.81887711 | E59: =AVERAGE(B40:B59) -> 2796.8207 | F59: =AVERAGE(B10:B59) -> 2736.1666
A60: 44309 | B60: 2733.4897 | C60: -0.29818715 | E60: =AVERAGE(B41:B60) -> 2795.935 | F60: =AVERAGE(B11:B60) -> 2735.3148
...

Sheet HDFC Bank
A1: Date | B1: Daily Closing Price | C1: Daily Return | D1: Total Return | E1: 20 SMA | F1: 50 SMA | G1: 200 SMA | I1: Stand Dev
A2: 44221 | B2: 692.7879 | D2: =(B1240-B2)/B1240 -> 0.24376387 | I2: =STDEV(C3:C1240)% -> 0.014953349
A3: 44223 | B3: 667.56946 | C3: =(Table5[[#This Row],[Daily Closing Price]]-B2)/B2*100 -> 24.028184 | D3: CAGR | F3: Annual Standev
A4: 44224 | B4: 649.50201 | C4: -2.7064515 | D4: =(B1240/B2)^(1/5)-1 -> 0.057471119 | F4: =I2*SQRT(252) -> 0.23737706
A5: 44225 | B5: 658.5238 | C5: 1.3890318
A6: 44228 | B6: 699.37091 | C6: 6.2028292
A7: 44229 | B7: 739.0575 | C7: 5.6746118
A8: 44230 | B8: 745.80615 | C8: 0.91314374
A9: 44231 | B9: 747.84241 | C9: 0.27302736
A10: 44232 | B10: 756.60382 | C10: 1.1715588
A11: 44235 | B11: 760.22687 | C11: 0.47885654
A12: 44236 | B12: 763.3526 | C12: 0.41115785
A13: 44237 | B13: 749.09753 | C13: -1.8674287
A14: 44238 | B14: 744.64581 | C14: -0.59427791
A15: 44239 | B15: 749.19226 | C15: 0.61055171
A16: 44242 | B16: 765.60211 | C16: 2.1903391
... A20: 44246 | B20: 728.89905 | C20: -0.97793382
A21: 44249 | B21: 733.11389 | C21: 0.57824794 | E21: =AVERAGE(B2:B21) -> 730.45002
A22: 44250 | B22: 724.18683 | C22: -1.2176912 | E22: =AVERAGE(B3:B22) -> 732.01997
A23: 44251 | B23: 760.79517 | C23: 5.0550957 | E23: =AVERAGE(B4:B23) -> 736.68125
A24: 44252 | B24: 760.77148 | C24: -0.0031127486 | E24: =AVERAGE(B5:B24) -> 742.24473
A25: 44253 | B25: 726.67316 | C25: -4.4820723 | E25: =AVERAGE(B6:B25) -> 745.65219
A26: 44256 | B26: 738.27612 | C26: 1.5967242 | E26: =AVERAGE(B7:B26) -> 747.59745
A27: 44257 | B27: 742.68036 | C27: 0.59655672 | E27: =AVERAGE(B8:B27) -> 747.7786
A28: 44258 | B28: 751.51282 | C28: 1.1892678 | E28: =AVERAGE(B9:B28) -> 748.06393
A29: 44259 | B29: 735.03198 | C29: -2.1930211 | E29: =AVERAGE(B10:B29) -> 747.42341
A30: 44260 | B30: 724.58936 | C30: -1.4207038 | E30: =AVERAGE(B11:B30) -> 745.82269
A31: 44263 | B31: 719.6167 | C31: -0.68627233 | E31: =AVERAGE(B12:B31) -> 743.79218
A32: 44264 | B32: 739.98096 | C32: 2.8298757 | E32: =AVERAGE(B13:B32) -> 742.6236
... A50: 44293 | B50: 685.37628 | C50: 0.48255623 | E50: =AVERAGE(B31:B50) -> 710.10349
A51: 44294 | B51: 678.55664 | C51: -0.99502146 | E51: =AVERAGE(B32:B51) -> 708.05049 | F51: =AVERAGE(B2:B51) -> 723.08288
A52: 44295 | B52: 673.32355 | C52: -0.7712095 | E52: =AVERAGE(B33:B52) -> 704.71761 | F52: =AVERAGE(B3:B52) -> 722.69359
A53: 44298 | B53: 647.41827 | C53: -3.8473738 | E53: =AVERAGE(B34:B53) -> 700.24932 | F53: =AVERAGE(B4:B53) -> 722.29057
A54: 44299 | B54: 663.18872 | C54: 2.4358977 | E54: =AVERAGE(B35:B54) -> 696.65952 | F54: =AVERAGE(B5:B54) -> 722.56431
A55: 44301 | B55: 677.27783 | C55: 2.1244498 | E55: =AVERAGE(B36:B55) -> 694.32592 | F55: =AVERAGE(B6:B55) -> 722.93939
A56: 44302 | B56: 676.59131 | C56: -0.10136511 | E56: =AVERAGE(B37:B56) -> 692.34869 | F56: =AVERAGE(B7:B56) -> 722.48379
A57: 44305 | B57: 668.89545 | C57: -1.1374462 | E57: =AVERAGE(B38:B57) -> 690.38448 | F57: =AVERAGE(B8:B57) -> 721.08055
A58: 44306 | B58: 658.95013 | C58: -1.4868262 | E58: =AVERAGE(B39:B58) -> 688.02602 | F58: =AVERAGE(B9:B58) -> 719.34343
A59: 44308 | B59: 673.67865 | C59: 2.2351487 | E59: =AVERAGE(B40:B59) -> 686.25007 | F59: =AVERAGE(B10:B59) -> 717.86016
A60: 44309 | B60: 669.72424 | C60: -0.5869871 | E60: =AVERAGE(B41:B60) -> 684.9477 | F60: =AVERAGE(B11:B60) -> 716.12257
...

Sheet SBI Bank
A1: Date | B1: Daily Closing Price | C1: Daily return | D1: Total Return | E1: 20 SMA | F1: 50 SMA | G1: 200 SMA | I1: Stand Dev
A2: 44221 | B2: 259.23721 | D2: =(B1240-B2)/B1240 -> 0.74819115 | I2: =STDEV(C3:C1240)% -> 0.016378019
A3: 44223 | B3: 254.34682 | C3: =(Table9[[#This Row],[Daily Closing Price]]-B2)/B2*100 -> -1.8864561 | D3: CAGR | F3: Annual Standev
A4: 44224 | B4: 260.52902 | C4: =(Table9[[#This Row],[Daily Closing Price]]-B3)/B3*100 -> 2.4306202 | D4: =(B1240/B2)^(1/5)-1 -> 0.31760672 | F4: =I2*SQRT(252) -> 0.25999299
A5: 44225 | B5: 260.29837 | C5: =(Table9[[#This Row],[Daily Closing Price]]-B4)/B4*100 -> -0.088532116
A6: 44228 | B6: 286.68805 | C6: =(Table9[[#This Row],[Daily Closing Price]]-B5)/B5*100 -> 10.138242
A7: 44229 | B7: 307.3569 | C7: =(Table9[[#This Row],[Daily Closing Price]]-B6)/B6*100 -> 7.2095275
A8: 44230 | B8: 309.98666 | C8: =(Table9[[#This Row],[Daily Closing Price]]-B7)/B7*100 -> 0.85560491
A9: 44231 | B9: 327.65665 | C9: =(Table9[[#This Row],[Daily Closing Price]]-B8)/B8*100 -> 5.7002397
A10: 44232 | B10: 362.71991 | C10: =(Table9[[#This Row],[Daily Closing Price]]-B9)/B9*100 -> 10.701221
A11: 44235 | B11: 366.36462 | C11: =(Table9[[#This Row],[Daily Closing Price]]-B10)/B10*100 -> 1.0048289
A12: 44236 | B12: 364.28848 | C12: =(Table9[[#This Row],[Daily Closing Price]]-B11)/B11*100 -> -0.56668718
A13: 44237 | B13: 361.93561 | C13: =(Table9[[#This Row],[Daily Closing Price]]-B12)/B12*100 -> -0.64588228
A14: 44238 | B14: 359.99789 | C14: =(Table9[[#This Row],[Daily Closing Price]]-B13)/B13*100 -> -0.53537524
A15: 44239 | B15: 362.76602 | C15: =(Table9[[#This Row],[Daily Closing Price]]-B14)/B14*100 -> 0.76892879
A16: 44242 | B16: 375.49951 | C16: =(Table9[[#This Row],[Daily Closing Price]]-B15)/B15*100 -> 3.510111
... A21: 44249 | B21: 359.39807 | C21: =(Table9[[#This Row],[Daily Closing Price]]-B20)/B20*100 -> -2.5153336
A22: 44250 | B22: 365.02667 | C22: =(Table9[[#This Row],[Daily Closing Price]]-B21)/B21*100 -> 1.5661189 | E22: =AVERAGE(B2:B21) -> 334.10183
A23: 44251 | B23: 374.85364 | C23: =(Table9[[#This Row],[Daily Closing Price]]-B22)/B22*100 -> 2.6921225 | E23: =AVERAGE(B3:B22) -> 339.39131
A24: 44252 | B24: 375.77634 | C24: =(Table9[[#This Row],[Daily Closing Price]]-B23)/B23*100 -> 0.24614913 | E24: =AVERAGE(B4:B23) -> 345.41665
A25: 44253 | B25: 359.99789 | C25: =(Table9[[#This Row],[Daily Closing Price]]-B24)/B24*100 -> -4.198892 | E25: =AVERAGE(B5:B24) -> 351.17901
A26: 44256 | B26: 364.42691 | C26: =(Table9[[#This Row],[Daily Closing Price]]-B25)/B25*100 -> 1.2302894 | E26: =AVERAGE(B6:B25) -> 356.16399
A27: 44257 | B27: 363.73489 | C27: =(Table9[[#This Row],[Daily Closing Price]]-B26)/B26*100 -> -0.18989174 | E27: =AVERAGE(B7:B26) -> 360.05093
A28: 44258 | B28: 373.74634 | C28: =(Table9[[#This Row],[Daily Closing Price]]-B27)/B27*100 -> 2.7524013 | E28: =AVERAGE(B8:B27) -> 362.86983
A29: 44259 | B29: 365.07285 | C29: =(Table9[[#This Row],[Daily Closing Price]]-B28)/B28*100 -> -2.3206896 | E29: =AVERAGE(B9:B28) -> 366.05782
A30: 44260 | B30: 354.00021 | C30: =(Table9[[#This Row],[Daily Closing Price]]-B29)/B29*100 -> -3.0329924 | E30: =AVERAGE(B10:B29) -> 367.92863
A31: 44263 | B31: 359.49042 | C31: =(Table9[[#This Row],[Daily Closing Price]]-B30)/B30*100 -> 1.5509041 | E31: =AVERAGE(B11:B30) -> 367.49264
A32: 44264 | B32: 357.64496 | C32: =(Table9[[#This Row],[Daily Closing Price]]-B31)/B31*100 -> -0.51335415 | E32: =AVERAGE(B12:B31) -> 367.14893
A33: 44265 | B33: 357.73724 | C33: =(Table9[[#This Row],[Daily Closing Price]]-B32)/B32*100 -> 0.025803567 | E33: =AVERAGE(B13:B32) -> 366.81676
... A51: 44294 | B51: 328.11804 | C51: =(Table9[[#This Row],[Daily Closing Price]]-B50)/B50*100 -> -0.82275871 | E51: =AVERAGE(B31:B50) -> 340.72233
A52: 44295 | B52: 325.71893 | C52: =(Table9[[#This Row],[Daily Closing Price]]-B51)/B51*100 -> -0.7311725 | E52: =AVERAGE(B32:B51) -> 339.15371 | F52: =AVERAGE(B2:B51) -> 342.42474
A53: 44298 | B53: 303.43539 | C53: =(Table9[[#This Row],[Daily Closing Price]]-B52)/B52*100 -> -6.8413397 | E53: =AVERAGE(B33:B52) -> 337.55741 | F53: =AVERAGE(B3:B52) -> 343.75438
A54: 44299 | B54: 314.64639 | C54: =(Table9[[#This Row],[Daily Closing Price]]-B53)/B53*100 -> 3.6946905 | E54: =AVERAGE(B34:B53) -> 334.84232 | F54: =AVERAGE(B4:B53) -> 344.73615
A55: 44301 | B55: 316.215 | C55: =(Table9[[#This Row],[Daily Closing Price]]-B54)/B54*100 -> 0.498529 | E55: =AVERAGE(B35:B54) -> 332.99227 | F55: =AVERAGE(B5:B54) -> 345.8185
A56: 44302 | B56: 313.63138 | C56: =(Table9[[#This Row],[Daily Closing Price]]-B55)/B55*100 -> -0.81704479 | E56: =AVERAGE(B36:B55) -> 331.09148 | F56: =AVERAGE(B6:B55) -> 346.93683
A57: 44305 | B57: 305.55759 | C57: =(Table9[[#This Row],[Daily Closing Price]]-B56)/B56*100 -> -2.5742933 | E57: =AVERAGE(B37:B56) -> 329.30833 | F57: =AVERAGE(B7:B56) -> 347.4757
A58: 44306 | B58: 304.03513 | C58: =(Table9[[#This Row],[Daily Closing Price]]-B57)/B57*100 -> -0.49825663 | E58: =AVERAGE(B38:B57) -> 327.6013 | F58: =AVERAGE(B8:B57) -> 347.43971
A59: 44308 | B59: 310.63254 | C59: =(Table9[[#This Row],[Daily Closing Price]]-B58)/B58*100 -> 2.1699506 | E59: =AVERAGE(B39:B58) -> 325.8666 | F59: =AVERAGE(B9:B58) -> 347.32068
A60: 44309 | B60: 310.44806 | C60: =(Table9[[#This Row],[Daily Closing Price]]-B59)/B59*100 -> -0.059388099 | E60: =AVERAGE(B40:B59) -> 324.27491 | F60: =AVERAGE(B10:B59) -> 346.9802
A61: 44312 | B61: 317.69128 | C61: =(Table9[[#This Row],[Daily Closing Price]]-B60)/B60*100 -> 2.333152 | E61: =AVERAGE(B41:B60) -> 322.86546 | F61: =AVERAGE(B11:B60) -> 345.93476
...

Sheet DLF
A1: Date | B1: Daily Closing Price | C1: Daily Return | D1: Total Return | E1: 20 SMA | F1: 50 SMA | G1: 200 SMA | I1: Stand Dev
A2: 44221 | B2: 260.61835 | D2: =(B1240-B2)/B1240 -> 0.55711047 | I2: =STDEV(C3:C1240)% -> 0.068759374
A3: 44223 | B3: 249.8055 | C3: =(Table5[[#This Row],[Daily Closing Price]]-B2)/B2*100 -> 229.69753 | D3: CAGR | F3: Annual Standev
A4: 44224 | B4: 251.97772 | C4: 0.86956692 | D4: =(B1240/B2)^(1/5)-1 -> 0.17690367 | F4: =I2*SQRT(252) -> 1.0915212
A5: 44225 | B5: 246.61957 | C5: -2.1264397
A6: 44228 | B6: 271.91388 | C6: 10.256409
A7: 44229 | B7: 284.3197 | C7: 4.5624088
A8: 44230 | B8: 279.92697 | C8: -1.5449969
A9: 44231 | B9: 294.21536 | C9: 5.1043281
A10: 44232 | B10: 294.7464 | C10: 0.1804924
A11: 44235 | B11: 302.22849 | C11: 2.5384826
A12: 44236 | B12: 296.38757 | C12: -1.9326146
A13: 44237 | B13: 300.63547 | C13: 1.4332228
A14: 44238 | B14: 298.94595 | C14: -0.56198098
A15: 44239 | B15: 300.97336 | C15: 0.67818439
A16: 44242 | B16: 306.28329 | C16: 1.7642547
... A21: 44249 | B21: 283.9335 | C21: -2.1623599
A22: 44250 | B22: 294.84293 | C22: 3.8422461 | E22: =AVERAGE(B3:B22) -> 287.78077
A23: 44251 | B23: 302.37326 | C23: 2.5540156 | E23: =AVERAGE(B4:B23) -> 290.40915
A24: 44252 | B24: 303.82144 | C24: 0.47893823 | E24: =AVERAGE(B5:B24) -> 293.00134
A25: 44253 | B25: 292.04315 | C25: -3.8767145 | E25: =AVERAGE(B6:B25) -> 295.27252
A26: 44256 | B26: 296.67722 | C26: 1.5867736 | E26: =AVERAGE(B7:B26) -> 296.51069
A27: 44257 | B27: 302.75946 | C27: 2.050122 | E27: =AVERAGE(B8:B27) -> 297.43267
A28: 44258 | B28: 312.99304 | C28: 3.380103 | E28: =AVERAGE(B9:B28) -> 299.08598
A29: 44259 | B29: 315.11694 | C29: 0.67857782 | E29: =AVERAGE(B10:B29) -> 300.13106
A30: 44260 | B30: 307.10388 | C30: -2.542885 | E30: =AVERAGE(B11:B30) -> 300.74893
A31: 44263 | B31: 305.31784 | C31: -0.58157561 | E31: =AVERAGE(B12:B31) -> 300.9034
A32: 44264 | B32: 300.63547 | C32: -1.5336061 | E32: =AVERAGE(B13:B32) -> 301.11579
A33: 44265 | B33: 303.38699 | C33: 0.91523662 | E33: =AVERAGE(B14:B33) -> 301.25337
... A51: 44294 | B51: 270.7554 | C51: -0.93607075 | E51: =AVERAGE(B32:B51) -> 280.80552
A52: 44295 | B52: 269.88647 | C52: -0.32092693 | E52: =AVERAGE(B33:B52) -> 279.26807 | F52: =AVERAGE(B3:B52) -> 287.59637
A53: 44298 | B53: 238.07552 | C53: -11.786793 | E53: =AVERAGE(B34:B53) -> 276.0025 | F53: =AVERAGE(B4:B53) -> 287.36177
A54: 44299 | B54: 246.86095 | C54: 3.6901867 | E54: =AVERAGE(B35:B54) -> 273.45376 | F54: =AVERAGE(B5:B54) -> 287.25943
A55: 44301 | B55: 239.42711 | C55: -3.0113463 | E55: =AVERAGE(B36:B55) -> 270.73848 | F55: =AVERAGE(B6:B55) -> 287.11558
A56: 44302 | B56: 243.7233 | C56: 1.7943617 | E56: =AVERAGE(B37:B56) -> 268.24043 | F56: =AVERAGE(B7:B56) -> 286.55177
A57: 44305 | B57: 228.61427 | C57: -6.1992531 | E57: =AVERAGE(B38:B57) -> 265.61687 | F57: =AVERAGE(B8:B57) -> 285.43766
A58: 44306 | B58: 226.29723 | C58: -1.0135181 | E58: =AVERAGE(B39:B58) -> 263.01985 | F58: =AVERAGE(B9:B58) -> 284.36507
A59: 44308 | B59: 238.4617 | C59: 5.3754413 | E59: =AVERAGE(B40:B59) -> 261.06968 | F59: =AVERAGE(B10:B59) -> 283.25
A60: 44309 | B60: 233.58624 | C60: -2.0445454 | E60: =AVERAGE(B41:B60) -> 258.63921 | F60: =AVERAGE(B11:B60) -> 282.02679
A61: 44312 | B61: 238.26859 | C61: 2.0045455 | E61: =AVERAGE(B42:B61) -> 256.17011 | F61: =AVERAGE(B12:B61) -> 280.74759
...

Sheet Tata Steel
A1: Date | B1: Daily Closing Price | C1: Daily Return | D1: Total Return | E1: 20 SMA | F1: 50 SMA | G1: 200 SMA | I1: Stand Dev
A2: 44221 | B2: 56.124908 | D2: =(B1240-B2)/B1240 -> 0.70084266 | I2: =STDEV(C3:C1240)% -> 0.020528355
A3: 44223 | B3: 53.890926 | C3: =(Table4[[#This Row],[Daily Closing Price]]-B2)/B2*100 -> -3.9803755 | D3: CAGR | F3: Annual Standev
A4: 44224 | B4: 53.692928 | C4: -0.36740516 | D4: =(B1240/B2)^(1/5)-1 -> 0.27297557 | F4: =I2*SQRT(252) -> 0.32587753
A5: 44225 | B5: 51.738735 | C5: -3.6395726
A6: 44228 | B6: 54.760414 | C6: 5.8402644
A7: 44229 | B7: 55.238205 | C7: 0.87251136
A8: 44230 | B8: 56.228214 | C8: 1.7922547
A9: 44231 | B9: 56.469261 | C9: 0.42869387
A10: 44232 | B10: 58.974407 | C10: 4.4363003
A11: 44235 | B11: 60.515381 | C11: 2.6129532
A12: 44236 | B12: 60.192554 | C12: -0.53346171
A13: 44237 | B13: 59.42207 | C13: -1.2800336
A14: 44238 | B14: 59.805161 | C14: 0.64469477
A15: 44239 | B15: 58.582714 | C15: -2.0440484
A16: 44242 | B16: 57.863873 | C16: -1.227054
... A21: 44249 | B21: 58.93137 | C21: 2.0650113
A22: 44250 | B22: 62.783802 | C22: 6.5371504 | E22: =AVERAGE(B2:B20) -> 57.44658
A23: 44251 | B23: 62.646049 | C23: -0.21940776 | E23: =AVERAGE(B3:B21) -> 57.594289
A24: 44252 | B24: 63.954586 | C24: 2.0887774 | E24: =AVERAGE(B4:B22) -> 58.062335
A25: 44253 | B25: 61.565651 | C25: -3.7353617 | E25: =AVERAGE(B5:B23) -> 58.533552
A26: 44256 | B26: 62.878494 | C26: 2.1324282 | E26: =AVERAGE(B6:B24) -> 59.176491
A27: 44257 | B27: 63.317551 | C27: 0.69826163 | E27: =AVERAGE(B7:B25) -> 59.534662
A28: 44258 | B28: 66.903099 | C28: 5.6628034 | E28: =AVERAGE(B8:B26) -> 59.936782
A29: 44259 | B29: 65.250206 | C29: -2.4705777 | E29: =AVERAGE(B9:B27) -> 60.309905
A30: 44260 | B30: 63.128143 | C30: -3.2521931 | E30: =AVERAGE(B10:B28) -> 60.859055
A31: 44263 | B31: 63.468193 | C31: 0.53866584 | E31: =AVERAGE(B11:B29) -> 61.18936
A32: 44264 | B32: 60.842522 | C32: -4.1369878 | E32: =AVERAGE(B12:B30) -> 61.326874
A33: 44265 | B33: 62.370571 | C33: 2.5114828 | E33: =AVERAGE(B13:B31) -> 61.499276
... A51: 44294 | B51: 79.062981 | C51: 4.9779771 | E51: =AVERAGE(B31:B49) -> 65.128102
A52: 44295 | B52: 77.435936 | C52: -2.0579096 | E52: =AVERAGE(B32:B50) -> 65.751558 | F52: =AVERAGE(B2:B51) -> 62.293095
A53: 44298 | B53: 73.308029 | C53: -5.3307379 | E53: =AVERAGE(B33:B51) -> 66.71053 | F53: =AVERAGE(B3:B52) -> 62.719316
A54: 44299 | B54: 75.671135 | C54: 3.2235293 | E54: =AVERAGE(B34:B52) -> 67.503444 | F54: =AVERAGE(B4:B53) -> 63.107658
A55: 44301 | B55: 77.324005 | C55: 2.1842809 | E55: =AVERAGE(B35:B53) -> 68.099715 | F55: =AVERAGE(B5:B54) -> 63.547222
A56: 44302 | B56: 76.639618 | C56: -0.88509022 | E56: =AVERAGE(B36:B54) -> 68.745827 | F56: =AVERAGE(B6:B55) -> 64.058927
A57: 44305 | B57: 76.450226 | C57: -0.24712035 | E57: =AVERAGE(B37:B55) -> 69.534888 | F57: =AVERAGE(B7:B56) -> 64.496511
A58: 44306 | B58: 76.962448 | C58: 0.67000756 | E58: =AVERAGE(B38:B56) -> 70.376962 | F58: =AVERAGE(B8:B57) -> 64.920752
A59: 44308 | B59: 79.321251 | C59: 3.064875 | E59: =AVERAGE(B39:B57) -> 71.207029 | F59: =AVERAGE(B9:B58) -> 65.335437
A60: 44309 | B60: 79.682816 | C60: 0.45582316 | E60: =AVERAGE(B40:B58) -> 71.936509 | F60: =AVERAGE(B10:B59) -> 65.792476
A61: 44312 | B61: 80.987045 | C61: 1.6367767 | E61: =AVERAGE(B41:B59) -> 72.742562 | F61: =AVERAGE(B11:B60) -> 66.206645
...

Sheet Vedanta
A1: Date | B1: Daily Closing Price | C1: Daily Return | D1: Total Return | E1: 20 SMA | F1: 50 SMA | G1: 200 SMA | I1: Stand Dev
A2: 44221 | B2: 80.527779 | D2: =(B1240-B2)/B1240 -> 0.88229515 | I2: =STDEV(C3:C1240)% -> 0.023275375
A3: 44223 | B3: 79.431015 | C3: -1.3619693 | D3: CAGR | F3: Annual Standev
A4: 44224 | B4: 79.333527 | C4: -0.12273342 | D4: =(B1240/B2)^(1/5)-1 -> 0.53405569 | F4: =I2*SQRT(252) -> 0.36948512
A5: 44225 | B5: 78.602348 | C5: -0.92165105
A6: 44228 | B6: 83.525658 | C6: 6.2635652
A7: 44229 | B7: 84.45182 | C7: 1.1088362
A8: 44230 | B8: 84.768677 | C8: 0.37519189
A9: 44231 | B9: 85.987312 | C9: 1.4376013
A10: 44232 | B10: 85.036766 | C10: -1.1054494
A11: 44235 | B11: 86.767227 | C11: 2.0349564
A12: 44236 | B12: 88.595207 | C12: 2.1067632
A13: 44237 | B13: 90.715637 | C13: 2.3933913
A14: 44238 | B14: 91.373695 | C14: 0.72540764
A15: 44239 | B15: 88.887672 | C15: -2.7207206
A16: 44242 | B16: 89.716362 | C16: 0.93228853
... A21: 44249 | B21: 99.562965 | C21: 7.0492591
A22: 44250 | B22: 101.65903 | C22: 2.1052624 | E22: =AVERAGE(B3:B22) -> 88.667099
A23: 44251 | B23: 99.709221 | C23: -1.9179863 | E23: =AVERAGE(B4:B23) -> 89.681009
A24: 44252 | B24: 101.46404 | C24: 1.7599393 | E24: =AVERAGE(B5:B24) -> 90.787535
A25: 44253 | B25: 101.04973 | C25: -0.40833606 | E25: =AVERAGE(B6:B25) -> 91.909904
A26: 44256 | B26: 104.12069 | C26: 3.0390591 | E26: =AVERAGE(B7:B26) -> 92.939655
A27: 44257 | B27: 104.68124 | C27: 0.53836995 | E27: =AVERAGE(B8:B27) -> 93.951126
A28: 44258 | B28: 106.89918 | C28: 2.1187498 | E28: =AVERAGE(B9:B28) -> 95.057652
A29: 44259 | B29: 103.9501 | C29: -2.7587432 | E29: =AVERAGE(B10:B29) -> 95.955791
A30: 44260 | B30: 106.8748 | C30: 2.8135594 | E30: =AVERAGE(B11:B30) -> 97.047693
A31: 44263 | B31: 109.58018 | C31: 2.5313504 | E31: =AVERAGE(B12:B31) -> 98.18834
A32: 44264 | B32: 109.43395 | C32: -0.13344108 | E32: =AVERAGE(B13:B32) -> 99.230278
A33: 44265 | B33: 110.28702 | C33: 0.77952543 | E33: =AVERAGE(B14:B33) -> 100.20885
... A51: 44294 | B51: 115.89275 | C51: 0.3799761 | E51: =AVERAGE(B32:B51) -> 110.74643
A52: 44295 | B52: 112.77303 | C52: -2.691903 | E52: =AVERAGE(B33:B52) -> 110.91339 | F52: =AVERAGE(B3:B52) -> 100.78746
A53: 44298 | B53: 103.9257 | C53: -7.8452584 | E53: =AVERAGE(B34:B53) -> 110.59532 | F53: =AVERAGE(B4:B53) -> 101.27735
A54: 44299 | B54: 106.48485 | C54: 2.4624811 | E54: =AVERAGE(B35:B54) -> 110.52342 | F54: =AVERAGE(B5:B54) -> 101.82038
A55: 44301 | B55: 109.8483 | C55: 3.1586175 | E55: =AVERAGE(B36:B55) -> 110.50149 | F55: =AVERAGE(B6:B55) -> 102.4453
A56: 44302 | B56: 112.99242 | C56: 2.8622376 | E56: =AVERAGE(B37:B56) -> 110.63066 | F56: =AVERAGE(B7:B56) -> 103.03463
A57: 44305 | B57: 111.16444 | C57: -1.61779 | E57: =AVERAGE(B38:B57) -> 110.70988 | F57: =AVERAGE(B8:B57) -> 103.56888
A58: 44306 | B58: 110.21388 | C58: -0.85508812 | E58: =AVERAGE(B39:B58) -> 110.81346 | F58: =AVERAGE(B9:B58) -> 104.07779
A59: 44308 | B59: 110.40888 | C59: 0.17692843 | E59: =AVERAGE(B40:B59) -> 110.91826 | F59: =AVERAGE(B10:B59) -> 104.56622
A60: 44309 | B60: 111.14008 | C60: 0.66225971 | E60: =AVERAGE(B41:B60) -> 111.0255 | F60: =AVERAGE(B11:B60) -> 105.08829
A61: 44312 | B61: 115.35655 | C61: 3.7938398 | E61: =AVERAGE(B42:B61) -> 111.33992 | F61: =AVERAGE(B12:B61) -> 105.66007
...

Sheet Cipla
A1: Date | B1: Daily Closing Price | C1: Daily Return | D1: Total Return | E1: 20 | F1: 50 | G1: 200 | I1: Stand Dev
A2: 44221 | B2: 806.00531 | D2: =(B1240-B2)/B1240 -> 0.38706821 | I2: =STDEV(C3:C1240)% -> 0.014542542
A3: 44223 | B3: 811.49561 | C3: 0.6811736 | D3: CAGR | F3: Annual Standev
A4: 44224 | B4: 810.9176 | C4: -0.071226871 | D4: =(B1240/B2)^(1/5)-1 -> 0.10285285 | F4: =I2*SQRT(252) -> 0.2308557
A5: 44225 | B5: 795.50647 | C5: -1.9004561
A6: 44228 | B6: 776.72412 | C6: -2.3610554
A7: 44229 | B7: 791.36469 | C7: 1.8849117
A8: 44230 | B8: 817.99719 | C8: 3.3653899
A9: 44231 | B9: 803.74176 | C9: -1.7427238
A10: 44232 | B10: 816.50421 | C10: 1.5878796
A11: 44235 | B11: 816.07074 | C11: -0.053088726
A12: 44236 | B12: 810.77313 | C12: -0.64916032
A13: 44237 | B13: 831.6264 | C13: 2.572023
A14: 44238 | B14: 828.15881 | C14: -0.41696492
A15: 44239 | B15: 817.323 | C15: -1.3084224
A16: 44242 | B16: 813.22925 | C16: -0.50087297
... A21: 44249 | B21: 763.28748 | C21: -1.8455378
A22: 44250 | B22: 761.84265 | C22: -0.18928965 | E22: =AVERAGE(B3:B22) -> 803.06756
A23: 44251 | B23: 760.01257 | C23: -0.24021734 | E23: =AVERAGE(B4:B23) -> 800.49341
A24: 44252 | B24: 779.37292 | C24: 2.5473725 | E24: =AVERAGE(B5:B24) -> 798.91617
A25: 44253 | B25: 758.08618 | C25: -2.7312654 | E25: =AVERAGE(B6:B25) -> 797.04516
A26: 44256 | B26: 760.73499 | C26: 0.34940667 | E26: =AVERAGE(B7:B26) -> 796.2457
A27: 44257 | B27: 781.92542 | C27: 2.7855206 | E27: =AVERAGE(B8:B27) -> 795.77374
A28: 44258 | B28: 782.59955 | C28: 0.086214527 | E28: =AVERAGE(B9:B28) -> 794.00386
A29: 44259 | B29: 777.06122 | C29: -0.70768378 | E29: =AVERAGE(B10:B29) -> 792.66983
A30: 44260 | B30: 775.52014 | C30: -0.19832114 | E30: =AVERAGE(B11:B30) -> 790.62063
A31: 44263 | B31: 779.46924 | C31: 0.5092191 | E31: =AVERAGE(B12:B31) -> 788.79055
A32: 44264 | B32: 767.66998 | C32: -1.5137551 | E32: =AVERAGE(B13:B32) -> 786.63539
A33: 44265 | B33: 782.5033 | C33: 1.9322513 | E33: =AVERAGE(B14:B33) -> 784.17924
... A51: 44294 | B51: 811.01392 | C51: 0.13676472 | E51: =AVERAGE(B32:B51) -> 770.65832
A52: 44295 | B52: 850.55328 | C52: 4.8753008 | E52: =AVERAGE(B33:B52) -> 774.80249 | F52: =AVERAGE(B3:B52) -> 785.59706
A53: 44298 | B53: 869.19122 | C53: 2.1912724 | E53: =AVERAGE(B34:B53) -> 779.13688 | F53: =AVERAGE(B4:B53) -> 786.75098
A54: 44299 | B54: 852.62408 | C54: -1.9060407 | E54: =AVERAGE(B35:B54) -> 782.95355 | F54: =AVERAGE(B5:B54) -> 787.5851
A55: 44301 | B55: 880.55695 | C55: 3.2761051 | E55: =AVERAGE(B36:B55) -> 788.18854 | F55: =AVERAGE(B6:B55) -> 789.28611
A56: 44302 | B56: 903.5293 | C56: 2.6088433 | E56: =AVERAGE(B37:B56) -> 795.20786 | F56: =AVERAGE(B7:B56) -> 791.82222
A57: 44305 | B57: 911.47577 | C57: 0.87949247 | E57: =AVERAGE(B38:B57) -> 803.59492 | F57: =AVERAGE(B8:B57) -> 794.22444
A58: 44306 | B58: 914.36523 | C58: 0.31700956 | E58: =AVERAGE(B39:B58) -> 812.94518 | F58: =AVERAGE(B9:B58) -> 796.1518
A59: 44308 | B59: 909.59747 | C59: -0.52142853 | E59: =AVERAGE(B40:B59) -> 821.79217 | F59: =AVERAGE(B10:B59) -> 798.26891
A60: 44309 | B60: 901.16943 | C60: -0.92656805 | E60: =AVERAGE(B41:B60) -> 829.6302 | F60: =AVERAGE(B11:B60) -> 799.96222
A61: 44312 | B61: 872.08087 | C61: -3.2278682 | E61: =AVERAGE(B42:B61) -> 835.85729 | F61: =AVERAGE(B12:B61) -> 801.08242
...

Sheet NIFTY 50
A1: Date | B1: Daily Closing Price | C1: Daily Return | D1: Total Return | E1: 20 SMA | F1: 50 SMA | G1: 200 SMA | I1: Stand Dev
A2: 44221 | B2: 14238.9 | D2: =(B1237-B2)/B1237 -> 0.4315502 | I2: =STDEV(C3:C1240)% -> 0.0087787019
A3: 44223 | B3: 13967.5 | C3: -1.9060488 | D3: CAGR | F3: Annual Standev
A4: 44224 | B4: 13817.55 | C4: -1.073565 | D4: =((B1237/B2)^(1/5)-1) -> 0.11959661 | F4: =I2*SQRT(252) -> 0.13935757
A5: 44225 | B5: 13634.6 | C5: -1.3240422
A6: 44228 | B6: 14281.2 | C6: 4.7423511
A7: 44229 | B7: 14647.85 | C7: 2.5673571
A8: 44230 | B8: 14789.95 | C8: 0.97011227
A9: 44231 | B9: 14895.65 | C9: 0.7146758
A10: 44232 | B10: 14924.25 | C10: 0.19199974
A11: 44235 | B11: 15115.8 | C11: 1.2834803
A12: 44236 | B12: 15109.3 | C12: -0.043001363
A13: 44237 | B13: 15106.5 | C13: -0.01853034
A14: 44238 | B14: 15173.3 | C14: 0.44219246
A15: 44239 | B15: 15163.3 | C15: -0.065905242
A16: 44242 | B16: 15314.7 | C16: 0.99846598
... A21: 44249 | B21: 14675.7 | C21: -2.0428175
A22: 44250 | B22: 14707.8 | C22: 0.21872625 | E22: =AVERAGE(B2:B22) -> 14770.805
A23: 44251 | B23: 14982 | C23: 1.8643182 | E23: =AVERAGE(B3:B23) -> 14806.19
A24: 44252 | B24: 15097.35 | C24: 0.7699213 | E24: =AVERAGE(B4:B24) -> 14859.993
A25: 44253 | B25: 14529.15 | C25: -3.7635693 | E25: =AVERAGE(B5:B25) -> 14893.879
A26: 44256 | B26: 14761.55 | C26: 1.5995389 | E26: =AVERAGE(B6:B26) -> 14947.543
A27: 44257 | B27: 14919.1 | C27: 1.0672985 | E27: =AVERAGE(B7:B27) -> 14977.919
A28: 44258 | B28: 15245.6 | C28: 2.1884699 | E28: =AVERAGE(B8:B28) -> 15006.383
A29: 44259 | B29: 15080.75 | C29: -1.0812931 | E29: =AVERAGE(B9:B29) -> 15020.231
A30: 44260 | B30: 14938.1 | C30: -0.94591045 | E30: =AVERAGE(B10:B30) -> 15022.252
A31: 44263 | B31: 14956.2 | C31: 0.12117061 | E31: =AVERAGE(B11:B31) -> 15023.774
A32: 44264 | B32: 15098.4 | C32: 0.95077756 | E32: =AVERAGE(B12:B32) -> 15022.945
A33: 44265 | B33: 15174.8 | C33: 0.50600999 | E33: =AVERAGE(B13:B33) -> 15026.064
... A51: 44294 | B51: 14873.8 | C51: 0.36945689 | E51: =AVERAGE(B31:B51) -> 14784.452
A52: 44295 | B52: 14834.85 | C52: -0.26187118 | E52: =AVERAGE(B32:B52) -> 14778.674 | F52: =AVERAGE(B2:B51) -> 14804.28
A53: 44298 | B53: 14310.8 | C53: -3.5325589 | E53: =AVERAGE(B33:B53) -> 14741.169 | F53: =AVERAGE(B3:B52) -> 14816.199
A54: 44299 | B54: 14504.8 | C54: 1.3556196 | E54: =AVERAGE(B34:B54) -> 14709.264 | F54: =AVERAGE(B4:B53) -> 14823.065
A55: 44301 | B55: 14581.45 | C55: 0.52844846 | E55: =AVERAGE(B35:B55) -> 14687.859 | F55: =AVERAGE(B5:B54) -> 14836.81
A56: 44302 | B56: 14617.85 | C56: 0.24962822 | E56: =AVERAGE(B36:B56) -> 14673.019 | F56: =AVERAGE(B6:B55) -> 14855.747
A57: 44305 | B57: 14359.45 | C57: -1.7676979 | E57: =AVERAGE(B37:B57) -> 14646.781 | F57: =AVERAGE(B7:B56) -> 14862.48
A58: 44306 | B58: 14296.4 | C58: -0.4390823 | E58: =AVERAGE(B38:B58) -> 14626.548 | F58: =AVERAGE(B8:B57) -> 14856.712
A59: 44308 | B59: 14406.15 | C59: 0.76767576 | E59: =AVERAGE(B39:B59) -> 14619.324 | F59: =AVERAGE(B9:B58) -> 14846.841
A60: 44309 | B60: 14341.35 | C60: -0.44981331 | E60: =AVERAGE(B40:B60) -> 14600.15 | F60: =AVERAGE(B10:B59) -> 14837.051
A61: 44312 | B61: 14485 | C61: 1.0016518 | E61: =AVERAGE(B41:B61) -> 14588.179 | F61: =AVERAGE(B11:B60) -> 14825.393
...

Sheet Analysis
B2: Name | C2: Return | D2: NIFTY 50 | E2: Beta | F2: Sharpe Ratio | G2: Rf R | I2: Name | J2: Standard Deviation | K2: CAGR | L2: Risk Free Rate | M2: Sharpe Ratio | N2: Sharpe
B3: Reliance | C3: 0.36504577 | D3: 0.4315502 | E3: =SLOPE('Reliance Industries'!C3:C1237,'NIFTY 50'!C3:C1237) -> 1.11202 | G3: 0.066 | I3: Reliance | J3: ='Reliance Industries'!F4 -> 0.22563555 | K3: ='Reliance Industries'!D4 -> 0.095094293 | L3: =G3 -> 0.066 | M3: =(K3-L3)/J3 -> 0.12894374 | N3: (Annual - RF)/Standev
B4: Adani | C4: -0.0066444731 | D4: - | E4: =SLOPE('Adani Energy Sol.'!C3:C600,'NIFTY 50'!C3:C600) -> 0.10376292 | G4: 0.066 | I4: Adani | J4: ='Adani Energy Sol.'!F4 -> 0.50628646 | K4: ='Adani Energy Sol.'!D4 -> -0.0013236224 | L4: =G4 -> 0.066 | M4: =(K4-L4)/J4 -> -0.13297536
B5: TCS | C5: 0.085120816 | D5: - | E5: =SLOPE(TCS!C3:C1237,'NIFTY 50'!C3:C1237) -> 0.90925114 | G5: 0.066 | I5: TCS | J5: =TCS!F4 -> 0.3785628 | K5: =TCS!D4 -> 0.017951885 | L5: =G5 -> 0.066 | M5: =(K5-L5)/J5 -> -0.12692244
B6: HDFC | C6: 0.24376387 | D6: - | E6: =SLOPE('HDFC Bank'!C3:C1237,'NIFTY 50'!C3:C1237) -> 0.99256919 | G6: 0.066 | I6: HDFC | J6: ='HDFC Bank'!F4 -> 0.23737706 | K6: ='HDFC Bank'!D4 -> 0.057471119 | L6: =G6 -> 0.066 | M6: =(K6-L6)/J6 -> -0.035929676
B7: SBI | C7: 0.74819115 | D7: - | E7: =SLOPE('SBI Bank'!C3:C1237,'NIFTY 50'!C3:C1237) -> 1.2173863 | G7: 0.066 | I7: SBI | J7: ='SBI Bank'!F4 -> 0.25999299 | K7: ='SBI Bank'!D4 -> 0.31760672 | L7: =G7 -> 0.066 | M7: =(K7-L7)/J7 -> 0.96774423
B8: DLF | C8: 0.55711047 | D8: - | E8: =SLOPE(DLF!C3:C1237,'NIFTY 50'!C3:C1237) -> 1.1216027 | G8: 0.066 | I8: DLF | J8: =DLF!F4 -> 1.0915212 | K8: =DLF!D4 -> 0.17690367 | L8: =G8 -> 0.066 | M8: =(K8-L8)/J8 -> 0.10160469
B9: TATA STEEL | C9: 0.70084266 | D9: - | E9: =SLOPE('Tata Steel'!C3:C1237,'NIFTY 50'!C3:C1237) -> 1.3375348 | G9: 0.066 | I9: TATA STEEL | J9: ='Tata Steel'!F4 -> 0.32587753 | K9: ='Tata Steel'!D4 -> 0.27297557 | L9: =G9 -> 0.066 | M9: =(K9-L9)/J9 -> 0.63513298
B10: Vedanta | C10: 0.88229515 | D10: - | E10: =SLOPE(Vedanta!C3:C1237,'NIFTY 50'!C3:C1237) -> 1.2200888 | G10: 0.066 | I10: Vedanta | J10: =Vedanta!F4 -> 0.36948512 | K10: =Vedanta!D4 -> 0.53405569 | L10: =G10 -> 0.066 | M10: =(K10-L10)/J10 -> 1.2667782
B11: CIPLA | C11: 0.38706821 | D11: - | E11: =SLOPE(Cipla!C3:C1237,'NIFTY 50'!C3:C1237) -> 0.36723112 | G11: 0.066 | I11: CIPLA | J11: =Cipla!F4 -> 0.2308557 | K11: =Cipla!D4 -> 0.10285285 | L11: =G11 -> 0.066 | M11: =(K11-L11)/J11 -> 0.15963587
I12: Nifty 50 | J12: ='NIFTY 50'!F4 -> 0.13935757 | K12: ='NIFTY 50'!D4 -> 0.11959661 | L12: 0.066 | M12: =(K12-L12)/J12 -> 0.38459778
B13: Beta | C13: usually means sensitivity of stock to the index if index moved 1 % reliance moved 1.12% not necessarily the case but volatility also effects beta
B14: Correlation | C14: refers to the trend and movement followed by the asset in comparison to the index
B17: Fundamental Analysis
B18: Name | C18: ROE | D18: ROCE | E18: PB | F18: PE
B19: Reliance | C19: 9.72 | D19: 10 | E19: 2.25 | F19: 23.79
B20: Adani | C20: 10.54 | D20: 10 | E20: 4.18 | F20: 55.12
B21: TCS | C21: 42.63 | D21: 65 | E21: 10.22 | F21: 22.2
B22: HDFC | C22: 14.02 | D22: 7.51 | E22: 2.55 | F22: 19.15
B23: SBI | C23: 15.68 | D23: 6.47 | E23: 1.78 | F23: 12.9
B24: DLF | C24: 10.29 | D24: 7 | E24: 3.53 | F24: 37.52
B25: TATA STEEL | C25: 7.17 | D25: 9 | E25: 2.59 | F25: 28.25
B26: VEDANTA | C26: 35.05 | D26: 25 | E26: 6.62 | F26: 20.21
B27: CIPLA | C27: 17.68 | D27: 23 | E27: 3.23 | F27: 23.97
