Workbook
Name UPDATE: 'Data Sheet'!$E$1

Sheet Adani Power DCF
B2: Adani Power Ltd.
B4: Ticker | C4: ADANIPOWER
B6: INR | C6: 231
B9: Period | C9: 2023 | D9: =C9+1 -> 2024 | E9: =D9+1 -> 2025 | F9: =E9+1 -> 2026 | G9: =F9+1 -> 2027 | H9: =G9+1 -> 2028 | I9: =H9+1 -> 2029 | J9: =I9+1 -> 2030 | K9: =J9+1 -> 2031
B10: Year | G10: 1 | H10: =G10+1 -> 2 | I10: =H10+1 -> 3 | J10: =I10+1 -> 4 | K10: =J10+1 -> 5
B11: Growth | D11: =D12/C12-1 -> 0.29860626 | E11: =E12/D12-1 -> 0.11622035 | F11: =F12/E12-1 -> -0.034919254 | G11: =AVERAGE($D$11:$F$11) -> 0.12663578 | H11: =G11*(1+0.12) -> 0.14183208 | I11: =H11*(1-0.05) -> 0.13474048 | J11: =I11*(1+0.05) -> 0.1414775 | K11: =J11*(1+0.05) -> 0.14855137
B12: Revenue | C12: ='Profit & Loss'!H4 -> 38773.3 | D12: ='Profit & Loss'!I4 -> 50351.25 | E12: ='Profit & Loss'!J4 -> 56203.09 | F12: ='Profit & Loss'!K4 -> 54240.52 | G12: =F12*(1+G11) -> 61109.311 | H12: =G12*(1+H11) -> 69776.571 | I12: =H12*(1+I11) -> 79178.3 | J12: =I12*(1+J11) -> 90380.248 | K12: =J12*(1+K11) -> 103806.36
B13: EBITDA | C13: ='Profit & Loss'!H6+'Profit & Loss'!H8 -> 13400.02 | D13: ='Profit & Loss'!I6+'Profit & Loss'!I8 -> 22158.95 | E13: ='Profit & Loss'!J6+'Profit & Loss'!J8 -> 25727.21 | F13: ='Profit & Loss'!K6+'Profit & Loss'!K8 -> 24370.64 | G13: =G12*0.44905 -> 27441.136 | H13: =H12*0.44905 -> 31333.169 | I13: =I12*0.44905 -> 35555.016 | J13: =J12*0.44905 -> 40585.25 | K13: =K12*0.44905 -> 46614.245
B14: Less: Depreciation & Ammortisation | C14: ='Profit & Loss'!H8 -> 3303.68 | D14: ='Profit & Loss'!I8 -> 3931.33 | E14: ='Profit & Loss'!J8 -> 4308.88 | F14: ='Profit & Loss'!K8 -> 4564.53 | G14: =G12*0.079633 -> 4866.3177 | H14: =H12*0.079633 -> 5556.5177 | I14: =I12*0.079633 -> 6305.2056 | J14: =J12*0.079633 -> 7197.2503 | K14: =K12*0.079633 -> 8266.4117
B15: EBIT | C15: =C13-C14 -> 10096.34 | D15: =D13-D14 -> 18227.62 | E15: =E13-E14 -> 21418.33 | F15: =F13-F14 -> 19806.11 | G15: =G12*0.36942 -> 22575.002 | H15: =H12*0.36942 -> 25776.861 | I15: =I12*0.36942 -> 29250.048 | J15: =J12*0.36942 -> 33388.271 | K15: =K12*0.36942 -> 38348.145
B16: Less: Tax | C16: ='Profit & Loss'!H11 -> -3051.94 | D16: ='Profit & Loss'!I11 -> -37.28 | E16: ='Profit & Loss'!J11 -> 3609.9 | F16: ='Profit & Loss'!K11 -> 2528.43 | G16: =G15*$D$34 -> 4515.0003 | H16: =H15*$D$34 -> 5155.3722 | I16: =I15*$D$34 -> 5850.0095 | J16: =J15*$D$34 -> 6677.6542 | K16: =K15*$D$34 -> 7669.6289
B17: EBIT(1-Tax) | C17: =C15-C16 -> 13148.28 | D17: =D15-D16 -> 18264.9 | E17: =E15-E16 -> 17808.43 | F17: =F15-F16 -> 17277.68 | G17: =G15-G16 -> 18060.001 | H17: =H15-H16 -> 20621.489 | I17: =I15-I16 -> 23400.038 | J17: =J15-J16 -> 26710.617 | K17: =K15-K16 -> 30678.516
B18: Add: Depreciation & Ammortisation | C18: =C14 -> 3303.68 | D18: =D14 -> 3931.33 | E18: =E14 -> 4308.88 | F18: =F14 -> 4564.53 | G18: =G14 -> 4866.3177 | H18: =H14 -> 5556.5177 | I18: =I14 -> 6305.2056 | J18: =J14 -> 7197.2503 | K18: =K14 -> 8266.4117
B19: NOPAT | C19: =C17+C18 -> 16451.96 | D19: =D17+D18 -> 22196.23 | E19: =E17+E18 -> 22117.31 | F19: =F17+F18 -> 21842.21 | G19: =G17+G18 -> 22926.319 | H19: =H17+H18 -> 26178.007 | I19: =I17+I18 -> 29705.244 | J19: =J17+J18 -> 33907.867 | K19: =K17+K18 -> 38944.927
B20: Less: Capex | C20: =-'Cash Flow'!V14 -> 3244 | D20: =-'Cash Flow'!W14 -> 2602 | E20: =-'Cash Flow'!X14 -> 11559 | F20: =-'Cash Flow'!Y14 -> 23350 | G20: =G12*0.23 -> 14055.141 | H20: =H12*0.23 -> 16048.611 | I20: =I12*0.23 -> 18211.009 | J20: =J12*0.23 -> 20787.457 | K20: =K12*0.23 -> 23875.462
B21: Less: Net Change in Working Capital | C21: =C51 -> 3214 | D21: ='Cash Flow'!V10 -> 2897 | E21: ='Cash Flow'!W10 -> -2261 | F21: ='Cash Flow'!X10 -> -531 | G21: =G51 -> 1930.7751 | H21: =H51 -> 2057.1006 | I21: =I51 -> 2231.4203 | J21: =J51 -> 2658.687 | K21: =K51 -> 3186.573
B22: Free Cash Flow to the Firm | C22: =C19-C20-C21 -> 9993.96 | D22: =D19-D20-D21 -> 16697.23 | E22: =E19-E20-E21 -> 12819.31 | F22: =F19-F20-F21 -> -976.79 | G22: =(G19-G20)-G21 -> 6940.4025 | H22: =H19-H20-H21 -> 8072.2945 | I22: =I19-I20-I21 -> 9262.8144 | J22: =J19-J20-J21 -> 10461.723 | K22: =K19-K20-K21 -> 11882.892
B23: Discount Rate (r)
B24: PV of Free Cash Flows | G24: =G22/(1+$D$43)^G10 -> 6128.9387 | H24: =H22/(1+$D$43)^H10 -> 6295.0365 | I24: =I22/(1+$D$43)^I10 -> 6378.886 | J24: =J22/(1+$D$43)^J10 -> 6362.1767 | K24: =K22/(1+$D$43)^K10 -> 6381.5369
B26: WACC | F26: Sum of PV of FCFF | G26: =SUM(G24:K24) -> 31546.575 | I26: Market Cap. In Cr.
B27: WACC = (% Equity x Cost of Equity) + (% Debt x Cost of Debt x (1 -Tax rate)) | I27: =D37 -> 445476.45
B28: Cost of Equity = Risk Free Rate + (Beta x (Expected Market Return - Risk Free Rate)) | F28: Terminal Value
F29: Terminal Growth Rate | G29: 0.07 | I29: Intrincsic Value in Cr.
B30: Cost of Debt | F30: Terminal Value | G30: =K22*(1+G29)/(D43-G29) -> 203765.28 | I30: =G40 -> 93282.798
B31: Debt | D31: ='Balance Sheet'!Y6 -> 54670 | F31: PV of Terminal Value | G31: =G30/(1+D43)^K10 -> 109429.22
B32: % Debt | D32: =D31/(D31+D37) -> 0.10930798 | I32: Current Market Price
B33: Cost of Debt | D33: 0.062 | F33: Enterprise Value 1 + 2 | I33: =C6 -> 231
B34: Tax Rate | D34: 0.2 | F34: Enterprise Value | G34: =G31+G26 -> 140975.8
F35: Add: Cash | G35: ='Balance Sheet'!Y24 -> 6926 | I35: Implied Share Price
B36: Cost of Equity | D36: =D39+D40*(D41-D39) -> 0.14256 | F36: Add: Other Non Operating Assets | G36: ='Balance Sheet'!Y20 -> 1516 | I36: =G42 -> 241.85701
B37: Equity | D37: =C6*'Data Sheet'!K71 -> 445476.45 | F37: Less: Debt | G37: =D31 -> 54670
B38: % Equity | D38: =D37/(D31+D37) -> 0.89069202 | F38: Less: Minority Interest | G38: ='Balance Sheet'!Y13 -> 1465 | J38: WACC
B39: Risk Free Rate | D39: 0.0731 | I39: =G42 -> 241.85701 | J39: =K39-0.5% -> 0.11739873 | K39: =L39-0.5% -> 0.12239873 | L39: =M39-0.5% -> 0.12739873 | M39: 0.13239873 | N39: =M39+0.5% -> 0.13739873 | O39: =N39+0.5% -> 0.14239873 | P39: =O39+0.5% -> 0.14739873
B40: Beta | D40: 1.15 | F40: Equity Value (DCF) | G40: =G34+G35+G36-G37-G38 -> 93282.798 | I40: =I42-0.5% -> 0.065 | J40: 320.98449 | K40: 281.27804 | L40: 247.95042 | M40: 219.58167 | N40: 195.14408 | O40: 173.8755 | P40: 155.19881
B41: Market Return | D41: 0.1335 | F41: No of shares | G41: ='Data Sheet'!K57/10 -> 385.694 | I41: =I42-0.5% -> 0.065 | J41: 320.98449 | K41: 281.27804 | L41: 247.95042 | M41: 219.58167 | N41: 195.14408 | O41: 173.8755 | P41: 155.19881
F42: Value Per Share | G42: =G40/G41 -> 241.85701 | H42: TGR | I42: 0.07 | J42: 360.77038 | K42: 313.55091 | L42: 274.57368 | M42: 241.85701 | N42: 214.00729 | O42: 190.01588 | P42: 169.13479
B43: WACC | D43: =(D36*D38)+(D33*D32)*(1-D34) -> 0.13239873 | F43: CMP | G43: =C6 -> 231 | I43: =I42+0.5% -> 0.075 | J43: 409.94002 | K43: 352.63258 | L43: 306.27782 | M43: 268.01316 | N43: 235.89351 | O43: 208.55102 | P43: 184.99566
F44: OV/UV By | G44: =G42/G43-1 -> 0.047000048 | I44: 0.06766 | J44: 341.15481 | K44: 297.71325 | L44: 261.5592 | M44: 231.00381 | N44: 204.84259 | O44: 182.19334 | P44: 162.39519
B46: Change in Working Capital Calculation | C46: 2023 | D46: =C46+1 -> 2024 | E46: =D46+1 -> 2025 | F46: =E46+1 -> 2026 | G46: =F46+1 -> 2027 | H46: =G46+1 -> 2028 | I46: =H46+1 -> 2029 | J46: =I46+1 -> 2030 | K46: =J46+1 -> 2031
B47: Debtors/Receivables | C47: ='Balance Sheet'!V23 -> 11529 | D47: ='Balance Sheet'!W23 -> 11677 | E47: ='Balance Sheet'!X23 -> 13022 | F47: ='Balance Sheet'!Y23 -> 11791 | G47: - | H47: - | I47: - | J47: - | K47: -
...

Sheet Profit & Loss
A1: ='Data Sheet'!B1 -> ADANI POWER LTD | H1: =UPDATE | M1: SCREENER.IN
A3: Narration | B3: ='Data Sheet'!B16 -> 42825 | C3: ='Data Sheet'!C16 -> 43190 | D3: ='Data Sheet'!D16 -> 43555 | E3: ='Data Sheet'!E16 -> 43921 | F3: ='Data Sheet'!F16 -> 44286 | G3: ='Data Sheet'!G16 -> 44651 | H3: ='Data Sheet'!H16 -> 45016 | I3: ='Data Sheet'!I16 -> 45382 | ... K3: ='Data Sheet'!K16 -> 46112 | L3: Trailing | M3: Best Case | N3: Worst Case
A4: Sales | B4: ='Data Sheet'!B17 -> 22615.51 | C4: ='Data Sheet'!C17 -> 20304.28 | D4: ='Data Sheet'!D17 -> 23884.18 | E4: ='Data Sheet'!E17 -> 26467.72 | F4: ='Data Sheet'!F17 -> 26221.48 | G4: ='Data Sheet'!G17 -> 27711.18 | H4: ='Data Sheet'!H17 -> 38773.3 | I4: ='Data Sheet'!I17 -> 50351.25 | ... K4: ='Data Sheet'!K17 -> 54240.52 | L4: =SUM(Quarters!H4:K4) -> 54240.52 | M4: =$K4+M23*K4 -> 60662.579 | N4: =$K4+N23*L4 -> 54240.52
A5: Expenses | B5: =SUM('Data Sheet'!B18,'Data Sheet'!B20:B24, -1*'Data Sheet'!B19) -> 16635.47 | C5: =SUM('Data Sheet'!C18,'Data Sheet'!C20:C24, -1*'Data Sheet'!C19) -> 14868.35 | D5: =SUM('Data Sheet'!D18,'Data Sheet'!D20:D24, -1*'Data Sheet'!D19) -> 18900.77 | E5: =SUM('Data Sheet'!E18,'Data Sheet'!E20:E24, -1*'Data Sheet'!E19) -> 20734.08 | F5: =SUM('Data Sheet'!F18,'Data Sheet'!F20:F24, -1*'Data Sheet'!F19) -> 17533.32 | G5: =SUM('Data Sheet'!G18,'Data Sheet'!G20:G24, -1*'Data Sheet'!G19) -> 17829.77 | H5: =SUM('Data Sheet'!H18,'Data Sheet'!H20:H24, -1*'Data Sheet'!H19) -> 28676.96 | I5: =SUM('Data Sheet'!I18,'Data Sheet'!I20:I24, -1*'Data Sheet'!I19) -> 32123.63 | ... K5: =SUM('Data Sheet'!K18,'Data Sheet'!K20:K24, -1*'Data Sheet'!K19) -> 34434.41 | L5: =SUM(Quarters!H5:K5) -> 34434.41 | M5: =M4-M6 -> 38233.284 | N5: =N4-N6 -> 36995.58
A6: Operating Profit | B6: =B4-B5 -> 5980.04 | C6: =C4-C5 -> 5435.93 | D6: =D4-D5 -> 4983.41 | E6: =E4-E5 -> 5733.64 | F6: =F4-F5 -> 8688.16 | G6: =G4-G5 -> 9881.41 | H6: =H4-H5 -> 10096.34 | I6: =I4-I5 -> 18227.62 | ... K6: =K4-K5 -> 19806.11 | L6: =SUM(Quarters!H6:K6) -> 19806.11 | M6: =M4*M24 -> 22429.295 | N6: =N4*N24 -> 17244.94
A7: Other Income | B7: ='Data Sheet'!B25 -> -3666.12 | C7: ='Data Sheet'!C25 -> 754.1 | D7: ='Data Sheet'!D25 -> 2447.87 | E7: ='Data Sheet'!E25 -> 322.76 | F7: ='Data Sheet'!F25 -> 1908.56 | G7: ='Data Sheet'!G25 -> 3908.04 | H7: ='Data Sheet'!H25 -> 4215.54 | I7: ='Data Sheet'!I25 -> 9883.31 | ... K7: ='Data Sheet'!K25 -> 3624.76 | L7: =SUM(Quarters!H7:K7) -> 3624.76 | M7: 0 | N7: 0
A8: Depreciation | B8: ='Data Sheet'!B26 -> 2672.36 | C8: ='Data Sheet'!C26 -> 2698.72 | D8: ='Data Sheet'!D26 -> 2750.62 | E8: ='Data Sheet'!E26 -> 3006.5 | F8: ='Data Sheet'!F26 -> 3201.65 | G8: ='Data Sheet'!G26 -> 3117.54 | H8: ='Data Sheet'!H26 -> 3303.68 | I8: ='Data Sheet'!I26 -> 3931.33 | ... K8: ='Data Sheet'!K26 -> 4564.53 | L8: =SUM(Quarters!H8:K8) -> 4564.53 | M8: =+$L8 -> 4564.53 | N8: =+$L8 -> 4564.53
A9: Interest | B9: ='Data Sheet'!B27 -> 5901.73 | C9: ='Data Sheet'!C27 -> 5570.23 | D9: ='Data Sheet'!D27 -> 5656.52 | E9: ='Data Sheet'!E27 -> 5314.82 | F9: ='Data Sheet'!F27 -> 5106.33 | G9: ='Data Sheet'!G27 -> 4094.78 | H9: ='Data Sheet'!H27 -> 3333.5 | I9: ='Data Sheet'!I27 -> 3388.09 | ... K9: ='Data Sheet'!K27 -> 3366.83 | L9: =SUM(Quarters!H9:K9) -> 3366.83 | M9: =+$L9 -> 3366.83 | N9: =+$L9 -> 3366.83
A10: Profit before tax | B10: ='Data Sheet'!B28 -> -6260.17 | C10: ='Data Sheet'!C28 -> -2078.92 | D10: ='Data Sheet'!D28 -> -975.86 | E10: ='Data Sheet'!E28 -> -2264.92 | F10: ='Data Sheet'!F28 -> 2288.74 | G10: ='Data Sheet'!G28 -> 6577.13 | H10: ='Data Sheet'!H28 -> 7674.7 | I10: ='Data Sheet'!I28 -> 20791.51 | ... K10: ='Data Sheet'!K28 -> 15499.51 | L10: =SUM(Quarters!H10:K10) -> 15499.51 | M10: =M6+M7-SUM(M8:M9) -> 14497.935 | N10: =N6+N7-SUM(N8:N9) -> 9313.5797
A11: Tax | B11: ='Data Sheet'!B29 -> -86.07 | C11: ='Data Sheet'!C29 -> -5.15 | D11: ='Data Sheet'!D29 -> 8.54 | E11: ='Data Sheet'!E29 -> 9.85 | F11: ='Data Sheet'!F29 -> 1018.76 | G11: ='Data Sheet'!G29 -> 1665.55 | H11: ='Data Sheet'!H29 -> -3051.94 | I11: ='Data Sheet'!I29 -> -37.28 | ... K11: ='Data Sheet'!K29 -> 2528.43 | L11: =SUM(Quarters!H11:K11) -> 2528.43 | M11: =IF($L10>0,$L11/$L10,0) -> 0.16312967 | N11: =IF($L10>0,$L11/$L10,0) -> 0.16312967
A12: Net profit | B12: ='Data Sheet'!B30 -> -6174.1 | C12: ='Data Sheet'!C30 -> -2102.95 | D12: ='Data Sheet'!D30 -> -984.4 | E12: ='Data Sheet'!E30 -> -2274.77 | F12: ='Data Sheet'!F30 -> 1269.98 | G12: ='Data Sheet'!G30 -> 4911.58 | H12: ='Data Sheet'!H30 -> 10726.64 | I12: ='Data Sheet'!I30 -> 20828.79 | ... K12: ='Data Sheet'!K30 -> 12834.3 | L12: =SUM(Quarters!H12:K12) -> 12834.3 | M12: =M10-M11*M10 -> 12132.891 | N12: =N10-N11*N10 -> 7794.2585
A13: EPS | B13: =IF('Data Sheet'!B93>0,B12/'Data Sheet'!B93,0) -> -3.2015536 | C13: =IF('Data Sheet'!C93>0,C12/'Data Sheet'!C93,0) -> -1.0904759 | D13: =IF('Data Sheet'!D93>0,D12/'Data Sheet'!D93,0) -> -0.51045648 | E13: =IF('Data Sheet'!E93>0,E12/'Data Sheet'!E93,0) -> -1.1795724 | F13: =IF('Data Sheet'!F93>0,F12/'Data Sheet'!F93,0) -> 0.65854278 | G13: =IF('Data Sheet'!G93>0,G12/'Data Sheet'!G93,0) -> 2.5468791 | H13: =IF('Data Sheet'!H93>0,H12/'Data Sheet'!H93,0) -> 5.562254 | I13: =IF('Data Sheet'!I93>0,I12/'Data Sheet'!I93,0) -> 10.800681 | ... K13: =IF('Data Sheet'!K93>0,K12/'Data Sheet'!K93,0) -> 6.6551722 | L13: =IF('Data Sheet'!$B6>0,'Profit & Loss'!L12/'Data Sheet'!$B6,0) -> 6.6551743 | M13: =IF('Data Sheet'!$B6>0,'Profit & Loss'!M12/'Data Sheet'!$B6,0) -> 6.2914617 | N13: =IF('Data Sheet'!$B6>0,'Profit & Loss'!N12/'Data Sheet'!$B6,0) -> 4.0416812
A14: Price to earning | B14: =IF(B15>0,B15/B13,"") -> -2.4925399 | C14: =IF(C15>0,C15/C13,"") -> -4.3467262 | D14: =IF(D15>0,D15/D13,"") -> -18.885058 | E14: =IF(E15>0,E15/E13,"") -> -4.7050948 | F14: =IF(F15>0,F15/F13,"") -> 25.829757 | G14: =IF(G15>0,G15/G13,"") -> 14.535437 | H14: =IF(H15>0,H15/H13,"") -> 6.8892934 | I14: =IF(I15>0,I15/I13,"") -> 9.8845616 | ... K14: =IF(K15>0,K15/K13,"") -> 22.603472 | L14: =IF(L13>0,L15/L13,0) -> 34.642218 | M14: =M25 -> 34.642218 | N14: =N25 -> 17.289465
A15: Price | B15: ='Data Sheet'!B90 -> 7.98 | C15: ='Data Sheet'!C90 -> 4.74 | D15: ='Data Sheet'!D90 -> 9.64 | E15: ='Data Sheet'!E90 -> 5.55 | F15: ='Data Sheet'!F90 -> 17.01 | G15: ='Data Sheet'!G90 -> 37.02 | H15: ='Data Sheet'!H90 -> 38.32 | I15: ='Data Sheet'!I90 -> 106.76 | ... K15: ='Data Sheet'!K90 -> 150.43 | L15: ='Data Sheet'!B8 -> 230.55 | M15: =M13*M14 -> 217.95019 | N15: =N13*N14 -> 69.878507
A17: RATIOS:
A18: Dividend Payout | B18: =IF('Data Sheet'!B30>0, 'Data Sheet'!B31/'Data Sheet'!B30, 0) -> 0 | C18: =IF('Data Sheet'!C30>0, 'Data Sheet'!C31/'Data Sheet'!C30, 0) -> 0 | D18: =IF('Data Sheet'!D30>0, 'Data Sheet'!D31/'Data Sheet'!D30, 0) -> 0 | E18: =IF('Data Sheet'!E30>0, 'Data Sheet'!E31/'Data Sheet'!E30, 0) -> 0 | F18: =IF('Data Sheet'!F30>0, 'Data Sheet'!F31/'Data Sheet'!F30, 0) -> 0 | G18: =IF('Data Sheet'!G30>0, 'Data Sheet'!G31/'Data Sheet'!G30, 0) -> 0 | H18: =IF('Data Sheet'!H30>0, 'Data Sheet'!H31/'Data Sheet'!H30, 0) -> 0 | I18: =IF('Data Sheet'!I30>0, 'Data Sheet'!I31/'Data Sheet'!I30, 0) -> 0 | ... K18: =IF('Data Sheet'!K30>0, 'Data Sheet'!K31/'Data Sheet'!K30, 0) -> 0
A19: OPM | B19: =IF(B6>0,B6/B4,0) -> 0.26442207 | C19: =IF(C6>0,C6/C4,0) -> 0.26772336 | D19: =IF(D6>0,D6/D4,0) -> 0.20864899 | E19: =IF(E6>0,E6/E4,0) -> 0.21662765 | F19: =IF(F6>0,F6/F4,0) -> 0.33133751 | G19: =IF(G6>0,G6/G4,0) -> 0.35658568 | H19: =IF(H6>0,H6/H4,0) -> 0.26039414 | I19: =IF(I6>0,I6/I4,0) -> 0.36200928 | ... L19: =IF(L6>0,L6/L4,0) -> 0.36515339
G22: TRENDS: | H22: 10 YEARS | I22: 7 YEARS | J22: 5 YEARS | K22: 3 YEARS | L22: RECENT | M22: BEST | N22: WORST
G23: Sales Growth | H23: =IF(B4=0,"",POWER($K4/B4,1/9)-1) -> 0.10207982 | I23: =IF(D4=0,"",POWER($K4/D4,1/7)-1) -> 0.12431407 | J23: =IF(F4=0,"",POWER($K4/F4,1/5)-1) -> 0.15646722 | K23: =IF(H4=0,"",POWER($K4/H4, 1/3)-1) -> 0.11839966 | L23: =IF(ISERROR(MAX(IF(J4=0,"",(K4-J4)/J4),IF(K4=0,"",(L4-K4)/K4))),"",MAX(IF(J4=0,"",(K4-J4)/J4),IF(K4=0,"",(L4-K4)/K4))) -> 1.3414248e-16 | M23: =MAX(K23:L23) -> 0.11839966 | N23: =MIN(H23:L23) -> 1.3414248e-16
G24: OPM | H24: =IF(SUM(B4:$K$4)=0,"",SUMPRODUCT(B19:$K$19,B4:$K$4)/SUM(B4:$K$4)) -> 0.31793463 | I24: =IF(SUM(E4:$K$4)=0,"",SUMPRODUCT(E19:$K$19,E4:$K$4)/SUM(E4:$K$4)) -> 0.33522199 | J24: =IF(SUM(G4:$K$4)=0,"",SUMPRODUCT(G19:$K$19,G4:$K$4)/SUM(G4:$K$4)) -> 0.349481 | K24: =IF(SUM(I4:$K$4)=0, "", SUMPRODUCT(I19:$K$19,I4:$K$4)/SUM(I4:$K$4)) -> 0.36973856 | L24: =L19 -> 0.36515339 | M24: =MAX(K24:L24) -> 0.36973856 | N24: =MIN(H24:L24) -> 0.31793463
G25: Price to Earning | H25: =IF(ISERROR(AVERAGEIF(B14:$L14,">0")),"",AVERAGEIF(B14:$L14,">0")) -> 18.509507 | I25: =IF(ISERROR(AVERAGEIF(E14:$L14,">0")),"",AVERAGEIF(E14:$L14,">0")) -> 18.509507 | J25: =IF(ISERROR(AVERAGEIF(G14:$L14,">0")),"",AVERAGEIF(G14:$L14,">0")) -> 17.289465 | K25: =IF(ISERROR(AVERAGEIF(I14:$L14,">0")),"",AVERAGEIF(I14:$L14,">0")) -> 20.578016 | L25: =L14 -> 34.642218 | M25: =MAX(K25:L25) -> 34.642218 | N25: =MIN(H25:L25) -> 17.289465

Sheet Quarters
A1: ='Profit & Loss'!A1 -> ADANI POWER LTD | E1: =UPDATE | J1: SCREENER.IN
A3: Narration | B3: ='Data Sheet'!B41 -> 45291 | C3: ='Data Sheet'!C41 -> 45382 | D3: ='Data Sheet'!D41 -> 45473 | E3: ='Data Sheet'!E41 -> 45565 | F3: ='Data Sheet'!F41 -> 45657 | G3: ='Data Sheet'!G41 -> 45747 | H3: ='Data Sheet'!H41 -> 45838 | I3: ='Data Sheet'!I41 -> 45930 | ... K3: ='Data Sheet'!K41 -> 46112
A4: Sales | B4: ='Data Sheet'!B42 -> 12991.44 | C4: ='Data Sheet'!C42 -> 13363.69 | D4: ='Data Sheet'!D42 -> 14955.63 | E4: ='Data Sheet'!E42 -> 13338.88 | F4: ='Data Sheet'!F42 -> 13671.18 | G4: ='Data Sheet'!G42 -> 14237.4 | H4: ='Data Sheet'!H42 -> 14109.15 | I4: ='Data Sheet'!I42 -> 13456.84 | ... K4: ='Data Sheet'!K42 -> 14223.09
A5: Expenses | B5: ='Data Sheet'!B43 -> 8346.1 | C5: ='Data Sheet'!C43 -> 8513.95 | D5: ='Data Sheet'!D43 -> 8761.32 | E5: ='Data Sheet'!E43 -> 8063.3 | F5: ='Data Sheet'!F43 -> 8648.26 | G5: ='Data Sheet'!G43 -> 9424.77 | H5: ='Data Sheet'!H43 -> 8423.87 | I5: ='Data Sheet'!I43 -> 8306.55 | ... K5: ='Data Sheet'!K43 -> 9490.62
A6: Operating Profit | B6: ='Data Sheet'!B50 -> 4645.34 | C6: ='Data Sheet'!C50 -> 4849.74 | D6: ='Data Sheet'!D50 -> 6194.31 | E6: ='Data Sheet'!E50 -> 5275.58 | F6: ='Data Sheet'!F50 -> 5022.92 | G6: ='Data Sheet'!G50 -> 4812.63 | H6: ='Data Sheet'!H50 -> 5685.28 | I6: ='Data Sheet'!I50 -> 5150.29 | ... K6: ='Data Sheet'!K50 -> 4732.47
A7: Other Income | B7: ='Data Sheet'!B44 -> 363.83 | C7: ='Data Sheet'!C44 -> 517.83 | D7: ='Data Sheet'!D44 -> 518.32 | E7: ='Data Sheet'!E44 -> 723.96 | F7: ='Data Sheet'!F44 -> 1162.26 | G7: ='Data Sheet'!G44 -> 298.2 | H7: ='Data Sheet'!H44 -> 464.55 | I7: ='Data Sheet'!I44 -> 850.95 | ... K7: ='Data Sheet'!K44 -> 1766
A8: Depreciation | B8: ='Data Sheet'!B45 -> 1002.23 | C8: ='Data Sheet'!C45 -> 990.03 | D8: ='Data Sheet'!D45 -> 995.63 | E8: ='Data Sheet'!E45 -> 1058.59 | F8: ='Data Sheet'!F45 -> 1170.01 | G8: ='Data Sheet'!G45 -> 1084.65 | H8: ='Data Sheet'!H45 -> 1088.59 | I8: ='Data Sheet'!I45 -> 1193.41 | ... K8: ='Data Sheet'!K45 -> 1147.23
A9: Interest | B9: ='Data Sheet'!B46 -> 796.56 | C9: ='Data Sheet'!C46 -> 819.6 | D9: ='Data Sheet'!D46 -> 811.49 | E9: ='Data Sheet'!E46 -> 806.87 | F9: ='Data Sheet'!F46 -> 956.53 | G9: ='Data Sheet'!G46 -> 764.9 | H9: ='Data Sheet'!H46 -> 856.93 | I9: ='Data Sheet'!I46 -> 841.63 | ... K9: ='Data Sheet'!K46 -> 967.26
A10: Profit before tax | B10: ='Data Sheet'!B47 -> 3210.38 | C10: ='Data Sheet'!C47 -> 3557.94 | D10: ='Data Sheet'!D47 -> 4905.51 | E10: ='Data Sheet'!E47 -> 4134.08 | F10: ='Data Sheet'!F47 -> 4058.64 | G10: ='Data Sheet'!G47 -> 3261.28 | H10: ='Data Sheet'!H47 -> 4204.31 | I10: ='Data Sheet'!I47 -> 3966.2 | ... K10: ='Data Sheet'!K47 -> 4383.98
A11: Tax | B11: ='Data Sheet'!B48 -> 472.42 | C11: ='Data Sheet'!C48 -> 820.7 | D11: ='Data Sheet'!D48 -> 992.72 | E11: ='Data Sheet'!E48 -> 836.56 | F11: ='Data Sheet'!F48 -> 1118.57 | G11: ='Data Sheet'!G48 -> 662.05 | H11: ='Data Sheet'!H48 -> 899.18 | I11: ='Data Sheet'!I48 -> 1059.74 | ... K11: ='Data Sheet'!K48 -> 112.58
A12: Net profit | B12: ='Data Sheet'!B49 -> 2737.96 | C12: ='Data Sheet'!C49 -> 2737.24 | D12: ='Data Sheet'!D49 -> 3912.79 | E12: ='Data Sheet'!E49 -> 3331.8 | F12: ='Data Sheet'!F49 -> 3057.21 | G12: ='Data Sheet'!G49 -> 2636.97 | H12: ='Data Sheet'!H49 -> 3384.86 | I12: ='Data Sheet'!I49 -> 2952.78 | ... K12: ='Data Sheet'!K49 -> 4017.08
A14: OPM | B14: =IF(B4>0,B6/B4,"") -> 0.35756929 | C14: =IF(C4>0,C6/C4,"") -> 0.36290426 | D14: =IF(D4>0,D6/D4,"") -> 0.41417914 | E14: =IF(E4>0,E6/E4,"") -> 0.39550397 | F14: =IF(F4>0,F6/F4,"") -> 0.3674094 | G14: =IF(G4>0,G6/G4,"") -> 0.33802731 | H14: =IF(H4>0,H6/H4,"") -> 0.40294986 | I14: =IF(I4>0,I6/I4,"") -> 0.38272655 | ... K14: =IF(K4>0,K6/K4,"") -> 0.3327315

Sheet Balance Sheet
A1: ='Profit & Loss'!A1 -> ADANI POWER LTD | E1: =UPDATE | J1: SCREENER.IN | U1: =U23+U22-U14 -> 8311
A3: Narration | B3: ='Data Sheet'!B56 -> 42825 | C3: ='Data Sheet'!C56 -> 43190 | D3: ='Data Sheet'!D56 -> 43555 | E3: ='Data Sheet'!E56 -> 43921 | F3: ='Data Sheet'!F56 -> 44286 | G3: ='Data Sheet'!G56 -> 44651 | H3: ='Data Sheet'!H56 -> 45016 | I3: ='Data Sheet'!I56 -> 45382 | ... K3: ='Data Sheet'!K56 -> 46112 | N3: 42064 | O3: 42430 | P3: 42795 | Q3: 43160 | R3: 43525 | S3: 43891 | T3: 44256 | U3: 44621 | V3: 44986 | W3: 45352 | X3: 45717 | Y3: 46082
A4: Equity Share Capital | B4: ='Data Sheet'!B57 -> 3856.94 | C4: ='Data Sheet'!C57 -> 3856.94 | D4: ='Data Sheet'!D57 -> 3856.94 | E4: ='Data Sheet'!E57 -> 3856.94 | F4: ='Data Sheet'!F57 -> 3856.94 | G4: ='Data Sheet'!G57 -> 3856.94 | H4: ='Data Sheet'!H57 -> 3856.94 | I4: ='Data Sheet'!I57 -> 3856.94 | ... K4: ='Data Sheet'!K57 -> 3856.94 | M4: Equity Capital | N4: 2872 | O4: 3334 | P4: 3857 | Q4: 3857 | R4: 3857 | S4: 3857 | T4: 3857 | U4: 3857 | V4: 3857 | W4: 3857 | X4: 3857 | Y4: 3857
A5: Reserves | B5: ='Data Sheet'!B58 -> -857.38 | C5: ='Data Sheet'!C58 -> -2967.61 | D5: ='Data Sheet'!D58 -> 3855.35 | E5: ='Data Sheet'!E58 -> 2623.5 | F5: ='Data Sheet'!F58 -> 9255.65 | G5: ='Data Sheet'!G58 -> 14599.95 | H5: ='Data Sheet'!H58 -> 26018.72 | I5: ='Data Sheet'!I58 -> 39041.54 | ... K5: ='Data Sheet'!K58 -> 61079.94 | M5: Reserves | N5: 2853 | O5: 4134 | P5: -857 | Q5: -2968 | R5: 3855 | S5: 2624 | T5: 9256 | U5: 14600 | V5: 26019 | W5: 39042 | X5: 52490 | Y5: 61080
A6: Borrowings | B6: ='Data Sheet'!B59 -> 52484.37 | C6: ='Data Sheet'!C59 -> 52834.81 | D6: ='Data Sheet'!D59 -> 46979.7 | E6: ='Data Sheet'!E59 -> 55198.76 | F6: ='Data Sheet'!F59 -> 52411.27 | G6: ='Data Sheet'!G59 -> 49144.98 | H6: ='Data Sheet'!H59 -> 42349.53 | I6: ='Data Sheet'!I59 -> 34862.11 | ... K6: ='Data Sheet'!K59 -> 54670.29 | M6: Borrowings - | N6: 44742 | O6: 52729 | P6: 52484 | Q6: 52835 | R6: 46980 | S6: 55199 | T6: 52411 | U6: 49145 | V6: 42350 | W6: 34862 | X6: 39495 | Y6: 54670
A7: Other Liabilities | B7: ='Data Sheet'!B60 -> 16027.12 | C7: ='Data Sheet'!C60 -> 15803.93 | D7: ='Data Sheet'!D60 -> 13292.61 | E7: ='Data Sheet'!E60 -> 13345.8 | F7: ='Data Sheet'!F60 -> 13011.61 | G7: ='Data Sheet'!G60 -> 14379.15 | H7: ='Data Sheet'!H60 -> 13596.08 | I7: ='Data Sheet'!I60 -> 14248.38 | ... K7: ='Data Sheet'!K60 -> 21861.36 | M7: Long term Borrowings | N7: 35090 | O7: 35418 | P7: 36651 | Q7: 34560 | R7: 36410 | S7: 44566 | T7: 39957 | U7: 37871 | V7: 33703 | W7: 26595 | X7: 27647 | Y7: 42830
A8: Total | B8: ='Data Sheet'!B61 -> 71511.05 | C8: ='Data Sheet'!C61 -> 69528.07 | D8: ='Data Sheet'!D61 -> 67984.6 | E8: ='Data Sheet'!E61 -> 75025 | F8: ='Data Sheet'!F61 -> 78535.47 | G8: ='Data Sheet'!G61 -> 81981.02 | H8: ='Data Sheet'!H61 -> 85821.27 | I8: ='Data Sheet'!I61 -> 92008.97 | ... K8: ='Data Sheet'!K61 -> 141468.53 | M8: Short term Borrowings | N8: 6295 | O8: 13436 | P8: 12580 | Q8: 14560 | R8: 7074 | S8: 7802 | T8: 9683 | U8: 10924 | V8: 8549 | W8: 7862 | X8: 10688 | Y8: 10726
M9: Lease Liabilities | N9: 0 | O9: 0 | P9: 0 | Q9: 0 | R9: 0 | S9: 0 | T9: 0 | U9: 103 | V9: 97 | W9: 159 | X9: 1160 | Y9: 1115
A10: Net Block | B10: ='Data Sheet'!B62 -> 54390.93 | C10: ='Data Sheet'!C62 -> 52137.14 | D10: ='Data Sheet'!D62 -> 50418.76 | E10: ='Data Sheet'!E62 -> 55845.81 | F10: ='Data Sheet'!F62 -> 52851.3 | G10: ='Data Sheet'!G62 -> 53274.21 | H10: ='Data Sheet'!H62 -> 51451.38 | I10: ='Data Sheet'!I62 -> 63015.85 | ... K10: ='Data Sheet'!K62 -> 69401.46 | M10: Preference Capital | N10: 0 | O10: 0 | P10: 0 | Q10: 0 | R10: 0 | S10: 76 | T10: 88 | U10: 401 | V10: 169 | W10: 431 | X10: 139 | Y10: 152
A11: Capital Work in Progress | B11: ='Data Sheet'!B63 -> 124.61 | C11: ='Data Sheet'!C63 -> 119.86 | D11: ='Data Sheet'!D63 -> 350.08 | E11: ='Data Sheet'!E63 -> 2346.77 | F11: ='Data Sheet'!F63 -> 6439.42 | G11: ='Data Sheet'!G63 -> 10269.74 | H11: ='Data Sheet'!H63 -> 12879.54 | I11: ='Data Sheet'!I63 -> 925.12 | ... K11: ='Data Sheet'!K63 -> 35053.46 | M11: Other Borrowings | N11: 3357 | O11: 3876 | P11: 3254 | Q11: 3715 | R11: 3496 | S11: 2754 | T11: 2683 | U11: -154 | V11: -169 | W11: -184 | X11: -139 | Y11: -152
A12: Investments | B12: ='Data Sheet'!B64 -> 164.33 | C12: ='Data Sheet'!C64 -> 0.01 | D12: ='Data Sheet'!D64 -> 2.72 | E12: ='Data Sheet'!E64 -> 2.8 | F12: ='Data Sheet'!F64 -> 20.1 | G12: ='Data Sheet'!G64 -> 183.25 | H12: ='Data Sheet'!H64 -> 654.05 | I12: ='Data Sheet'!I64 -> 373.51 | ... K12: ='Data Sheet'!K64 -> 1515.99 | M12: Other Liabilities - | N12: 8008 | O12: 15597 | P12: 16027 | Q12: 15804 | R12: 13293 | S12: 13346 | T12: 13012 | U12: 14379 | V12: 13596 | W12: 14248 | X12: 17076 | Y12: 21861
A13: Other Assets | B13: ='Data Sheet'!B65 -> 16831.18 | C13: ='Data Sheet'!C65 -> 17271.06 | D13: ='Data Sheet'!D65 -> 17213.04 | E13: ='Data Sheet'!E65 -> 16829.62 | F13: ='Data Sheet'!F65 -> 19224.65 | G13: ='Data Sheet'!G65 -> 18253.82 | H13: ='Data Sheet'!H65 -> 20836.3 | I13: ='Data Sheet'!I65 -> 27694.49 | ... K13: ='Data Sheet'!K65 -> 35497.62 | M13: Non controlling int | N13: 0 | O13: 0 | P13: 0 | Q13: 0 | R13: 0 | S13: 0 | T13: 0 | U13: 0 | V13: 0 | W13: 0 | X13: 1326 | Y13: 1465
A14: Total | B14: ='Data Sheet'!B66 -> 71511.05 | C14: ='Data Sheet'!C66 -> 69528.07 | D14: ='Data Sheet'!D66 -> 67984.6 | E14: ='Data Sheet'!E66 -> 75025 | F14: ='Data Sheet'!F66 -> 78535.47 | G14: ='Data Sheet'!G66 -> 81981.02 | H14: ='Data Sheet'!H66 -> 85821.27 | I14: ='Data Sheet'!I66 -> 92008.97 | ... K14: ='Data Sheet'!K66 -> 141468.53 | M14: Trade Payables | N14: 5685 | O14: 6232 | P14: 7400 | Q14: 7626 | R14: 6362 | S14: 5596 | T14: 3803 | U14: 3508 | V14: 3079 | W14: 3609 | X14: 2978 | Y14: 2841
M15: Advance from Customers | N15: 0 | O15: 660 | P15: 709 | Q15: 130 | R15: 72 | S15: 38 | T15: 753 | U15: 53 | V15: 33 | W15: 5 | X15: 21 | Y15: 116
A16: Working Capital | B16: =B13-B7 -> 804.06 | C16: =C13-C7 -> 1467.13 | D16: =D13-D7 -> 3920.43 | E16: =E13-E7 -> 3483.82 | F16: =F13-F7 -> 6213.04 | G16: =G13-G7 -> 3874.67 | H16: =H13-H7 -> 7240.22 | I16: =I13-I7 -> 13446.11 | ... K16: =K13-K7 -> 13636.26 | M16: Other liability items | N16: 2323 | O16: 8704 | P16: 7918 | Q16: 8047 | R16: 6859 | S16: 7712 | T16: 8456 | U16: 10818 | V16: 10484 | W16: 10635 | X16: 12750 | Y16: 17439
A17: Debtors | B17: ='Data Sheet'!B67 -> 7704.34 | C17: ='Data Sheet'!C67 -> 6069.81 | D17: ='Data Sheet'!D67 -> 8550.99 | E17: ='Data Sheet'!E67 -> 8366.47 | F17: ='Data Sheet'!F67 -> 11437.92 | G17: ='Data Sheet'!G67 -> 9560.92 | H17: ='Data Sheet'!H67 -> 11529.36 | I17: ='Data Sheet'!I67 -> 11677.48 | ... K17: ='Data Sheet'!K67 -> 11791.37 | M17: Total Liabilities | N17: 58474 | O17: 75794 | P17: 71511 | Q17: 69528 | R17: 67985 | S17: 75025 | T17: 78535 | U17: 81981 | V17: 85821 | W17: 92009 | X17: 112918 | Y17: 141469
A18: Inventory | B18: ='Data Sheet'!B68 -> 1760.41 | C18: ='Data Sheet'!C68 -> 873.98 | D18: ='Data Sheet'!D68 -> 1224.08 | E18: ='Data Sheet'!E68 -> 2522.77 | F18: ='Data Sheet'!F68 -> 2025.11 | G18: ='Data Sheet'!G68 -> 2258.27 | H18: ='Data Sheet'!H68 -> 3075.2 | I18: ='Data Sheet'!I68 -> 4142.1 | ... K18: ='Data Sheet'!K68 -> 3623.48 | M18: Fixed Assets + | N18: 45080 | O18: 56941 | P18: 54391 | Q18: 52137 | R18: 50419 | S18: 55846 | T18: 52851 | U18: 53274 | V18: 51451 | W18: 63016 | X18: 69297 | Y18: 69401
M19: CWIP | N19: 191 | O19: 88 | P19: 125 | Q19: 120 | R19: 350 | S19: 2347 | T19: 6439 | U19: 10270 | V19: 12880 | W19: 925 | X19: 12104 | Y19: 35053
A20: Debtor Days | B20: =IF('Profit & Loss'!B4>0,'Balance Sheet'!B17/('Profit & Loss'!B4/365),0) -> 124.34317 | C20: =IF('Profit & Loss'!C4>0,'Balance Sheet'!C17/('Profit & Loss'!C4/365),0) -> 109.11397 | D20: =IF('Profit & Loss'!D4>0,'Balance Sheet'!D17/('Profit & Loss'!D4/365),0) -> 130.67693 | E20: =IF('Profit & Loss'!E4>0,'Balance Sheet'!E17/('Profit & Loss'!E4/365),0) -> 115.37683 | F20: =IF('Profit & Loss'!F4>0,'Balance Sheet'!F17/('Profit & Loss'!F4/365),0) -> 159.21454 | G20: =IF('Profit & Loss'!G4>0,'Balance Sheet'!G17/('Profit & Loss'!G4/365),0) -> 125.93241 | H20: =IF('Profit & Loss'!H4>0,'Balance Sheet'!H17/('Profit & Loss'!H4/365),0) -> 108.53387 | I20: =IF('Profit & Loss'!I4>0,'Balance Sheet'!I17/('Profit & Loss'!I4/365),0) -> 84.650931 | ... K20: =IF('Profit & Loss'!K4>0,'Balance Sheet'!K17/('Profit & Loss'!K4/365),0) -> 79.347507 | M20: Investments | N20: 357 | O20: 0 | P20: 164 | Q20: 0 | R20: 3 | S20: 3 | T20: 20 | U20: 183 | V20: 654 | W20: 374 | X20: 1097 | Y20: 1516
A21: Inventory Turnover | B21: =IF('Balance Sheet'!B18>0,'Profit & Loss'!B4/'Balance Sheet'!B18,0) -> 12.846729 | C21: =IF('Balance Sheet'!C18>0,'Profit & Loss'!C4/'Balance Sheet'!C18,0) -> 23.231973 | D21: =IF('Balance Sheet'!D18>0,'Profit & Loss'!D4/'Balance Sheet'!D18,0) -> 19.511944 | E21: =IF('Balance Sheet'!E18>0,'Profit & Loss'!E4/'Balance Sheet'!E18,0) -> 10.491531 | F21: =IF('Balance Sheet'!F18>0,'Profit & Loss'!F4/'Balance Sheet'!F18,0) -> 12.948176 | G21: =IF('Balance Sheet'!G18>0,'Profit & Loss'!G4/'Balance Sheet'!G18,0) -> 12.270977 | H21: =IF('Balance Sheet'!H18>0,'Profit & Loss'!H4/'Balance Sheet'!H18,0) -> 12.608383 | I21: =IF('Balance Sheet'!I18>0,'Profit & Loss'!I4/'Balance Sheet'!I18,0) -> 12.155972 | ... K21: =IF('Balance Sheet'!K18>0,'Profit & Loss'!K4/'Balance Sheet'!K18,0) -> 14.969179 | M21: Other Assets - | N21: 12846 | O21: 18765 | P21: 16831 | Q21: 17271 | R21: 17213 | S21: 16830 | T21: 19225 | U21: 18254 | V21: 20836 | W21: 27694 | X21: 30418 | Y21: 35498
M22: Inventories | N22: 1629 | O22: 1619 | P22: 1760 | Q22: 874 | R22: 1224 | S22: 2523 | T22: 2025 | U22: 2258 | V22: 3075 | W22: 4142 | X22: 3317 | Y22: 3623
A23: Return on Equity | B23: =IF(SUM('Balance Sheet'!B4:B5)>0,'Profit & Loss'!B12/SUM('Balance Sheet'!B4:B5),"") -> -2.0583352 | C23: =IF(SUM('Balance Sheet'!C4:C5)>0,'Profit & Loss'!C12/SUM('Balance Sheet'!C4:C5),"") -> -2.3646453 | D23: =IF(SUM('Balance Sheet'!D4:D5)>0,'Profit & Loss'!D12/SUM('Balance Sheet'!D4:D5),"") -> -0.12764043 | E23: =IF(SUM('Balance Sheet'!E4:E5)>0,'Profit & Loss'!E12/SUM('Balance Sheet'!E4:E5),"") -> -0.35102092 | F23: =IF(SUM('Balance Sheet'!F4:F5)>0,'Profit & Loss'!F12/SUM('Balance Sheet'!F4:F5),"") -> 0.096851957 | G23: =IF(SUM('Balance Sheet'!G4:G5)>0,'Profit & Loss'!G12/SUM('Balance Sheet'!G4:G5),"") -> 0.26611092 | H23: =IF(SUM('Balance Sheet'!H4:H5)>0,'Profit & Loss'!H12/SUM('Balance Sheet'!H4:H5),"") -> 0.35904278 | I23: =IF(SUM('Balance Sheet'!I4:I5)>0,'Profit & Loss'!I12/SUM('Balance Sheet'!I4:I5),"") -> 0.48553678 | ... K23: =IF(SUM('Balance Sheet'!K4:K5)>0,'Profit & Loss'!K12/SUM('Balance Sheet'!K4:K5),"") -> 0.1976427 | M23: Trade receivables + | N23: 3490 | O23: 12477 | P23: 7704 | Q23: 6070 | R23: 8551 | S23: 8366 | T23: 11438 | U23: 9561 | V23: 11529 | W23: 11677 | X23: 13022 | Y23: 11791
A24: Return on Capital Emp | C24: =IF((B4+B5+B6+C4+C5+C6)>0,('Profit & Loss'!C10+'Profit & Loss'!C9)*2/(B4+B5+B6+C4+C5+C6),"") -> 0.063938681 | D24: =IF((C4+C5+C6+D4+D5+D6)>0,('Profit & Loss'!D10+'Profit & Loss'!D9)*2/(C4+C5+C6+D4+D5+D6),"") -> 0.086346192 | E24: =IF((D4+D5+D6+E4+E5+E6)>0,('Profit & Loss'!E10+'Profit & Loss'!E9)*2/(D4+D5+D6+E4+E5+E6),"") -> 0.052416754 | F24: =IF((E4+E5+E6+F4+F5+F6)>0,('Profit & Loss'!F10+'Profit & Loss'!F9)*2/(E4+E5+E6+F4+F5+F6),"") -> 0.11627189 | G24: =IF((F4+F5+F6+G4+G5+G6)>0,('Profit & Loss'!G10+'Profit & Loss'!G9)*2/(F4+F5+F6+G4+G5+G6),"") -> 0.16032829 | H24: =IF((G4+G5+G6+H4+H5+H6)>0,('Profit & Loss'!H10+'Profit & Loss'!H9)*2/(G4+G5+G6+H4+H5+H6),"") -> 0.1574545 | I24: =IF((H4+H5+H6+I4+I5+I6)>0,('Profit & Loss'!I10+'Profit & Loss'!I9)*2/(H4+H5+H6+I4+I5+I6),"") -> 0.32242523 | J24: =IF((I4+I5+I6+J4+J5+J6)>0,('Profit & Loss'!J10+'Profit & Loss'!J9)*2/(I4+I5+I6+J4+J5+J6),"") -> 0.22694713 | K24: =IF((J4+J5+J6+K4+K5+K6)>0,('Profit & Loss'!K10+'Profit & Loss'!K9)*2/(J4+J5+J6+K4+K5+K6),"") -> 0.17513498 | M24: Cash Equivalents | N24: 856 | O24: 869 | P24: 604 | Q24: 857 | R24: 916 | S24: 1979 | T24: 1607 | U24: 2365 | V24: 1874 | W24: 7212 | X24: 6120 | Y24: 6926
M25: Loans n Advances | N25: 33 | O25: 419 | P25: 771 | Q25: 752 | R25: 659 | S25: 880 | T25: 909 | U25: 1474 | V25: 1394 | W25: 1242 | X25: 1057 | Y25: 1479
M26: Other asset items | N26: 6838 | O26: 3382 | P26: 5991 | Q26: 8719 | R26: 5863 | S26: 3081 | T26: 3245 | U26: 2596 | V26: 2964 | W26: 3421 | X26: 6902 | Y26: 11677
M27: Total Assets | N27: 58474 | O27: 75794 | P27: 71511 | Q27: 69528 | R27: 67985 | S27: 75025 | T27: 78535 | U27: 81981 | V27: 85821 | W27: 92009 | X27: 112918 | Y27: 141469

Sheet Cash Flow
A1: ='Balance Sheet'!A1 -> ADANI POWER LTD | E1: =UPDATE | J1: SCREENER.IN
A3: Narration | B3: ='Data Sheet'!B81 -> 42825 | C3: ='Data Sheet'!C81 -> 43190 | D3: ='Data Sheet'!D81 -> 43555 | E3: ='Data Sheet'!E81 -> 43921 | F3: ='Data Sheet'!F81 -> 44286 | G3: ='Data Sheet'!G81 -> 44651 | H3: ='Data Sheet'!H81 -> 45016 | I3: ='Data Sheet'!I81 -> 45382 | ... K3: ='Data Sheet'!K81 -> 46112 | N3: 42064 | O3: 42430 | P3: 42795 | Q3: 43160 | R3: 43525 | S3: 43891 | T3: 44256 | U3: 44621 | V3: 44986 | W3: 45352 | X3: 45717 | Y3: 46082
A4: Cash from Operating Activity | B4: ='Data Sheet'!B82 -> 4725.2 | C4: ='Data Sheet'!C82 -> 5101.15 | D4: ='Data Sheet'!D82 -> 5610.38 | E4: ='Data Sheet'!E82 -> 5597.55 | F4: ='Data Sheet'!F82 -> 7014.35 | G4: ='Data Sheet'!G82 -> 10232.73 | H4: ='Data Sheet'!H82 -> 8430.53 | I4: ='Data Sheet'!I82 -> 14170.15 | ... K4: ='Data Sheet'!K82 -> 20513.65 | M4: Cash from Operating Activity - | N4: 5824 | O4: 5257 | P4: 4725 | Q4: 5101 | R4: 5610 | S4: 5598 | T4: 7014 | U4: 10233 | V4: 8431 | W4: 14170 | X4: 21501 | Y4: 20514
A5: Cash from Investing Activity | B5: ='Data Sheet'!B83 -> -1212.04 | C5: ='Data Sheet'!C83 -> -520.43 | D5: ='Data Sheet'!D83 -> -984.02 | E5: ='Data Sheet'!E83 -> -2303.81 | F5: ='Data Sheet'!F83 -> -2187.57 | G5: ='Data Sheet'!G83 -> 774.46 | H5: ='Data Sheet'!H83 -> 1544.79 | I5: ='Data Sheet'!I83 -> 3480.9 | ... K5: ='Data Sheet'!K83 -> -26460.56 | M5: Profit from operations | N5: 5591 | O5: 8460 | P5: 5463 | Q5: 5441 | R5: 5540 | S5: 6098 | T5: 8665 | U5: 10152 | V5: 9860 | W5: 18678 | X5: 21950 | Y5: 20858
A6: Cash from Financing Activity | B6: ='Data Sheet'!B84 -> -3538.93 | C6: ='Data Sheet'!C84 -> -4600.11 | D6: ='Data Sheet'!D84 -> -4663.44 | E6: ='Data Sheet'!E84 -> -2377.18 | F6: ='Data Sheet'!F84 -> -5654.84 | G6: ='Data Sheet'!G84 -> -10337.86 | H6: ='Data Sheet'!H84 -> -10408.46 | I6: ='Data Sheet'!I84 -> -16864.03 | ... K6: ='Data Sheet'!K84 -> 6554.93 | M6: Receivables | N6: -2137 | O6: -4283 | P6: -1284 | Q6: 1635 | R6: -1595 | S6: 1252 | T6: -489 | U6: 981 | V6: -2995 | W6: -1738 | X6: -342 | Y6: 1370
A7: Net Cash Flow | B7: ='Data Sheet'!B85 -> -25.77 | C7: ='Data Sheet'!C85 -> -19.39 | D7: ='Data Sheet'!D85 -> -37.08 | E7: ='Data Sheet'!E85 -> 916.56 | F7: ='Data Sheet'!F85 -> -828.06 | G7: ='Data Sheet'!G85 -> 669.33 | H7: ='Data Sheet'!H85 -> -433.14 | I7: ='Data Sheet'!I85 -> 787.02 | ... K7: ='Data Sheet'!K85 -> 608.02 | M7: Inventory | N7: -369 | O7: 158 | P7: -141 | Q7: 875 | R7: -350 | S7: -1233 | T7: 385 | U7: -262 | V7: -829 | W7: -1066 | X7: 1313 | Y7: -234
M8: Payables | N8: 1871 | O8: 285 | P8: 1241 | Q8: -26 | R8: -1447 | S8: -1105 | T8: -1489 | U8: -368 | V8: -423 | W8: 616 | X8: -880 | Y8: -182
M9: Loans Advances | N9: -156 | O9: 0 | P9: 0 | Q9: 0 | R9: 0 | S9: 0 | T9: 0 | U9: 0 | V9: 0 | W9: 0 | X9: 0 | Y9: 0
M10: Other WC items | N10: 1029 | O10: 642 | P10: -550 | Q10: -2810 | R10: 3471 | S10: 643 | T10: -53 | U10: -46 | V10: 2897 | W10: -2261 | X10: -531 | Y10: -1401
M11: Working capital changes | N11: 237 | O11: -3199 | P11: -734 | Q11: -327 | R11: 80 | S11: -443 | T11: -1645 | U11: 305 | V11: -1351 | W11: -4450 | X11: -440 | Y11: -447
M12: Direct taxes | N12: -5 | O12: -4 | P12: -4 | Q12: -13 | R12: -9 | S12: -58 | T12: -6 | U12: -224 | V12: -79 | W12: -57 | X12: -8 | Y12: 102
M13: Cash from Investing Activity - | N13: -4737 | O13: -2692 | P13: -1212 | Q13: -520 | R13: -984 | S13: -2304 | T13: -2188 | U13: 774 | V13: 1545 | W13: 3481 | X13: -17142 | Y13: -26461
M14: Fixed assets purchased | N14: -3072 | O14: -1978 | P14: -854 | Q14: -943 | R14: -962 | S14: -2227 | T14: -3618 | U14: -3435 | V14: -3244 | W14: -2602 | X14: -11559 | Y14: -23350
M15: Fixed assets sold | N15: 347 | O15: 10 | P15: 10 | Q15: 15 | R15: 3 | S15: 7 | T15: 10 | U15: 1 | V15: 1 | W15: 1 | X15: 15 | Y15: 19
M16: Investments purchased | N16: -25426 | O16: 0 | P16: -162 | Q16: 0 | R16: 0 | S16: 0 | T16: -429 | U16: -162 | V16: -458 | W16: 0 | X16: -626 | Y16: -460
M17: Investments sold | N17: 25208 | O17: 383 | P17: 0 | Q17: 172 | R17: 2 | S17: 4 | T17: 1415 | U17: 82 | V17: 0 | W17: 406 | X17: 0 | Y17: 137
M18: Interest received | N18: 197 | O18: 139 | P18: 139 | Q18: 230 | R18: 628 | S18: 126 | T18: 91 | U18: 4301 | V18: 4827 | W18: 9316 | X18: 884 | Y18: 1340
M19: Investment in group cos | N19: 0 | O19: 0 | P19: 0 | Q19: 0 | R19: 0 | S19: 0 | T19: 0 | U19: 0 | V19: 0 | W19: 0 | X19: 0 | Y19: -24
... M27: CFO/OP | N27: 1.25 | O27: 0.6 | P27: 0.79 | Q27: 0.94 | R27: 1.13 | S27: 0.99 | T27: 0.81 | U27: 1.06 | V27: 0.84 | W27: 0.78 | X27: 1 | Y27: 1.03

Sheet Customization
A1: How to use it?
A3: You can customize this workbook as you want.
B4: You can add custom formating, add conditional formating, add your own formulas… do ANYTHING.
B5: Please don't edit the "Data Sheet" only.
A7: After customization, you can upload this back on Screener.
B8: Upload on: | C8: https://www.screener.in/excel/
A10: Download your customized workbooks now onwards.
B11: Now whenever you will "Export to excel" from Screener, it will export your customized file.
A14: TESTING:
B15: This is a testing feature currently.
B16: You can report any formula errors on the worksheet at: support@screener.in

Sheet Data Sheet
A1: COMPANY NAME | B1: ADANI POWER LTD | E1: =IF(B2<>B3, "A NEW VERSION OF THE WORKSHEET IS AVAILABLE", "")
A2: LATEST VERSION | B2: 2.1 | E2: PLEASE DO NOT MAKE ANY CHANGES TO THIS SHEET
A3: CURRENT VERSION | B3: 2.1
A5: META
A6: Number of shares | B6: =IF(B9>0, B9/B8, 0) -> 1928.4694
A7: Face Value | B7: 2
A8: Current Price | B8: 230.55
A9: Market Capitalization | B9: 444608.62
A15: PROFIT & LOSS
A16: Report Date | B16: 42825 | C16: 43190 | D16: 43555 | E16: 43921 | F16: 44286 | G16: 44651 | H16: 45016 | I16: 45382 | J16: 45747 | K16: 46112
A17: Sales | B17: 22615.51 | C17: 20304.28 | D17: 23884.18 | E17: 26467.72 | F17: 26221.48 | G17: 27711.18 | H17: 38773.3 | I17: 50351.25 | J17: 56203.09 | K17: 54240.52
A18: Raw Material Cost
A19: Change in Inventory
A20: Power and Fuel | B20: 14630.49 | C20: 12535.25 | D20: 15952.45 | E20: 17580.39 | F20: 14781.15 | G20: 14762.21 | H20: 25480.85 | I20: 28452.64 | J20: 30273.25 | K20: 29168.02
A21: Other Mfr. Exp | B21: 1260.02 | C21: 1551.86 | D21: 1680.59 | E21: 1864.95 | F21: 1838.18 | G21: 2066.68 | H21: 1718.27 | I21: 1856.84 | J21: 2231.05 | K21: 2565.39
A22: Employee Cost | B22: 361.01 | C22: 353.9 | D22: 363.47 | E22: 427.04 | F22: 431.89 | G22: 470.72 | H22: 570.46 | I22: 644.17 | J22: 786.63 | K22: 857.81
A23: Selling and admin | B23: 307.25 | C23: 225.3 | D23: 222.73 | E23: 454.63 | F23: 281.14 | G23: 233.67 | H23: 443.65 | I23: 454.82 | J23: 543.57 | K23: 581.01
A24: Other Expenses | B24: 76.7 | C24: 202.04 | D24: 681.53 | E24: 407.07 | F24: 200.96 | G24: 296.49 | H24: 463.73 | I24: 715.16 | J24: 950.26 | K24: 1262.18
A25: Other Income | B25: -3666.12 | C25: 754.1 | D25: 2447.87 | E25: 322.76 | F25: 1908.56 | G25: 3908.04 | H25: 4215.54 | I25: 9883.31 | J25: 2589.85 | K25: 3624.76
A26: Depreciation | B26: 2672.36 | C26: 2698.72 | D26: 2750.62 | E26: 3006.5 | F26: 3201.65 | G26: 3117.54 | H26: 3303.68 | I26: 3931.33 | J26: 4308.88 | K26: 4564.53
A27: Interest | B27: 5901.73 | C27: 5570.23 | D27: 5656.52 | E27: 5314.82 | F27: 5106.33 | G27: 4094.78 | H27: 3333.5 | I27: 3388.09 | J27: 3339.79 | K27: 3366.83 | M27: =I27/'Balance Sheet'!Y6 -> 0.061973477
A28: Profit before tax | B28: -6260.17 | C28: -2078.92 | D28: -975.86 | E28: -2264.92 | F28: 2288.74 | G28: 6577.13 | H28: 7674.7 | I28: 20791.51 | J28: 16359.51 | K28: 15499.51
A29: Tax | B29: -86.07 | C29: -5.15 | D29: 8.54 | E29: 9.85 | F29: 1018.76 | G29: 1665.55 | H29: -3051.94 | I29: -37.28 | J29: 3609.9 | K29: 2528.43
A30: Net profit | B30: -6174.1 | C30: -2102.95 | D30: -984.4 | E30: -2274.77 | F30: 1269.98 | G30: 4911.58 | H30: 10726.64 | I30: 20828.79 | J30: 12938.77 | K30: 12834.3
A31: Dividend Amount
A40: Quarters
A41: Report Date | B41: 45291 | C41: 45382 | D41: 45473 | E41: 45565 | F41: 45657 | G41: 45747 | H41: 45838 | I41: 45930 | J41: 46022 | K41: 46112
A42: Sales | B42: 12991.44 | C42: 13363.69 | D42: 14955.63 | E42: 13338.88 | F42: 13671.18 | G42: 14237.4 | H42: 14109.15 | I42: 13456.84 | J42: 12451.44 | K42: 14223.09
A43: Expenses | B43: 8346.1 | C43: 8513.95 | D43: 8761.32 | E43: 8063.3 | F43: 8648.26 | G43: 9424.77 | H43: 8423.87 | I43: 8306.55 | J43: 8213.37 | K43: 9490.62
A44: Other Income | B44: 363.83 | C44: 517.83 | D44: 518.32 | E44: 723.96 | F44: 1162.26 | G44: 298.2 | H44: 464.55 | I44: 850.95 | J44: 543.26 | K44: 1766
A45: Depreciation | B45: 1002.23 | C45: 990.03 | D45: 995.63 | E45: 1058.59 | F45: 1170.01 | G45: 1084.65 | H45: 1088.59 | I45: 1193.41 | J45: 1135.3 | K45: 1147.23
A46: Interest | B46: 796.56 | C46: 819.6 | D46: 811.49 | E46: 806.87 | F46: 956.53 | G46: 764.9 | H46: 856.93 | I46: 841.63 | J46: 701.01 | K46: 967.26
A47: Profit before tax | B47: 3210.38 | C47: 3557.94 | D47: 4905.51 | E47: 4134.08 | F47: 4058.64 | G47: 3261.28 | H47: 4204.31 | I47: 3966.2 | J47: 2945.02 | K47: 4383.98
A48: Tax | B48: 472.42 | C48: 820.7 | D48: 992.72 | E48: 836.56 | F48: 1118.57 | G48: 662.05 | H48: 899.18 | I48: 1059.74 | J48: 456.93 | K48: 112.58
A49: Net profit | B49: 2737.96 | C49: 2737.24 | D49: 3912.79 | E49: 3331.8 | F49: 3057.21 | G49: 2636.97 | H49: 3384.86 | I49: 2952.78 | J49: 2479.58 | K49: 4017.08
A50: Operating Profit | B50: 4645.34 | C50: 4849.74 | D50: 6194.31 | E50: 5275.58 | F50: 5022.92 | G50: 4812.63 | H50: 5685.28 | I50: 5150.29 | J50: 4238.07 | K50: 4732.47
A55: BALANCE SHEET
A56: Report Date | B56: 42825 | C56: 43190 | D56: 43555 | E56: 43921 | F56: 44286 | G56: 44651 | H56: 45016 | I56: 45382 | J56: 45747 | K56: 46112
A57: Equity Share Capital | B57: 3856.94 | C57: 3856.94 | D57: 3856.94 | E57: 3856.94 | F57: 3856.94 | G57: 3856.94 | H57: 3856.94 | I57: 3856.94 | J57: 3856.94 | K57: 3856.94
A58: Reserves | B58: -857.38 | C58: -2967.61 | D58: 3855.35 | E58: 2623.5 | F58: 9255.65 | G58: 14599.95 | H58: 26018.72 | I58: 39041.54 | J58: 52490.15 | K58: 61079.94
...
