Workbook
Name UPDATE: 'Data Sheet'!$E$1

Sheet TITAN DCF
B2: TITAN Company Ltd.
B4: Ticker | C4: TITAN
B6: INR | C6: 4184
B9: Period | C9: 2023 | D9: =C9+1 -> 2024 | E9: =D9+1 -> 2025 | F9: =E9+1 -> 2026 | G9: =F9+1 -> 2027 | H9: =G9+1 -> 2028 | I9: =H9+1 -> 2029 | J9: =I9+1 -> 2030 | K9: =J9+1 -> 2031 | L9: =K9+1 -> 2032
B10: Year | G10: 1 | H10: =G10+1 -> 2 | I10: =H10+1 -> 3 | J10: =I10+1 -> 4 | K10: =J10+1 -> 5 | L10: =K10+1 -> 6
B11: Growth | D11: =D12/C12-1 -> 0.25900185 | E11: =E12/D12-1 -> 0.18346253 | F11: =F12/E12-1 -> 0.44872304 | G11: =30% -> 0.3 | H11: =G11*(1-0.1) -> 0.27 | I11: =H11*(1-0.1) -> 0.243 | J11: =I11*(1-0.1) -> 0.2187 | K11: =J11*(1-0.1) -> 0.19683 | L11: =K11*(1-0.1) -> 0.177147
B12: Revenue | C12: ='Data Sheet'!H17 -> 40575 | D12: ='Data Sheet'!I17 -> 51084 | E12: ='Data Sheet'!J17 -> 60456 | F12: ='Data Sheet'!K17 -> 87584 | G12: =F12*(1+G11) -> 113859.2 | H12: =G12*(1+H11) -> 144601.18 | I12: =H12*(1+I11) -> 179739.27 | J12: =I12*(1+J11) -> 219048.25 | K12: =J12*(1+K11) -> 262163.52 | L12: =K12*(1+L11) -> 308605
B13: EBITDA | C13: ='Data Sheet'!T19+'Data Sheet'!T21 -> 5323 | D13: ='Data Sheet'!U19+'Data Sheet'!U21 -> 5876 | E13: ='Data Sheet'!V19+'Data Sheet'!V21 -> 6387 | F13: ='Data Sheet'!W19+'Data Sheet'!W21 -> 9181 | G13: =G12*10.5% -> 11955.216 | H13: =H12*10.5% -> 15183.124 | I13: =I12*10.5% -> 18872.624 | J13: =J12*10.5% -> 23000.066 | K13: =K12*10.5% -> 27527.169 | L13: =L12*10.5% -> 32403.525
B14: Less: Depreciation & Ammortisation | C14: ='Data Sheet'!T21 -> 441 | D14: ='Data Sheet'!U21 -> 584 | E14: ='Data Sheet'!V21 -> 693 | F14: ='Data Sheet'!W21 -> 826 | G14: =G12*1% -> 1138.592 | H14: =H12*1% -> 1446.0118 | I14: =I12*1% -> 1797.3927 | J14: =J12*1% -> 2190.4825 | K14: =K12*1% -> 2621.6352 | L14: =L12*1% -> 3086.05
B15: EBIT | C15: =C13-C14 -> 4882 | D15: =D13-D14 -> 5292 | E15: =E13-E14 -> 5694 | F15: =F13-F14 -> 8355 | G15: =G12*9.95% -> 11328.99 | H15: =H12*9.95% -> 14387.818 | I15: =I12*9.95% -> 17884.058 | J15: =J12*9.95% -> 21795.301 | K15: =K12*9.95% -> 26085.27 | L15: =L12*9.95% -> 30706.197
B16: Less: Tax | C16: ='Data Sheet'!T24 -> 1173 | D16: ='Data Sheet'!U24 -> 1127 | E16: ='Data Sheet'!V24 -> 1198 | F16: ='Data Sheet'!W24 -> 1728 | G16: =G15*21.01% -> 2380.2209 | H16: =H15*21.01% -> 3022.8805 | I16: =I15*21.01% -> 3757.4405 | J16: =J15*21.01% -> 4579.1927 | K16: =K15*21.01% -> 5480.5152 | L16: =L15*21.01% -> 6451.3721
B17: EBIT(1-Tax) | C17: =C15-C16 -> 3709 | D17: =D15-D16 -> 4165 | E17: =E15-E16 -> 4496 | F17: =F15-F16 -> 6627 | G17: =G15-G16 -> 8948.7695 | H17: =H15-H16 -> 11364.937 | I17: =I15-I16 -> 14126.617 | J17: =J15-J16 -> 17216.108 | ... L17: =L15-L16 -> 24254.825
B18: Add: Depreciation & Ammortisation | C18: =C14 -> 441 | D18: =D14 -> 584 | E18: =E14 -> 693 | F18: =F14 -> 826 | G18: =G14 -> 1138.592 | H18: =H14 -> 1446.0118 | I18: =I14 -> 1797.3927 | J18: =J14 -> 2190.4825 | ... L18: =L14 -> 3086.05
B19: NOPAT | C19: =C17+C18 -> 4150 | D19: =D17+D18 -> 4749 | E19: =E17+E18 -> 5189 | F19: =F17+F18 -> 7453 | G19: =G17+G18 -> 10087.362 | H19: =H17+H18 -> 12810.949 | I19: =I17+I18 -> 15924.01 | J19: =J17+J18 -> 19406.591 | ... L19: =L17+L18 -> 27340.875
B20: Less: Capex | C20: =-'Data Sheet'!V93 -> 432 | D20: =-'Data Sheet'!W93 -> 691 | E20: =-'Data Sheet'!X93 -> 494 | F20: =-'Data Sheet'!Y93 -> 902 | G20: =G12*1.05% -> 1195.5216 | H20: =H12*1.05% -> 1518.3124 | I20: =I12*1.05% -> 1887.2624 | J20: =J12*1.05% -> 2300.0066 | K20: =K12*1.05% -> 2752.7169 | L20: =L12*1.05% -> 3240.3525
B21: Less: Net Change in Working Capital | C21: =C51 -> 3164 | D21: =D51 -> 2615 | E21: =E51 -> 8630 | F21: =F51 -> 13506 | G21: =G51 -> 7877.1016 | H21: =H51 -> 13141.467 | I21: =I51 -> 15020.697 | J21: =J51 -> 16803.654 | ... L21: =L51 -> 19852.629
B22: Free Cash Flow to the Firm | C22: =C19-C20-C21 -> 554 | D22: =D19-D20-D21 -> 1443 | E22: =E19-E20-E21 -> -3935 | F22: =F19-F20-F21 -> -6955 | G22: =G19-G20-G21 -> 1014.7383 | H22: =H19-H20-H21 -> -1848.8307 | I22: =I19-I20-I21 -> -983.94987 | J22: =J19-J20-J21 -> 302.93002 | ... L22: =L19-L20-L21 -> 4247.8937
B23: Discount Rate (r)
B24: PV of Free Cash Flows | G24: =G22/(1+$D$43)^G10 -> 903.14918 | H24: =H22/(1+$D$43)^H10 -> -1464.563 | I24: =I22/(1+$D$43)^I10 -> -693.72814 | J24: =J22/(1+$D$43)^J10 -> 190.09211 | K24: =K22/(1+$D$43)^K10 -> 1140.9821 | L24: =L22/(1+$D$43)^L10 -> 2111.574
B26: WACC | F26: Sum of PV of FCFF | G26: =SUM(G24:L24) -> 2187.5063 | I26: Market Cap. In Cr.
B27: WACC = (% Equity x Cost of Equity) + (% Debt x Cost of Debt x (1 -Tax rate)) | I27: =D37 -> 372376
B28: Cost of Equity = Risk Free Rate + (Beta x (Expected Market Return - Risk Free Rate)) | F28: Terminal Value
F29: Terminal Growth Rate | G29: 0.07 | I29: Intrinsic Value DCF
B30: Cost of Debt | F30: Terminal Value | G30: =L22*(1+$G$29)/(D43-$G$29) -> 84869.733 | I30: =G40 -> 35247.174
B31: Debt | D31: ='Data Sheet'!Y59 -> 14551 | F31: PV of Terminal Value | G31: =G30/(1+D43)^L10 -> 42187.668
B32: % Debt | D32: =D31/(D31+D37) -> 0.037606577 | I32: Current Market Price
B33: Cost of Debt | D33: ='Data Sheet'!AA22 -> 0.081094083 | F33: Enterprise Value 1 + 2 | I33: =C6 -> 4184
B34: Tax Rate | D34: 0.2115 | F34: Enterprise Value | G34: =G31+G26 -> 44375.174
F35: Add: Cash | G35: ='Data Sheet'!K69 -> 1917 | I35: Implied Share Price
B36: Cost of Equity | D36: =D39+D40*(D41-D39) -> 0.125885 | F36: Add: Other Non Operating Assets | G36: ='Data Sheet'!Y68 -> 3506 | I36: =G42 -> 396.03566
B37: Equity | D37: =(C6*'Data Sheet'!J70)/10000000 -> 372376 | F37: Less: Debt | G37: =D31 -> 14551
B38: % Equity | D38: =D37/(D31+D37) -> 0.96239342 | F38: Less: Minority Interest | G38: 0 | J38: WACC
B39: Risk Free Rate | D39: 0.0731 | I39: =G42 -> 396.03566 | J39: =K39-0.5% -> 0.10855556 | K39: =L39-0.5% -> 0.11355556 | L39: =M39-0.5% -> 0.11855556 | M39: 0.12355556 | N39: =M39+0.5% -> 0.12855556 | O39: =N39+0.5% -> 0.13355556 | P39: =O39+0.5% -> 0.13855556
B40: Beta | D40: 1.15 | F40: Equity Value (DCF) | G40: =G34+G35+G36-G37 -> 35247.174 | I40: =I41-0.5% -> 0.06 | J40: 485.8299 | K40: 419.0362 | L40: 363.92041 | M40: 317.71926 | N40: 278.47586 | O40: 244.76559 | P40: 215.52671
B41: Market Return | D41: 0.119 | F41: No of shares | G41: ='Data Sheet'!Y57 -> 89 | I41: =I42-0.5% -> 0.065 | J41: 553.2336 | K41: 472.63445 | L41: 407.38074 | M41: 353.53378 | N41: 308.39456 | O41: 270.05166 | P41: 237.11359
F42: Value Per Share | G42: =G40/G41 -> 396.03566 | H42: TGR | I42: 0.07 | J42: 638.11952 | K42: 538.53842 | L42: 459.79172 | M42: 396.03566 | N42: 343.42271 | O42: 299.31631 | P42: 261.8493
B43: WACC | D43: =(D36*D38)+(D33*D32)*(1-D34) -> 0.12355556 | F43: CMP | G43: =C6 -> 4184 | I43: =I42+0.5% -> 0.075 | J43: 748.30256 | K43: 621.53564 | L43: 524.23583 | M43: 447.29079 | N43: 384.99138 | O43: 333.57872 | P43: 290.47698
F44: OV/UV By | G44: =G42/G43-1 -> -0.90534521 | I44: 0.117336 | J44: -3348.3149 | K44: -7475.1036 | L44: 22249.162 | M44: 4184.2808 | N44: 2221.9453 | O44: 1470.3475 | P44: 1073.6042
B46: Change in Working Capital Calculation | C46: 2023 | D46: =C46+1 -> 2024 | E46: =D46+1 -> 2025 | F46: =E46+1 -> 2026 | G46: =F46+1 -> 2027 | H46: =G46+1 -> 2028 | I46: =H46+1 -> 2029 | J46: =I46+1 -> 2030 | K46: =J46+1 -> 2031 | L46: =K46+1 -> 2032
B47: Debtors/Receivables | C47: ='Data Sheet'!V71 -> 674 | D47: ='Data Sheet'!W71 -> 1018 | E47: ='Data Sheet'!X71 -> 1068 | F47: ='Data Sheet'!Y71 -> 916 | G47: - | H47: - | I47: - | J47: - | K47: - | L47: -
...

Sheet Data Sheet
A1: COMPANY NAME | B1: TITAN COMPANY LTD | E1: =IF(B2<>B3, "A NEW VERSION OF THE WORKSHEET IS AVAILABLE", "")
A2: LATEST VERSION | B2: 2.1 | E2: PLEASE DO NOT MAKE ANY CHANGES TO THIS SHEET
A3: CURRENT VERSION | B3: 2.1
A5: META
A6: Number of shares | B6: =IF(B9>0, B9/B8, 0) -> 88.778616
A7: Face Value | B7: 1
A8: Current Price | B8: 4184
A9: Market Capitalization | B9: 371449.73
A15: PROFIT & LOSS
A16: Report Date | B16: 42825 | C16: 43190 | D16: 43555 | E16: 43921 | F16: 44286 | G16: 44651 | H16: 45016 | I16: 45382 | J16: 45747 | K16: 46112 | M16: Narration | N16: 42825 | O16: 43190 | P16: 43555 | Q16: 43921 | R16: 44286 | S16: 44651 | T16: 45016 | U16: 45382 | V16: 45747 | W16: 46112 | X16: Trailing | Y16: Best Case | Z16: Worst Case
A17: Sales | B17: 13260.83 | C17: 16119.77 | D17: 19778.52 | E17: 21052 | F17: 21644 | G17: 28799 | H17: 40575 | I17: 51084 | J17: 60456 | K17: 87584 | M17: Sales | N17: 13260.83 | O17: 16119.77 | P17: 19778.52 | Q17: 21052 | R17: 21644 | S17: 28799 | T17: 40575 | U17: 51084 | V17: 60456 | W17: 87584 | X17: 87584 | Y17: 126884.96 | Z17: 108023.86
A18: Raw Material Cost | B18: 9821.14 | C18: 12664.83 | D18: 15170.66 | E18: 16033 | F18: 16292 | G18: 26436 | H18: 32589 | I18: 42103 | J18: 55271 | K18: 80243 | M18: Expenses | N18: 12096.93 | O18: 14475.57 | P18: 17784.73 | Q18: 18589 | R18: 19919 | S18: 25455 | T18: 35693 | U18: 45792 | V18: 54762 | W18: 79229 | X18: 79228 | Y18: 114560.57 | Z18: 97717.779
A19: Change in Inventory | B19: 313.71 | C19: 978.61 | D19: 776.41 | E19: 878 | F19: -122 | G19: 4795 | H19: 2234 | I19: 2671 | J19: 7815 | K19: 9936 | M19: Operating Profit | N19: 1163.9 | O19: 1644.2 | P19: 1993.79 | Q19: 2463 | R19: 1725 | S19: 3344 | T19: 4882 | U19: 5292 | V19: 5694 | W19: 8355 | X19: 8356 | Y19: 12324.391 | Z19: 10306.076
A20: Power and Fuel | B20: 43.84 | C20: 45.32 | D20: 48.51 | E20: 52 | F20: 37 | G20: 45 | H20: 59 | I20: 71 | J20: 78 | M20: Other Income | N20: -42.38 | O20: 69.93 | P20: 178.48 | Q20: 153 | R20: 180 | S20: 177 | T20: 306 | U20: 534 | V20: 487 | W20: 452 | X20: 452 | Y20: 0 | Z20: 0
A21: Other Mfr. Exp | B21: 160.42 | C21: 124.83 | D21: 193.28 | E21: 215 | F21: 141 | G21: 183 | H21: 225 | I21: 286 | J21: 326 | M21: Depreciation | N21: 110.53 | O21: 131.43 | P21: 162.84 | Q21: 348 | R21: 375 | S21: 399 | T21: 441 | U21: 584 | V21: 693 | W21: 826 | X21: 826 | Y21: 826 | Z21: 826
A22: Employee Cost | B22: 894.32 | C22: 906.26 | D22: 1024.44 | E22: 1204 | F22: 1069 | G22: 1356 | H22: 1656 | I22: 1875 | J22: 2164 | K22: 2681 | M22: Interest | N22: 37.74 | O22: 52.92 | P22: 52.54 | Q22: 166 | R22: 203 | S22: 218 | T22: 300 | U22: 619 | V22: 953 | W22: 1180 | X22: 1180 | Y22: 1180 | Z22: 1180 | AA22: =W22/Y59 -> 0.081094083 | AB22: =T22/T19 -> 0.061450225 | AC22: =U22/U19 -> 0.11696901 | AD22: =V22/V19 -> 0.16736916 | AE22: =W22/W19 -> 0.14123279 | AF22: =X22/X19 -> 0.14121589 | AG22: =Y22/Y19 -> 0.095745098 | AH22: =Z22/Z19 -> 0.11449557 | AJ22: =MEDIAN(AB22:AH22) -> 0.11696901
A23: Selling and admin | B23: 1211.16 | C23: 1277.81 | D23: 1454.32 | E23: 1470 | F23: 1029 | G23: 1697 | H23: 2715 | I23: 3249 | J23: 3488 | K23: 1535 | M23: Profit before tax | N23: 973.25 | O23: 1529.78 | P23: 1956.89 | Q23: 2102 | R23: 1327 | S23: 2904 | T23: 4447 | U23: 4623 | V23: 4535 | W23: 6801 | X23: 6802 | Y23: 10318.391 | Z23: 8300.0757
A24: Other Expenses | B24: 279.76 | C24: 435.13 | D24: 669.93 | E24: 493 | F24: 1229 | G24: 533 | H24: 683 | I24: 879 | J24: 1250 | K24: 4706 | M24: Tax | N24: 275.97 | O24: 427.87 | P24: 568.24 | Q24: 609 | R24: 353 | S24: 706 | T24: 1173 | U24: 1127 | V24: 1198 | W24: 1728 | X24: 1728 | Y24: 0.25404293 | Z24: 0.25404293
A25: Other Income | B25: -42.38 | C25: 69.93 | D25: 178.48 | E25: 153 | F25: 180 | G25: 177 | H25: 306 | I25: 534 | J25: 487 | K25: 452 | M25: Net profit | N25: 711.47 | O25: 1130.09 | P25: 1404.15 | Q25: 1501 | R25: 973 | S25: 2173 | T25: 3250 | U25: 3496 | V25: 3337 | W25: 5073 | X25: 5074 | Y25: 7697.0765 | Z25: 6191.5002
A26: Depreciation | B26: 110.53 | C26: 131.43 | D26: 162.84 | E26: 348 | F26: 375 | G26: 399 | H26: 441 | I26: 584 | J26: 693 | K26: 826 | M26: EPS | N26: 8.0138545 | O26: 12.729106 | P26: 15.816062 | Q26: 16.906961 | R26: 10.959676 | S26: 24.476233 | T26: 36.607344 | U26: 39.378238 | V26: 37.587294 | W26: 57.141248 | X26: 57.153403 | Y26: 86.699668 | Z26: 69.740895
A27: Interest | B27: 37.74 | C27: 52.92 | D27: 52.54 | E27: 166 | F27: 203 | G27: 218 | H27: 300 | I27: 619 | J27: 953 | K27: 1180 | M27: Price to earning | N27: 57.743749 | O27: 74.027196 | P27: 72.195594 | Q27: 55.225773 | R27: 142.16205 | S27: 103.61684 | T27: 68.69933 | U27: 96.545711 | V27: 81.499614 | W27: 69.151447 | X27: 73.20649 | Y27: 80.100816 | Z27: 73.20649
A28: Profit before tax | B28: 973.25 | C28: 1529.78 | D28: 1956.89 | E28: 2102 | F28: 1327 | G28: 2904 | H28: 4447 | I28: 4623 | J28: 4535 | K28: 6801 | M28: Price | N28: 462.75 | O28: 942.3 | P28: 1141.85 | Q28: 933.7 | R28: 1558.05 | S28: 2536.15 | T28: 2514.9 | U28: 3801.8 | V28: 3063.35 | W28: 3951.4 | X28: 4184 | Y28: 6944.7141 | Z28: 5105.4861
A29: Tax | B29: 275.97 | C29: 427.87 | D29: 568.24 | E29: 609 | F29: 353 | G29: 706 | H29: 1173 | I29: 1127 | J29: 1198 | K29: 1728
A30: Net profit | B30: 711.47 | C30: 1130.09 | D30: 1404.15 | E30: 1501 | F30: 973 | G30: 2173 | H30: 3250 | I30: 3496 | J30: 3337 | K30: 5073
A31: Dividend Amount | B31: 230.83 | C31: 332.92 | D31: 443.9 | E31: 356 | F31: 356 | G31: 667.5 | H31: 890 | I31: 979 | J31: 979 | K31: 1335
A40: Quarters
A41: Report Date | B41: 45291 | C41: 45382 | D41: 45473 | E41: 45565 | F41: 45657 | G41: 45747 | H41: 45838 | I41: 45930 | J41: 46022 | K41: 46112
A42: Sales | B42: 14164 | C42: 12494 | D42: 13266 | E42: 14534 | F42: 17740 | G42: 14916 | H42: 16523 | I42: 18725 | J42: 25416 | K42: 26920
A43: Expenses | B43: 12599 | C43: 11303 | D43: 12019 | E43: 13298 | F43: 16066 | G43: 13379 | H43: 14693 | I43: 16850 | J43: 22703 | K43: 24982
A44: Other Income | B44: 136 | C44: 159 | D44: 120 | E44: 123 | F44: 128 | G44: 116 | H44: 105 | I44: 113 | J44: -1 | K44: 235
A45: Depreciation | B45: 154 | C45: 158 | D45: 164 | E45: 171 | F45: 175 | G45: 183 | H45: 184 | I45: 189 | J45: 207 | K45: 246
A46: Interest | B46: 169 | C46: 201 | D46: 230 | E46: 240 | F46: 231 | G46: 252 | H46: 271 | I46: 277 | J46: 282 | K46: 350
A47: Profit before tax | B47: 1378 | C47: 991 | D47: 973 | E47: 948 | F47: 1396 | G47: 1218 | H47: 1480 | I47: 1522 | J47: 2223 | K47: 1577
A48: Tax | B48: 325 | C48: 220 | D48: 258 | E48: 244 | F48: 349 | G48: 347 | H48: 389 | I48: 402 | J48: 539 | K48: 398
A49: Net profit | B49: 1053 | C49: 771 | D49: 715 | E49: 704 | F49: 1047 | G49: 871 | H49: 1091 | I49: 1120 | J49: 1684 | K49: 1179
A50: Operating Profit | B50: 1565 | C50: 1191 | D50: 1247 | E50: 1236 | F50: 1674 | G50: 1537 | H50: 1830 | I50: 1875 | J50: 2713 | K50: 1938
A55: BALANCE SHEET
A56: Report Date | B56: 42825 | C56: 43190 | D56: 43555 | E56: 43921 | F56: 44286 | G56: 44651 | H56: 45016 | I56: 45382 | J56: 45747 | K56: 46112 | N56: 42064 | O56: 42430 | P56: 42795 | Q56: 43160 | R56: 43525 | S56: 43891 | T56: 44256 | U56: 44621 | V56: 44986 | W56: 45352 | X56: 45717 | Y56: 46082
A57: Equity Share Capital | B57: 88.78 | C57: 88.78 | D57: 88.78 | E57: 89 | F57: 89 | G57: 89 | H57: 89 | I57: 89 | J57: 89 | K57: 89 | M57: Equity Capital | N57: 89 | O57: 89 | P57: 89 | Q57: 89 | R57: 89 | S57: 89 | T57: 89 | U57: 89 | V57: 89 | W57: 89 | X57: 89 | Y57: 89
A58: Reserves | B58: 4143.6 | C58: 5001.1 | D58: 5981.37 | E58: 6580 | F58: 7408 | G58: 9214 | H58: 11762 | I58: 9304 | J58: 11535 | K58: 15614 | M58: Reserves | N58: 2995 | O58: 3418 | P58: 4144 | Q58: 5001 | R58: 5981 | S58: 6580 | T58: 7408 | U58: 9214 | V58: 11762 | W58: 9304 | X58: 11535 | Y58: 15614
...
