Workbook
Name UPDATE: #REF!
Name UPDATE: #REF!
Name UPDATE: #REF!
Name UPDATE: #REF!
Name UPDATE: 'Data Sheet'!$E$1

Sheet Profile
B11: INR (Crs)
B12: Key Financial Metrics | C12: Mar-22 | D12: Mar-23 | E12: Mar-24 | F12: Mar-25 | G12: Mar-26 | I12: Share Price
B13: Total Sales | C13: ='H2'!E9 -> 973.76 | D13: ='H2'!F9 -> 1173.57 | E13: ='H2'!G9 -> 1296.9 | F13: ='H2'!H9 -> 1515.87 | G13: ='H2'!I9 -> 1703.08
B14: Sales Growth (y-o-y) | C14: ='H2'!E10 -> 0.49797708 | D14: ='H2'!F10 -> 0.2051943 | E14: ='H2'!G10 -> 0.1050896 | F14: ='H2'!H10 -> 0.16884108 | G14: ='H2'!I10 -> 0.12350004
B15: Gross Profit Margins (%) | C15: ='H2'!E21 -> 0.71539188 | D15: ='H2'!F21 -> 0.77303442 | E15: ='H2'!G21 -> 0.77823271 | F15: ='H2'!H21 -> 0.77705212 | G15: ='H2'!I21 -> 0.77550086
B16: EBITDA Margins (%) | C16: ='H2'!E29 -> 0.31622782 | D16: ='H2'!F29 -> 0.34047394 | E16: ='H2'!G29 -> 0.33338731 | F16: ='H2'!H29 -> 0.32604379 | G16: ='H2'!I29 -> 0.32202833
B17: EBIT Margins (%) | C17: ='H2'!E33 -> 0.2307242 | D17: ='H2'!F33 -> 0.26355479 | E17: ='H2'!G33 -> 0.24696584 | F17: ='H2'!H33 -> 0.2347167 | G17: ='H2'!I33 -> 0.23361792
B18: Net Profit Margins (%) | C18: ='H2'!E42 -> 0.14241702 | D18: ='H2'!F42 -> 0.18096918 | E18: ='H2'!G42 -> 0.16831676 | F18: ='H2'!H42 -> 0.1611088 | G18: ='H2'!I42 -> 0.16531226
B19: Earnings Per Share (In Rs) | C19: ='H2'!E46 -> 14.737513 | D19: ='H2'!F46 -> 20.924138 | E19: ='H2'!G46 -> 21.506404 | F19: ='H2'!H46 -> 24.037402 | G19: ='H2'!I46 -> 27.71063
B20: EPS Growth (y-o-y) | C20: ='H2'!E47 -> 0.6203163 | D20: ='H2'!F47 -> 0.41978755 | E20: ='H2'!G47 -> 0.027827479 | F20: ='H2'!H47 -> 0.11768577 | G20: ='H2'!I47 -> 0.15281304
B21: Dividend Per Share (In Rs) | C21: ='H2'!E49 -> 1.9989373 | D21: ='H2'!F49 -> 3 | E21: ='H2'!G49 -> 3 | F21: ='H2'!H49 -> 2.9980315 | G21: ='H2'!I49 -> 3.4990157
B23: Key Financial Ratios | C23: Mar-22 | D23: Mar-23 | E23: Mar-24 | F23: Mar-25 | G23: Mar-26 | I23: Volume (Thousands)
B24: Return on Equity | C24: ='F3'!D27 -> 0.864364 | D24: ='F3'!E27 -> 0.85662492 | E24: ='F3'!F27 -> 0.86050667 | F24: ='F3'!G27 -> 0.87527639 | G24: ='F3'!H27 -> 0.8737302
B25: Return on Capital Employed | C25: ='F3'!D26 -> 0.18975507 | D25: ='F3'!E26 -> 0.1897546 | E25: ='F3'!F26 -> 0.15824605 | F25: ='F3'!G26 -> 0.15933721 | G25: ='F3'!H26 -> 0.15664173
B26: CFO to NP | C26: ='Cash Flow'!U4/'H2'!E41 -> 1.6152293 | D26: ='Cash Flow'!V4/'H2'!F41 -> 1.5491101 | E26: ='Cash Flow'!W4/'H2'!G41 -> 1.4705209 | F26: ='Cash Flow'!X4/'H2'!H41 -> 1.6214888 | G26: ='Cash Flow'!Y4/'H2'!I41 -> 1.4917951
B27: Debt to Profit | C27: ='Balance Sheet'!U6/'H2'!E41 -> 4.2688203 | D27: ='Balance Sheet'!V6/'H2'!F41 -> 2.6838685 | E27: ='Balance Sheet'!W6/'H2'!G41 -> 3.5045123 | F27: ='Balance Sheet'!X6/'H2'!H41 -> 3.1283269 | G27: ='Balance Sheet'!Y6/'H2'!I41 -> 3.1647368
B28: Debt to Equity | C28: ='F3'!D31 -> 0.045608108 | D28: ='F3'!E31 -> 0 | E28: ='F3'!F31 -> 0 | F28: ='F3'!G31 -> 0 | G28: ='F3'!H31 -> 0
B30: Shareholding | C30: No. Shares (In Crs) | E30: % Holding | F30: Institutional Inv> > 1% Holding | I30: Shareholding Pattern
B31: Promoter & Promoter Grp | C31: 5.06 | E31: 0.4984 | F31: ICICI Bank | G31: 0.052
B32: MF/AIF | C32: 1.94 | E32: 0.1916 | F32: DSP Mutual Fund | G32: 0.043
B33: Financial Inst./Banks/Insurance Comp. | C33: 0.2 | E33: 0.0197 | F33: Franklin Templeton | G33: 0.029
B34: FPI & FII & Foreign Nationals | C34: 1.75 | E34: 0.1724 | F34: Abu Dhabi Inv | G34: 0.021
B35: Resident Individuals (Trusts & HUF) | C35: 1.11 | E35: 0.1095 | F35: Vanguard Fund | G35: 0.018
B36: Corporates | C36: 0.058 | E36: 0.0057 | F36: Ashoka Whiteoak | G36: 0.017
B37: NRI | C37: 0.027 | E37: 0.0027 | F37: Tata MF | G37: 0.017
B38: Clearing Members | C38: 0.00027 | E38: 0 | F38: HDFC Life | G38: 0.015
B42: Company Snapshot | E42: Returns Abs. | G42: CAGR | I42: Capital Structure
B43: CMP | C43: 1439.8 | E43: 1 | F43: -0.0525 | G43: -0.05 | I43: Share price as on 25-Aug-26 | J43: =C43 -> 1439.8
B44: Market Cap | C44: =J45 -> 14628.368 | E44: 3 | F44: 0.3793 | G44: 0.11 | I44: Number of Shares o/s | J44: ='Data Sheet'!K93 -> 10.16
B45: 52 Wk High/Low | C45: 1,439.1/1,610 | E45: 5 | F45: - | G45: - | I45: Market Capitalization | J45: =J44*J43 -> 14628.368
B46: Div Yield | C46: ='H2'!I49/Profile!C43 -> 0.0024302096 | E46: Max | F46: 9.837 | G46: 0.2819 | I46: Less : Cash & Equivalents | J46: ='Balance Sheet'!Y35 -> 34
B47: P/E | C47: =Profile!C43/'H2'!I46 -> 51.9584 | I47: Add : Total Debt | J47: ='Balance Sheet'!Y6 -> 891
B48: Industry P/E | C48: 49.28 | I48: Enterprise Value | J48: =J45+J46-J47 -> 13771.368
B50: Recent Updates
B56: Source : Screener.in & Capitalmarket.com
B57: Made by Shivansh Chandra

Sheet Business
B3: B | C3: usiness
B6: Business Description | H6: Revenue Model
B19: Industry Overview | H19: Positioning

Sheet B2
B3: B | C3: usiness
B6: Growth Strategies | H6: Capex Plans
B17: Recent Developments | H17: Corporate History

Sheet B3
B3: B | C3: usiness
B6: Strength | H6: Weakness
B17: Opportunities | H17: Threats

Sheet Management
B3: M | C3: anagement
B6: Management Analysis
D8: Name | F8: Education | J8: Insights
C12: DR. Ramesh Kancharla
C19: Dr. Dinesh Kumar Chirla
C26: Abrarali Dalal

Sheet M2
B3: M | C3: anagement
B6: Management Analysis
B8: Name | F8: Education | J8: Insights
C12: Vikas Maheshwari
C19: Dr. Adarsh Kancharla
C26: Ms. Shreya Mitra

Sheet Financials
B3: F | C3: inancials
B6: Quarterly Performance
D8: FY25 | H8: FY26
D9: Q1 | E9: Q2 | F9: Q3 | G9: Q4 | H9: Q1 | I9: Q2 | J9: Q3 | K9: Q4
D10: 45444 | E10: 45536 | F10: 45627 | G10: 45717 | H10: 45809 | I10: 45901 | J10: 45992 | K10: 46082
B11: Sales | D11: 1543 | E11: 1707 | F11: 1868 | G11: 1910 | H11: 2028 | I11: 2135 | J11: 2068 | K11: 2143
B12: Growth % | D12: - | E12: =E11/D11-1 -> 0.10628645 | F12: =F11/E11-1 -> 0.094317516 | G12: =G11/F11-1 -> 0.02248394 | H12: =H11/G11-1 -> 0.061780105 | I12: =I11/H11-1 -> 0.052761341 | J12: =J11/I11-1 -> -0.031381733 | K12: =K11/J11-1 -> 0.036266925
B13: Expenses | D13: 1156 | E13: 1257 | F13: 1369 | G13: 1398 | H13: 1505 | I13: 1560 | J13: 1529 | K13: 1536
B14: EBITDA | D14: 387 | E14: 451 | F14: 499 | G14: 512 | H14: 523 | I14: 575 | J14: 538 | K14: 606
B15: EBITDA Margin | D15: =D14/D11 -> 0.25081011 | E15: =E14/E11 -> 0.26420621 | F15: =F14/F11 -> 0.26713062 | G15: =G14/G11 -> 0.26806283 | H15: =H14/H11 -> 0.25788955 | I15: =I14/I11 -> 0.26932084 | J15: =J14/J11 -> 0.26015474 | K15: =K14/K11 -> 0.28278115
B16: Other Income | D16: 35 | E16: 41 | F16: -40 | G16: 47 | H16: 37 | I16: 33 | J16: -3 | K16: 48
B17: Depreciation | D17: 77 | E17: 84 | F17: 98 | G17: 101 | H17: 104 | I17: 108 | J17: 111 | K17: 123
B18: EBIT | D18: =(D14+D16)-D17 -> 345 | E18: =(E14+E16)-E17 -> 408 | F18: =(F14+F16)-F17 -> 361 | G18: =(G14+G16)-G17 -> 458 | H18: =(H14+H16)-H17 -> 456 | I18: =(I14+I16)-I17 -> 500 | J18: =(J14+J16)-J17 -> 424 | K18: =(K14+K16)-K17 -> 531
B19: Interest | D19: 24 | E19: 34 | F19: 52 | G19: 55 | H19: 55 | I19: 54 | J19: 60 | K19: 67
B20: EBT | D20: =D18-D19 -> 321 | E20: =E18-E19 -> 374 | F20: =F18-F19 -> 309 | G20: =G18-G19 -> 403 | H20: =H18-H19 -> 401 | I20: =I18-I19 -> 446 | J20: =J18-J19 -> 364 | K20: =K18-K19 -> 464
B21: Tax | D21: =D20*D22 -> 83.46 | E21: =E20*E22 -> 93.5 | F21: =F20*F22 -> 71.07 | G21: =G20*G22 -> 84.63 | H21: =H20*H22 -> 92.23 | I21: =I20*I22 -> -44.6 | J21: =J20*J22 -> 61.88 | K21: =K20*K22 -> 120.64
B22: Tax % | D22: 0.26 | E22: 0.25 | F22: 0.23 | G22: 0.21 | H22: 0.23 | I22: -0.1 | J22: 0.17 | K22: 0.26
B23: Net Profit | D23: =D20-D21 -> 237.54 | E23: =E20-E21 -> 280.5 | F23: =F20-F21 -> 237.93 | G23: =G20-G21 -> 318.37 | H23: =H20-H21 -> 308.77 | I23: =I20-I21 -> 490.6 | J23: =J20-J21 -> 302.12 | K23: =K20-K21 -> 343.36
B25: Interpretation

Sheet H2
B3: F | C3: inancials
B6: P/L Statement
B8: Income Statement (₹ Cr) | E8: 2022 | F8: =E8+1 -> 2023 | G8: =F8+1 -> 2024 | H8: =G8+1 -> 2025 | I8: =H8+1 -> 2026 | J8: =I8+1 -> 2027 | K8: =J8+1 -> 2028 | L8: =K8+1 -> 2029
B9: Sales | E9: ='Data Sheet'!G17 -> 973.76 | F9: ='Data Sheet'!H17 -> 1173.57 | G9: ='Data Sheet'!I17 -> 1296.9 | H9: ='Data Sheet'!J17 -> 1515.87 | I9: ='Data Sheet'!K17 -> 1703.08 | J9: =I9*(1+J10) -> 1928.6988 | K9: =J9*(1+K10) -> 2184.2068 | L9: =K9*(1+L10) -> 2473.5638
B10: Sales Growth% | E10: ='Data Sheet'!G17/'Data Sheet'!F17-1 -> 0.49797708 | F10: ='Data Sheet'!H17/'Data Sheet'!G17-1 -> 0.2051943 | G10: ='Data Sheet'!I17/'Data Sheet'!H17-1 -> 0.1050896 | H10: ='Data Sheet'!J17/'Data Sheet'!I17-1 -> 0.16884108 | I10: ='Data Sheet'!K17/'Data Sheet'!J17-1 -> 0.12350004 | J10: =AVERAGE($G$10:$I$10) -> 0.13247691 | K10: =AVERAGE($G$10:$I$10) -> 0.13247691 | L10: =AVERAGE($G$10:$I$10) -> 0.13247691
B11: COGS
B12: Raw Material Cost | E12: ='Data Sheet'!G18 -> 194.73 | F12: ='Data Sheet'!H18 -> 158.28 | G12: ='Data Sheet'!I18 -> 165.28 | H12: ='Data Sheet'!J18 -> 194.92 | I12: ='Data Sheet'!K18 -> 227.03
B13: Change in Inventory | E13: ='Data Sheet'!G19 -> 0 | F13: ='Data Sheet'!H19 -> 0 | G13: ='Data Sheet'!I19 -> 0 | H13: ='Data Sheet'!J19 -> 0 | I13: ='Data Sheet'!K19 -> 0
B14: Power and Fuel | E14: ='Data Sheet'!G20 -> 16.81 | F14: ='Data Sheet'!H20 -> 21.23 | G14: ='Data Sheet'!I20 -> 26.61 | H14: ='Data Sheet'!J20 -> 27.72 | I14: ='Data Sheet'!K20 -> 28.85
B15: Other Mfr. Exp | E15: ='Data Sheet'!G21 -> 65.6 | F15: ='Data Sheet'!H21 -> 86.85 | G15: ='Data Sheet'!I21 -> 95.72 | H15: ='Data Sheet'!J21 -> 115.32 | I15: ='Data Sheet'!K21 -> 126.46
B17: Total COGS | E17: =IF(E13<0,SUM(E12:E15),SUM(E15,E14,E12)-E13) -> 277.14 | F17: =SUM(F14:F15,F12)-F13 -> 266.36 | G17: =IF(G13<0,SUM(G12:G15),SUM(G15,G14,G12)-G13) -> 287.61 | H17: =IF(H13<0,SUM(H12:H15),SUM(H15,H14,H12)-H13) -> 337.96 | I17: =IF(I13<0,SUM(I12:I15),SUM(I15,I14,I12)-I13) -> 382.34 | J17: =J9*J18 -> 430.23761 | K17: =K9*K18 -> 487.23415 | L17: =L9*L18 -> 551.78143
B18: COGS % of Sales | E18: =E17/E9 -> 0.28460812 | F18: =F17/F9 -> 0.22696558 | G18: =G17/G9 -> 0.22176729 | H18: =H17/H9 -> 0.22294788 | I18: =I17/I9 -> 0.22449914 | J18: =AVERAGE($G$18:$I$18) -> 0.22307144 | K18: =AVERAGE($G$18:$I$18) -> 0.22307144 | L18: =AVERAGE($G$18:$I$18) -> 0.22307144
B20: Gross Profit | E20: =E9-E17 -> 696.62 | F20: =F9-F17 -> 907.21 | G20: =G9-G17 -> 1009.29 | H20: =H9-H17 -> 1177.91 | I20: =I9-I17 -> 1320.74 | J20: =J9-J17 -> 1498.4612 | K20: =K9-K17 -> 1696.9727 | L20: =L9-L17 -> 1921.7823
B21: Gross Margin % Sales | E21: =E20/E9 -> 0.71539188 | F21: =F20/F9 -> 0.77303442 | G21: =G20/G9 -> 0.77823271 | H21: =H20/H9 -> 0.77705212 | I21: =I20/I9 -> 0.77550086 | J21: =J20/J9 -> 0.77692856 | K21: =K20/K9 -> 0.77692856 | L21: =L20/L9 -> 0.77692856
B22: SG&A
B23: Employee Cost | E23: ='Data Sheet'!G22 -> 116.37 | F23: ='Data Sheet'!H22 -> 144.56 | G23: ='Data Sheet'!I22 -> 176.71 | H23: ='Data Sheet'!J22 -> 206.82 | I23: ='Data Sheet'!K22 -> 234.11
B24: Selling and admin | E24: ='Data Sheet'!G23 -> 266.44 | F24: ='Data Sheet'!H23 -> 350.18 | G24: ='Data Sheet'!I23 -> 395.45 | H24: ='Data Sheet'!J23 -> 469.57 | I24: ='Data Sheet'!K23 -> 525.36
B25: Other Expenses | E25: ='Data Sheet'!G24 -> 5.88 | F25: ='Data Sheet'!H24 -> 12.9 | G25: ='Data Sheet'!I24 -> 4.76 | H25: ='Data Sheet'!J24 -> 7.28 | I25: ='Data Sheet'!K24 -> 12.83
B26: Total OpEx | E26: =SUM(E23:E25) -> 388.69 | F26: =SUM(F23:F25) -> 507.64 | G26: =SUM(G23:G25) -> 576.92 | H26: =SUM(H23:H25) -> 683.67 | I26: =SUM(I23:I25) -> 772.3 | J26: =J9*J27 -> 867.4813 | K26: =K9*K27 -> 982.40254 | L26: =L9*L27 -> 1112.5482
B27: OpEx % Sales | E27: =E26/E9 -> 0.39916407 | F27: =F26/F9 -> 0.43256048 | G27: =G26/G9 -> 0.4448454 | H27: =H26/H9 -> 0.45100833 | I27: =I26/I9 -> 0.45347253 | J27: =AVERAGE($G$27:$I$27) -> 0.44977542 | K27: =AVERAGE($G$27:$I$27) -> 0.44977542 | L27: =AVERAGE($G$27:$I$27) -> 0.44977542
B28: EBITDA | E28: =E20-E26 -> 307.93 | F28: =F20-F26 -> 399.57 | G28: =G20-G26 -> 432.37 | H28: =H20-H26 -> 494.24 | I28: =I20-I26 -> 548.44 | J28: =J9*J29 -> 630.97986 | K28: =K9*K29 -> 714.57012 | L28: =L9*L29 -> 809.23416
B29: EBITDA Margin % Sales | E29: =E28/E9 -> 0.31622782 | F29: =F28/F9 -> 0.34047394 | G29: =G28/G9 -> 0.33338731 | H29: =H28/H9 -> 0.32604379 | I29: =I28/I9 -> 0.32202833 | J29: =AVERAGE($G$29:$I$29) -> 0.32715314 | K29: =AVERAGE($G$29:$I$29) -> 0.32715314 | L29: =AVERAGE($G$29:$I$29) -> 0.32715314
B30: D&A | E30: ='Data Sheet'!G26 -> 83.26 | F30: ='Data Sheet'!H26 -> 90.27 | G30: ='Data Sheet'!I26 -> 112.08 | H30: ='Data Sheet'!J26 -> 138.44 | I30: ='Data Sheet'!K26 -> 150.57 | J30: =J9*J31 -> 171.11349 | K30: =K9*K31 -> 193.78208 | L30: =L9*L31 -> 219.45373
B31: D&A as % Sales | E31: =E30/E9 -> 0.085503615 | F31: =F30/F9 -> 0.076919144 | G31: =G30/G9 -> 0.086421467 | H31: =H30/H9 -> 0.091327093 | I31: =I30/I9 -> 0.088410409 | J31: =AVERAGE($G$31:$I$31) -> 0.088719656 | K31: =AVERAGE($G$31:$I$31) -> 0.088719656 | L31: =AVERAGE($G$31:$I$31) -> 0.088719656
B32: EBIT | E32: =E28-E30 -> 224.67 | F32: =F28-F30 -> 309.3 | G32: =G28-G30 -> 320.29 | H32: =H28-H30 -> 355.8 | I32: =I28-I30 -> 397.87 | J32: =J28-J30 -> 459.86637 | K32: =K28-K30 -> 520.78804 | L32: =L28-L30 -> 589.78043
B33: EBIT Margin % Sales | E33: =E32/E9 -> 0.2307242 | F33: =F32/F9 -> 0.26355479 | G33: =G32/G9 -> 0.24696584 | H33: =H32/H9 -> 0.2347167 | I33: =I32/I9 -> 0.23361792 | J33: =AVERAGE($G$33:$I$33) -> 0.23843348 | K33: =AVERAGE($G$33:$I$33) -> 0.23843348 | L33: =AVERAGE($G$33:$I$33) -> 0.23843348
B34: Interest | E34: ='Data Sheet'!G27 -> 56.17 | F34: ='Data Sheet'!H27 -> 58.39 | G34: ='Data Sheet'!I27 -> 62.53 | H34: ='Data Sheet'!J27 -> 76.81 | I34: ='Data Sheet'!K27 -> 81.89 | J34: =J9*J35 -> 94.486322 | K34: =K9*K35 -> 107.00358 | L34: =L9*L35 -> 121.17908
B35: Interest % Sales | E35: =E34/E9 -> 0.057683618 | F35: =F34/F9 -> 0.049754169 | G35: =G34/G9 -> 0.048214974 | H35: =H34/H9 -> 0.050670572 | I35: =I34/I9 -> 0.048083472 | J35: =AVERAGE($G$35:$I$35) -> 0.048989673 | K35: =AVERAGE($G$35:$I$35) -> 0.048989673 | L35: =AVERAGE($G$35:$I$35) -> 0.048989673
B36: EBT | E36: =(E32-E34)+E40 -> 187.35 | F36: =(F32-F34)+F40 -> 281.78 | G36: =(G32-G34)+G40 -> 294.82 | H36: =(H32-H34)+H40 -> 330 | I36: =(I32-I34)+I40 -> 358.23 | J36: =J32-J34 -> 365.38005 | K36: =K32-K34 -> 413.78447 | L36: =L32-L34 -> 468.60135
B37: EBT % Sales | E37: =E36/E9 -> 0.19239854 | F37: =F36/F9 -> 0.24010498 | G37: =G36/G9 -> 0.2273267 | H37: =H36/H9 -> 0.21769677 | I37: =I36/I9 -> 0.21034244 | J37: =AVERAGE($G$37:$I$37) -> 0.2184553 | K37: =AVERAGE($G$37:$I$37) -> 0.2184553 | L37: =AVERAGE($G$37:$I$37) -> 0.2184553
B38: Tax | E38: ='Data Sheet'!G29 -> 48.67 | F38: ='Data Sheet'!H29 -> 69.4 | G38: ='Data Sheet'!I29 -> 76.53 | H38: ='Data Sheet'!J29 -> 85.78 | I38: ='Data Sheet'!K29 -> 76.69 | J38: =J36*J39 -> 89.347826 | K38: =K36*K39 -> 101.18435 | L38: =L36*L39 -> 114.58894
B39: Tax % EBT | E39: =E38/E36 -> 0.25978116 | F39: =F38/F36 -> 0.24629143 | G39: =G38/G36 -> 0.25958212 | H39: =H38/H36 -> 0.25993939 | I39: =I38/I36 -> 0.21408034 | J39: =AVERAGE($G$39:$I$39) -> 0.24453395 | K39: =AVERAGE($G$39:$I$39) -> 0.24453395 | L39: =AVERAGE($G$39:$I$39) -> 0.24453395
B40: Other Income | E40: ='Data Sheet'!G25 -> 18.85 | F40: ='Data Sheet'!H25 -> 30.87 | G40: ='Data Sheet'!I25 -> 37.06 | H40: ='Data Sheet'!J25 -> 51.01 | I40: ='Data Sheet'!K25 -> 42.25 | J40: =I40*(1+0.046) -> 44.1935 | K40: =J40*(1+0.046) -> 46.226401 | L40: =K40*(1+0.046) -> 48.352815
B41: Net Profit | E41: =(E36-E38) -> 138.68 | F41: =(F36-F38) -> 212.38 | G41: =(G36-G38) -> 218.29 | H41: =(H36-H38) -> 244.22 | I41: =(I36-I38) -> 281.54 | J41: =(J36-J38) -> 276.03222 | K41: =(K36-K38) -> 312.60012 | L41: =(L36-L38) -> 354.01241
B42: Net Profit Margin % | E42: =E41/E9 -> 0.14241702 | F42: =F41/F9 -> 0.18096918 | G42: =G41/G9 -> 0.16831676 | H42: =H41/H9 -> 0.1611088 | I42: =I41/I9 -> 0.16531226 | J42: =AVERAGE(G42:I42) -> 0.16491261 | K42: =AVERAGE(H42:J42) -> 0.16377789 | L42: =AVERAGE(I42:K42) -> 0.16466758
B44: No. of Equity Shares | E44: ='Data Sheet'!G93 -> 9.41 | F44: ='Data Sheet'!H93 -> 10.15 | G44: ='Data Sheet'!I93 -> 10.15 | H44: ='Data Sheet'!J93 -> 10.16 | I44: ='Data Sheet'!K93 -> 10.16 | J44: =I44 -> 10.16 | K44: =J44 -> 10.16 | L44: =K44 -> 10.16
B46: Earnings Per Share | E46: =E41/E44 -> 14.737513 | F46: =F41/F44 -> 20.924138 | G46: =G41/G44 -> 21.506404 | H46: =H41/H44 -> 24.037402 | I46: =I41/I44 -> 27.71063 | J46: =J41/J44 -> 27.168526 | K46: =K41/K44 -> 30.767728 | L46: =L41/L44 -> 34.843741
B47: EPS Growth % | E47: =E46/'Profit & Loss'!F13-1 -> 0.6203163 | F47: =F46/E46-1 -> 0.41978755 | G47: =G46/F46-1 -> 0.027827479 | H47: =H46/G46-1 -> 0.11768577 | I47: =I46/H46-1 -> 0.15281304 | J47: =J46/I46-1 -> -0.019563043 | K47: =K46/J46-1 -> 0.13247691 | L47: =L46/K46-1 -> 0.13247691
B49: Dividend Per Share | E49: ='Data Sheet'!G31/'H2'!E44 -> 1.9989373 | F49: ='Data Sheet'!H31/'H2'!F44 -> 3 | G49: ='Data Sheet'!I31/'H2'!G44 -> 3 | H49: ='Data Sheet'!J31/'H2'!H44 -> 2.9980315 | I49: ='Data Sheet'!K31/'H2'!I44 -> 3.4990157 | J49: =(J50*J41)/J44 -> 3.5363164 | K49: =(K50*K41)/K44 -> 3.9090979 | L49: =(L50*L41)/L44 -> 4.454005
B50: Dividend Payout Ratio | E50: ='Data Sheet'!G31/'H2'!E41 -> 0.135636 | F50: ='Data Sheet'!H31/'H2'!F41 -> 0.14337508 | G50: ='Data Sheet'!I31/'H2'!G41 -> 0.13949333 | H50: ='Data Sheet'!J31/'H2'!H41 -> 0.12472361 | I50: ='Data Sheet'!K31/'H2'!I41 -> 0.1262698 | J50: =AVERAGE(G50:I50) -> 0.13016225 | K50: =AVERAGE(H50:J50) -> 0.12705189 | L50: =AVERAGE(I50:K50) -> 0.12782798
...

Sheet F3
B3: F | C3: inancials
B6: Ratios Analysis Rainbow Hospitals
B8: Years | D8: 44651 | E8: 45016 | F8: 45382 | G8: 45747 | H8: 46112 | I8: Trend | J8: Mean | K8: Median
B10: Sales Growth | D10: ='Data Sheet'!G17/'Data Sheet'!F17-1 -> 0.49797708 | E10: ='Data Sheet'!H17/'Data Sheet'!G17-1 -> 0.2051943 | F10: ='Data Sheet'!I17/'Data Sheet'!H17-1 -> 0.1050896 | G10: ='Data Sheet'!J17/'Data Sheet'!I17-1 -> 0.16884108 | H10: ='Data Sheet'!K17/'Data Sheet'!J17-1 -> 0.12350004 | J10: =IFERROR(AVERAGE(D10:H10),0) -> 0.22012042 | K10: =IFERROR(MEDIAN(D10:H10),0) -> 0.16884108
B11: EBITDA Growth | D11: ='Profit & Loss'!G6/'Profit & Loss'!F6-1 -> 0.86466029 | E11: ='H2'!F28/'H2'!E28-1 -> 0.2976001 | F11: ='H2'!G28/'H2'!F28-1 -> 0.082088245 | G11: ='H2'!H28/'H2'!G28-1 -> 0.14309503 | H11: ='H2'!I28/'H2'!H28-1 -> 0.10966332 | J11: =IFERROR(AVERAGE(D11:H11),0) -> 0.2994214 | K11: =IFERROR(MEDIAN(D11:H11),0) -> 0.14309503
B12: EBIT Growth | D12: =('Profit & Loss'!G6-'Profit & Loss'!G8)/('Profit & Loss'!F6-'Profit & Loss'!F8)-1 -> 1.4473856 | E12: ='H2'!F36/'H2'!E36-1 -> 0.50402989 | F12: ='H2'!G36/'H2'!F36-1 -> 0.046277238 | G12: ='H2'!H36/'H2'!G36-1 -> 0.11932705 | H12: ='H2'!I36/'H2'!H36-1 -> 0.085545455 | J12: =IFERROR(AVERAGE(D12:H12),0) -> 0.44051305 | K12: =IFERROR(MEDIAN(D12:H12),0) -> 0.11932705
B13: Net Profit Growth | D13: ='H2'!E42 -> 0.14241702 | E13: ='H2'!F42 -> 0.18096918 | F13: ='H2'!G42 -> 0.16831676 | G13: ='H2'!H42 -> 0.1611088 | H13: ='H2'!I42 -> 0.16531226 | J13: =IFERROR(AVERAGE(D13:H13),0) -> 0.1636248 | K13: =IFERROR(MEDIAN(D13:H13),0) -> 0.16531226
B14: Dividend Growth | D14: ='H2'!E50 -> 0.135636 | E14: ='H2'!F50 -> 0.14337508 | F14: ='H2'!G50 -> 0.13949333 | G14: ='H2'!H50 -> 0.12472361 | H14: ='H2'!I50 -> 0.1262698 | J14: =IFERROR(AVERAGE(D14:H14),0) -> 0.13389957 | K14: =IFERROR(MEDIAN(D14:H14),0) -> 0.135636
B16: Gross Margin | D16: ='H2'!E21 -> 0.71539188 | E16: ='H2'!F21 -> 0.77303442 | F16: ='H2'!G21 -> 0.77823271 | G16: ='H2'!H21 -> 0.77705212 | H16: ='H2'!I21 -> 0.77550086 | J16: =IFERROR(AVERAGE(D16:H16),0) -> 0.7638424 | K16: =IFERROR(MEDIAN(D16:H16),0) -> 0.77550086
B17: EBITDA Margin | D17: ='H2'!E29 -> 0.31622782 | E17: ='H2'!F29 -> 0.34047394 | F17: ='H2'!G29 -> 0.33338731 | G17: ='H2'!H29 -> 0.32604379 | H17: ='H2'!I29 -> 0.32202833 | J17: =IFERROR(AVERAGE(D17:H17),0) -> 0.32763224 | K17: =IFERROR(MEDIAN(D17:H17),0) -> 0.32604379
B18: EBIT Margin | D18: ='H2'!E33 -> 0.2307242 | E18: ='H2'!F33 -> 0.26355479 | F18: ='H2'!G33 -> 0.24696584 | G18: ='H2'!H33 -> 0.2347167 | H18: ='H2'!I33 -> 0.23361792 | J18: =IFERROR(AVERAGE(D18:H18),0) -> 0.24191589 | K18: =IFERROR(MEDIAN(D18:H18),0) -> 0.2347167
B19: EBT Margin | D19: ='H2'!E37 -> 0.19239854 | E19: ='H2'!F37 -> 0.24010498 | F19: ='H2'!G37 -> 0.2273267 | G19: ='H2'!H37 -> 0.21769677 | H19: ='H2'!I37 -> 0.21034244 | J19: =IFERROR(AVERAGE(D19:H19),0) -> 0.21757389 | K19: =IFERROR(MEDIAN(D19:H19),0) -> 0.21769677
B20: Net Profit Margin | D20: ='H2'!E42 -> 0.14241702 | E20: ='H2'!F42 -> 0.18096918 | F20: ='H2'!G42 -> 0.16831676 | G20: ='H2'!H42 -> 0.1611088 | H20: ='H2'!I42 -> 0.16531226 | J20: =IFERROR(AVERAGE(D20:H20),0) -> 0.1636248 | K20: =IFERROR(MEDIAN(D20:H20),0) -> 0.16531226
B22: SalesExpenses%Sales | D22: ='H2'!E18 -> 0.28460812 | E22: ='H2'!F18 -> 0.22696558 | F22: ='H2'!G18 -> 0.22176729 | G22: ='H2'!H18 -> 0.22294788 | H22: ='H2'!I18 -> 0.22449914 | J22: =IFERROR(AVERAGE(D22:H22),0) -> 0.2361576 | K22: =IFERROR(MEDIAN(D22:H22),0) -> 0.22449914
B23: Depreciation%Sales | D23: ='H2'!E31 -> 0.085503615 | E23: ='H2'!F31 -> 0.076919144 | F23: ='H2'!G31 -> 0.086421467 | G23: ='H2'!H31 -> 0.091327093 | H23: ='H2'!I31 -> 0.088410409 | J23: =IFERROR(AVERAGE(D23:H23),0) -> 0.085716346 | K23: =IFERROR(MEDIAN(D23:H23),0) -> 0.086421467
B24: OperatingIncome%Sales | D24: ='H2'!E33 -> 0.2307242 | E24: ='H2'!F33 -> 0.26355479 | F24: ='H2'!G33 -> 0.24696584 | G24: ='H2'!H33 -> 0.2347167 | H24: ='H2'!I33 -> 0.23361792 | J24: =IFERROR(AVERAGE(D24:H24),0) -> 0.24191589 | K24: =IFERROR(MEDIAN(D24:H24),0) -> 0.2347167
B26: Return on Capital Employed | D26: ='H2'!E32/SUM('Balance Sheet'!U4:U6) -> 0.18975507 | E26: ='H2'!F32/SUM('Balance Sheet'!V4:V6) -> 0.1897546 | F26: ='H2'!G32/SUM('Balance Sheet'!W4:W6) -> 0.15824605 | G26: ='H2'!H32/SUM('Balance Sheet'!X4:X6) -> 0.15933721 | H26: ='H2'!I32/SUM('Balance Sheet'!Y4:Y6) -> 0.15664173 | J26: =IFERROR(AVERAGE(D26:H26),0) -> 0.17074693 | K26: =IFERROR(MEDIAN(D26:H26),0) -> 0.15933721
B27: Retained Earnings% | D27: ='H2'!E52 -> 0.864364 | E27: ='H2'!F52 -> 0.85662492 | F27: ='H2'!G52 -> 0.86050667 | G27: ='H2'!H52 -> 0.87527639 | H27: ='H2'!I52 -> 0.8737302 | J27: =IFERROR(AVERAGE(D27:H27),0) -> 0.86610043 | K27: =IFERROR(MEDIAN(D27:H27),0) -> 0.864364
B28: Return on Equity% | D28: ='H2'!E41/SUM('Balance Sheet'!U4:U5) -> 0.23425676 | E28: ='H2'!F41/SUM('Balance Sheet'!V4:V5) -> 0.20035849 | F28: ='H2'!G41/SUM('Balance Sheet'!W4:W5) -> 0.17338364 | G28: ='H2'!H41/SUM('Balance Sheet'!X4:X5) -> 0.16624915 | H28: ='H2'!I41/SUM('Balance Sheet'!Y4:Y5) -> 0.17073378 | J28: =IFERROR(AVERAGE(D28:H28),0) -> 0.18899636 | K28: =IFERROR(MEDIAN(D28:H28),0) -> 0.17338364
B29: Self Sustained Growth Rate | D29: =IFERROR(D27*D28,0) -> 0.20248311 | E29: =IFERROR(E27*E28,0) -> 0.17163208 | F29: =IFERROR(F27*F28,0) -> 0.14919778 | G29: =IFERROR(G27*G28,0) -> 0.14551396 | H29: =IFERROR(H27*H28,0) -> 0.14917526 | J29: =IFERROR(AVERAGE(D29:H29),0) -> 0.16360043 | K29: =IFERROR(MEDIAN(D29:H29),0) -> 0.14919778
B30: Debt servicing ratio | D30: ='H2'!E28/'H2'!E34 -> 5.4821079 | E30: ='H2'!F28/'H2'!F34 -> 6.8431238 | F30: ='H2'!G28/'H2'!G34 -> 6.914601 | G30: ='H2'!H28/'H2'!H34 -> 6.4345788 | H30: ='H2'!I28/'H2'!I34 -> 6.6972768 | J30: =IFERROR(AVERAGE(D30:H30),0) -> 6.4743377 | K30: =IFERROR(MEDIAN(D30:H30),0) -> 6.6972768
B31: Debt/Equity Ratio | D31: ='Balance Sheet'!U7/SUM('Balance Sheet'!U4:U5) -> 0.045608108 | E31: ='Balance Sheet'!V7/SUM('Balance Sheet'!V4:V5) -> 0 | F31: ='Balance Sheet'!W7/SUM('Balance Sheet'!W4:W5) -> 0 | G31: ='Balance Sheet'!X7/SUM('Balance Sheet'!X4:X5) -> 0 | H31: ='Balance Sheet'!Y7/SUM('Balance Sheet'!Y4:Y5) -> 0 | J31: =IFERROR(AVERAGE(D31:H31),0) -> 0.0091216216 | K31: =IFERROR(MEDIAN(D31:H31),0) -> 0
B32: Interest Coverage Ratio | D32: ='H2'!E32/'H2'!E34 -> 3.999822 | E32: ='H2'!F32/'H2'!F34 -> 5.2971399 | F32: ='H2'!G32/'H2'!G34 -> 5.1221814 | G32: ='H2'!H32/'H2'!H34 -> 4.6322093 | H32: ='H2'!I32/'H2'!I34 -> 4.8585908 | J32: =IFERROR(AVERAGE(D32:H32),0) -> 4.7819887 | K32: =IFERROR(MEDIAN(D32:H32),0) -> 4.8585908
B34: Debtor Turnover Ratio | D34: ='H2'!E12/'Balance Sheet'!U34 -> 4.86825 | E34: ='H2'!F12/'Balance Sheet'!V34 -> 3.1035294 | F34: ='H2'!G12/'Balance Sheet'!W34 -> 2.3611429 | G34: ='H2'!H12/'Balance Sheet'!X34 -> 2.5314286 | H34: ='H2'!I12/'Balance Sheet'!Y34 -> 2.2041748 | J34: =IFERROR(AVERAGE(D34:H34),0) -> 3.0137051 | K34: =IFERROR(MEDIAN(D34:H34),0) -> 2.5314286
B35: Creditor Turnover Ratio | D35: ='H2'!E9/'Balance Sheet'!U14 -> 15.215 | E35: ='H2'!F9/'Balance Sheet'!V14 -> 14.855316 | F35: ='H2'!G9/'Balance Sheet'!W14 -> 15.815854 | G35: ='H2'!H9/'Balance Sheet'!X14 -> 16.657912 | H35: ='H2'!I9/'Balance Sheet'!Y14 -> 16.862178 | J35: =IFERROR(AVERAGE(D35:H35),0) -> 15.881252 | K35: =IFERROR(MEDIAN(D35:H35),0) -> 15.815854
B36: Inventory Turnover | D36: ='H2'!E9/'Balance Sheet'!U33 -> 64.917333 | E36: ='H2'!F9/'Balance Sheet'!V33 -> 61.766842 | F36: ='H2'!G9/'Balance Sheet'!W33 -> 54.0375 | G36: ='H2'!H9/'Balance Sheet'!X33 -> 54.138214 | H36: ='H2'!I9/'Balance Sheet'!Y33 -> 40.549524 | J36: =IFERROR(AVERAGE(D36:H36),0) -> 55.081883 | K36: =IFERROR(MEDIAN(D36:H36),0) -> 54.138214
B37: Fixed Asset Turnover | D37: ='H2'!E9/'Balance Sheet'!U18 -> 1.1349184 | E37: ='H2'!F9/'Balance Sheet'!V18 -> 1.2605478 | F37: ='H2'!G9/'Balance Sheet'!W18 -> 1.0350359 | G37: ='H2'!H9/'Balance Sheet'!X18 -> 1.0843133 | H37: ='H2'!I9/'Balance Sheet'!Y18 -> 0.96986333 | J37: =IFERROR(AVERAGE(D37:H37),0) -> 1.0969358 | K37: =IFERROR(MEDIAN(D37:H37),0) -> 1.0843133
B38: Current Ratio | D38: =SUM('Balance Sheet'!U33:U37)/SUM('Balance Sheet'!U13:U16) -> 3.6846847 | E38: =SUM('Balance Sheet'!V33:V37)/SUM('Balance Sheet'!V13:V16) -> 5.3758865 | F38: =SUM('Balance Sheet'!W33:W37)/SUM('Balance Sheet'!W13:W16) -> 4.0068027 | G38: =SUM('Balance Sheet'!X33:X37)/SUM('Balance Sheet'!X13:X16) -> 2.6206897 | H38: =SUM('Balance Sheet'!Y33:Y37)/SUM('Balance Sheet'!Y13:Y16) -> 2.2616034 | J38: =IFERROR(AVERAGE(D38:H38),0) -> 3.5899334 | K38: =IFERROR(MEDIAN(D38:H38),0) -> 3.6846847
B39: Acid Test Ratio | D39: {=SUM('Balance Sheet'!U34:U37/SUM('Balance Sheet'!U13:U16))} -> 3.5495495 | E39: {=SUM('Balance Sheet'!V34:V37/SUM('Balance Sheet'!V13:V16))} -> 5.2411348 | F39: {=SUM('Balance Sheet'!W34:W37/SUM('Balance Sheet'!W13:W16))} -> 3.8435374 | G39: {=SUM('Balance Sheet'!X34:X37/SUM('Balance Sheet'!X13:X16))} -> 2.4275862 | H39: {=SUM('Balance Sheet'!Y34:Y37/SUM('Balance Sheet'!Y13:Y16))} -> 2.0843882 | J39: =IFERROR(AVERAGE(D39:H39),0) -> 3.4292392 | K39: =IFERROR(MEDIAN(D39:H39),0) -> 3.5495495
B40: Equity Capital Turnover Ratio | D40: ='H2'!E9/SUM('Balance Sheet'!U4:U5) -> 1.6448649 | E40: ='H2'!F9/SUM('Balance Sheet'!V4:V5) -> 1.1071415 | F40: ='H2'!G9/SUM('Balance Sheet'!W4:W5) -> 1.0301033 | G40: ='H2'!H9/SUM('Balance Sheet'!X4:X5) -> 1.0319061 | H40: ='H2'!I9/SUM('Balance Sheet'!Y4:Y5) -> 1.0327956 | J40: =IFERROR(AVERAGE(D40:H40),0) -> 1.1693623 | K40: =IFERROR(MEDIAN(D40:H40),0) -> 1.0327956
B42: Debtor Days | D42: =365/D34 -> 74.975607 | E42: =365/E34 -> 117.60804 | F42: =365/F34 -> 154.58616 | G42: =365/G34 -> 144.18736 | H42: =365/H34 -> 165.59486 | J42: =IFERROR(AVERAGE(D42:H42),0) -> 131.3904 | K42: =IFERROR(MEDIAN(D42:H42),0) -> 144.18736
B43: Payable Days | D43: =365/D35 -> 23.989484 | E43: =365/E35 -> 24.570328 | F43: =365/F35 -> 23.078109 | G43: =365/G35 -> 21.91151 | H43: =365/H35 -> 21.646077 | J43: =IFERROR(AVERAGE(D43:H43),0) -> 23.039102 | K43: =IFERROR(MEDIAN(D43:H43),0) -> 23.078109
B44: Inventory Days | D44: =365/D36 -> 5.6225353 | E44: =365/E36 -> 5.9093194 | F44: =365/F36 -> 6.7545686 | G44: =365/G36 -> 6.7420029 | H44: =365/H36 -> 9.0013388 | J44: =IFERROR(AVERAGE(D44:H44),0) -> 6.805953 | K44: =IFERROR(MEDIAN(D44:H44),0) -> 6.7420029
B45: Cash Conversion Cycle (in days) | D45: =(D42+D44)-D43 -> 56.608659 | E45: =(E42+E44)-E43 -> 98.947028 | F45: =(F42+F44)-F43 -> 138.26262 | G45: =(G42+G44)-G43 -> 129.01785 | H45: =(H42+H44)-H43 -> 152.95012 | J45: =IFERROR(AVERAGE(D45:H45),0) -> 115.15725 | K45: =IFERROR(MEDIAN(D45:H45),0) -> 129.01785
B47: CFO/Sales | D47: ='Cash Flow'!U4/'H2'!E9 -> 0.23003615 | E47: ='Cash Flow'!V4/'H2'!F9 -> 0.28034118 | F47: ='Cash Flow'!W4/'H2'!G9 -> 0.2475133 | G47: ='Cash Flow'!X4/'H2'!H9 -> 0.26123612 | H47: ='Cash Flow'!Y4/'H2'!I9 -> 0.24661202 | J47: =IFERROR(AVERAGE(D47:H47),0) -> 0.25314775 | K47: =IFERROR(MEDIAN(D47:H47),0) -> 0.2475133
B48: CFO/Total Assets | D48: ='Cash Flow'!U4/'Balance Sheet'!U38 -> 0.17283951 | E48: ='Cash Flow'!V4/'Balance Sheet'!V38 -> 0.18577075 | F48: ='Cash Flow'!W4/'Balance Sheet'!W38 -> 0.14792627 | G48: ='Cash Flow'!X4/'Balance Sheet'!X38 -> 0.16659655 | H48: ='Cash Flow'!Y4/'Balance Sheet'!Y38 -> 0.15135135 | J48: =IFERROR(AVERAGE(D48:H48),0) -> 0.16489689 | K48: =IFERROR(MEDIAN(D48:H48),0) -> 0.16659655
B49: CFO/Total Debt | D49: ='Cash Flow'!U4/'Balance Sheet'!U6 -> 0.37837838 | E49: ='Cash Flow'!V4/'Balance Sheet'!V6 -> 0.57719298 | F49: ='Cash Flow'!W4/'Balance Sheet'!W6 -> 0.41960784 | G49: ='Cash Flow'!X4/'Balance Sheet'!X6 -> 0.51832461 | H49: ='Cash Flow'!Y4/'Balance Sheet'!Y6 -> 0.47138047 | J49: =IFERROR(AVERAGE(D49:H49),0) -> 0.47297686 | K49: =IFERROR(MEDIAN(D49:H49),0) -> 0.47138047
B51: Interpretation

Sheet Valuations
B3: V | C3: aluations
B6: Company Comparables
L7: EV/Revenue | M7: EV/EBITDA | N7: P/E
L8: ='V3'!O30/'V3'!O31 -> 1368.3104 | M8: ='V3'!P30/'V3'!P31 -> 2010.1961 | N8: ='V3'!Q30/'V3'!Q31 -> 1849.3867
L9: =IF('V3'!E13<L8,"Undervalued","Overvalued") -> Overvalued | M9: =IF($D$7<M8,"Undervalued","Overvalued") -> Undervalued | N9: =IF($D$7<N8,"Undervalued","Overvalued") -> Undervalued
B20: DCF
L21: Equity Value (DCF) | M21: ='V2'!G41 -> 10996.379
L22: No of shares | M22: ='V2'!G42 -> 10.155916
L23: Value Per Share | M23: ='V2'!G43 -> 1082.756
L24: CMP | M24: ='V2'!G44 -> 1439.8
L25: OV/UV By | M25: ='V2'!G45 -> -0.24798163

Sheet V2
B3: V | C3: aluations
B6: Period | C6: 2023 | G6: =C6+1 -> 2024 | H6: =G6+1 -> 2025 | I6: =H6+1 -> 2026 | J6: =I6+1 -> 2027 | K6: =J6+1 -> 2028 | L6: =K6+1 -> 2029 | M6: =L6+1 -> 2030 | N6: =M6+1 -> 2031
B7: Year | J7: 1 | K7: =J7+1 -> 2 | L7: =K7+1 -> 3 | M7: =L7+1 -> 4 | N7: =M7+1 -> 5
B8: Growth | G8: ='Data Sheet'!I17/'Data Sheet'!H17-1 -> 0.1050896 | H8: ='Data Sheet'!J17/'Data Sheet'!I17-1 -> 0.16884108 | I8: ='Data Sheet'!K17/'Data Sheet'!J17-1 -> 0.12350004 | J8: =AVERAGE($G$8:$I$8) -> 0.13247691 | K8: =AVERAGE($G$8:$I$8) -> 0.13247691 | L8: =AVERAGE($G$8:$I$8) -> 0.13247691 | M8: =AVERAGE($G$8:$I$8) -> 0.13247691 | N8: =AVERAGE($G$8:$I$8) -> 0.13247691
B9: Revenue | G9: ='H2'!G9 -> 1296.9 | H9: ='H2'!H9 -> 1515.87 | I9: ='H2'!I9 -> 1703.08 | J9: =I9*(1+J8) -> 1928.6988 | K9: =J9*(1+K8) -> 2184.2068 | L9: =K9*(1+L8) -> 2473.5638 | M9: =L9*(1+M8) -> 2801.2538 | N9: =M9*(1+N8) -> 3172.3553
B10: EBITDA | G10: ='H2'!G28 -> 432.37 | H10: ='H2'!H28 -> 494.24 | I10: ='H2'!I28 -> 548.44 | J10: =J9*J11 -> 630.97986 | K10: =K9*K11 -> 714.57012 | L10: =L9*L11 -> 809.23416 | M10: =M9*M11 -> 916.439 | N10: =N9*N11 -> 1037.846
B11: EBITDA Margin% | G11: =G10/G9 -> 0.33338731 | H11: =H10/H9 -> 0.32604379 | I11: =I10/I9 -> 0.32202833 | J11: =AVERAGE($G$11:$I$11) -> 0.32715314 | K11: =AVERAGE($G$11:$I$11) -> 0.32715314 | L11: =AVERAGE($G$11:$I$11) -> 0.32715314 | M11: =AVERAGE($G$11:$I$11) -> 0.32715314 | N11: =AVERAGE($G$11:$I$11) -> 0.32715314
B12: Less: Depreciation & Ammortisation | G12: ='H2'!G30 -> 112.08 | H12: ='H2'!H30 -> 138.44 | I12: ='H2'!I30 -> 150.57 | J12: =J9*J13 -> 171.11349 | K12: =K9*K13 -> 193.78208 | L12: =L9*L13 -> 219.45373 | M12: =M9*M13 -> 248.52628 | N12: =N9*N13 -> 281.45027
B13: Depreciation % Sales | G13: =G12/G9 -> 0.086421467 | H13: =H12/H9 -> 0.091327093 | I13: =I12/I9 -> 0.088410409 | J13: =AVERAGE($G$13:$I$13) -> 0.088719656 | K13: =AVERAGE($G$13:$I$13) -> 0.088719656 | L13: =AVERAGE($G$13:$I$13) -> 0.088719656 | M13: =AVERAGE($G$13:$I$13) -> 0.088719656 | N13: =AVERAGE($G$13:$I$13) -> 0.088719656
B14: EBIT | G14: =(G10-G12) -> 320.29 | H14: =(H10-H12) -> 355.8 | I14: =(I10-I12) -> 397.87 | J14: =(J10-J12) -> 459.86637 | K14: =(K10-K12) -> 520.78804 | L14: =(L10-L12) -> 589.78043 | M14: =(M10-M12) -> 667.91272 | N14: =(N10-N12) -> 756.39573
B15: Less: Tax | G15: ='H2'!G38 -> 76.53 | H15: ='H2'!H38 -> 85.78 | I15: ='H2'!I38 -> 76.69 | J15: =J14*J16 -> 112.45294 | K15: =K14*K16 -> 127.35036 | L15: =L14*L16 -> 144.22134 | M15: =M14*M16 -> 163.32734 | N15: =N14*N16 -> 184.96444
B16: Tax % EBT | G16: ='H2'!G39 -> 0.25958212 | H16: ='H2'!H39 -> 0.25993939 | I16: ='H2'!I39 -> 0.21408034 | J16: =AVERAGE($G$16:$I$16) -> 0.24453395 | K16: =AVERAGE($G$16:$I$16) -> 0.24453395 | L16: =AVERAGE($G$16:$I$16) -> 0.24453395 | M16: =AVERAGE($G$16:$I$16) -> 0.24453395 | N16: =AVERAGE($G$16:$I$16) -> 0.24453395
B17: EBIT(1-Tax) | G17: =G14-G15 -> 243.76 | H17: =H14-H15 -> 270.02 | I17: =I14-I15 -> 321.18 | J17: =J14-J15 -> 347.41343 | K17: =K14-K15 -> 393.43769 | L17: =L14-L15 -> 445.55909 | M17: =M14-M15 -> 504.58538 | N17: =N14-N15 -> 571.43129
B18: Add: Depreciation & Ammortisation | G18: ='H2'!G30 -> 112.08 | H18: ='H2'!H30 -> 138.44 | I18: ='H2'!I30 -> 150.57 | J18: =J12 -> 171.11349 | K18: =K12 -> 193.78208 | L18: =L12 -> 219.45373 | M18: =M12 -> 248.52628 | N18: =N12 -> 281.45027
B19: NOPAT | G19: =G17+G18 -> 355.84 | H19: =H17+H18 -> 408.46 | I19: =I17+I18 -> 471.75 | J19: =J17+J18 -> 518.52692 | K19: =K17+K18 -> 587.21976 | L19: =L17+L18 -> 665.01282 | M19: =M17+M18 -> 753.11166 | N19: =N17+N18 -> 852.88156
B20: Less: Capex | G20: =-'Cash Flow'!W15 -> 354 | H20: =-'Cash Flow'!X15 -> 146 | I20: =-'Cash Flow'!Y15 -> 216 | J20: =J9*12% -> 231.44385 | K20: =K9*12% -> 262.10482 | L20: =L9*12% -> 296.82765 | M20: =M9*12% -> 336.15046 | N20: =N9*12% -> 380.68263
B21: Add: Reinvestment | G21: ='Cash Flow'!W16 -> 0 | H21: ='Cash Flow'!X16 -> 0 | I21: ='Cash Flow'!Y16 -> 1 | J21: 0 | K21: 0 | L21: 0 | M21: 0 | N21: 0
B22: Less: Net Change in Working Capital | G22: =G52 -> 21 | H22: =H52 -> 2 | I22: =I52 -> 30 | J22: =J52 -> -12.769624 | K22: =K52 -> 4.1373035 | L22: =L52 -> 4.6854007 | M22: =M52 -> 5.3061081 | N22: =N52 -> 6.0090449
B23: Free Cash Flow to the Firm | G23: =(G19-G20-G22)+G21 -> -19.16 | H23: =(H19-H20-H22)+H21 -> 260.46 | I23: =(I19-I20-I22)+I21 -> 226.75 | J23: =(J19-J20-J22)+J21 -> 299.85269 | K23: =(K19-K20-K22)+K21 -> 320.97764 | L23: =(L19-L20-L22)+L21 -> 363.49977 | M23: =(M19-M20-M22)+M21 -> 411.65509 | N23: =(N19-N20-N22)+N21 -> 466.18988
B24: Discount Rate (r)
B25: PV of Free Cash Flows | J25: =J23/(1+$D$41)^J7 -> 278.29567 | K25: =K23/(1+$D$41)^K7 -> 276.48512 | L25: =L23/(1+$D$41)^L7 -> 290.60268 | M25: =M23/(1+$D$41)^M7 -> 305.44109 | N25: =N23/(1+$D$41)^N7 -> 321.03716
B27: WACC | F27: Sum of PV of FCFF | G27: =SUM(J25:N25) -> 1471.8617 | I27: Market Cap. In Cr.
B28: Cost of Debt | I28: =D35 -> 14622.487
B29: Debt | D29: ='Balance Sheet'!Y6 -> 891 | F29: Terminal Value
B30: % Debt | D30: =D29/SUM((D29,D35)) -> 0.057433895 | F30: Terminal Growth Rate | G30: 0.042 | I30: Intrinsic Value DCF
B31: Cost of Debt | D31: ='H2'!I34/'Balance Sheet'!Y6 -> 0.091907969 | F31: Terminal Value | G31: =(N23*(1+G30))/(D41-G30) -> 13698.758 | I31: =G41 -> 10996.379
B32: Tax Rate | D32: 0.245 | F32: PV of TV | G32: =G31/((1+D41)^N7) -> 9433.5173
I33: Current Market Price
B34: Cost of Equity | D34: =D37+D38*(D39-D37) -> 0.077952625 | F34: Enterprise Value 1 + 2 | I34: =G44 -> 1439.8
B35: Equity | D35: =Profile!C43*('Data Sheet'!K70/10000000) -> 14622.487 | F35: Enterprise Value | G35: =G32+G27 -> 10905.379
B36: % Equity | D36: =D35/SUM(D35,D29) -> 0.9425661 | F36: Add: Cash | G36: 594 | I36: Implied Share Price
B37: Risk Free Rate | D37: 0.0687 | F37: Add: Other Non Operating Assets | G37: ='Balance Sheet'!Y31 -> 404 | I37: =G43 -> 1082.756
B38: Beta | D38: =Closing!Y3 -> 0.81881635 | F38: Less: Debt | G38: ='Balance Sheet'!Y6 -> 891
B39: Market Return | D39: 0.08 | F39: Less: Minority Interest | G39: ='Balance Sheet'!Y13 -> 16
I40: =G43 -> 1082.756 | J40: =K40-1% -> 0.057461865 | K40: =L40-1% -> 0.067461865 | L40: 0.077461865 | M40: =L40+1% -> 0.087461865 | N40: =M40+0.5% -> 0.092461865
B41: WACC | D41: =((D34*D36))+((D31*D30)*(1-D32)) -> 0.07746087 | F41: Equity Value (DCF) | G41: =(G35+G36+G37)-(G38+G39) -> 10996.379 | I41: =I42-1% -> 0.022 | J41: 1163.0264 | K41: 902.65463 | L41: 736.37933 | M41: 621.06933 | N41: 575.74303
F42: No of shares | G42: =('Data Sheet'!K70/10000000) -> 10.155916 | I42: =I43-1% -> 0.032 | J42: 1569.5943 | K42: 1121.948 | L42: 871.46038 | M42: 711.4769 | N42: 651.3885
F43: Value Per Share | G43: =G41/G42 -> 1082.756 | I43: 0.042 | J43: 2502.0598 | K43: 1513.4937 | L43: 1082.7253 | M43: 841.65738 | N43: 757.01522
F44: CMP | G44: =Profile!C43 -> 1439.8 | I44: =I43+1% -> 0.052 | J44: 6848.9835 | K44: 2411.5058 | L44: 1459.9362 | M44: 1045.2579 | N44: 914.85244
F45: OV/UV By | G45: =(G43/G44)-1 -> -0.24798163 | I45: =I44+1% -> 0.062 | J45: -7961.408 | K45: 6597.8159 | L45: 2325.0715 | M45: 1408.7841 | N45: 1176.319
...

Sheet V3
B3: V | C3: aluations
B6: Relative Valuation
B8: Relative Valuation method 22/08/26 Healthcare
E10: Market Data | K10: Financials | O10: Valuation
B11: Company | D11: Ticker | E11: Share Price | F11: Shares Outstanding | G11: Equity Value | H11: Net Debt | I11: Enterprise Value | K11: Revenue | L11: EBITDA | M11: Net Income | O11: EV/Revenue | P11: EV/EBITDA | Q11: P/E
A13: x | B13: Rainbow Hosp. | D13: RAINBOW | E13: =Profile!C43 -> 1439.8 | F13: ='Data Sheet'!K70/10000000 -> 10.155916 | G13: =E13*F13 -> 14622.487 | H13: =891-20.3 -> 870.7 | I13: =G13+H13 -> 15493.187 | K13: 1820 | L13: ='H2'!I28 -> 548.44 | M13: ='H2'!I41 -> 281.54 | O13: =I13/K13 -> 8.5127403 | P13: =I13/L13 -> 28.249557 | Q13: =G13/M13 -> 51.937513
B14: Max | D14: MAXHEALTH | E14: 1000 | F14: 97.2 | G14: =E14*F14 -> 97200 | H14: =3478-682 -> 2796 | I14: =G14+H14 -> 99996 | K14: 8712 | L14: 2318 | M14: 1457 | O14: =I14/K14 -> 11.477961 | P14: =I14/L14 -> 43.138913 | Q14: =G14/M14 -> 66.712423
B15: Apollo | D15: APOLLOHOSP | E15: 8693 | F15: 14.4 | G15: =E15*F15 -> 125179.2 | H15: =8493-1360 -> 7133 | I15: =G15+H15 -> 132312.2 | K15: 26430 | L15: 4010 | M15: 2172 | O15: =I15/K15 -> 5.006137 | P15: =I15/L15 -> 32.995561 | Q15: =G15/M15 -> 57.633149
B16: Fortis | D16: FORTIS | E16: 907 | F16: 75.5 | G16: =E16*F16 -> 68478.5 | H16: =3473-508 -> 2965 | I16: =G16+H16 -> 71443.5 | K16: 9506 | L16: 2131 | M16: 1070 | O16: =I16/K16 -> 7.5156217 | P16: =I16/L16 -> 33.525809 | Q16: =G16/M16 -> 63.998598
B17: Aster DM | D17: ASTERDM | E17: 762 | F17: 87.17 | G17: =E17*F17 -> 66423.54 | H17: =2220-1380 -> 840 | I17: =G17+H17 -> 67263.54 | K17: 4876 | L17: 918 | M17: 363 | O17: =I17/K17 -> 13.79482 | P17: =I17/L17 -> 73.27183 | Q17: =G17/M17 -> 182.98496
B18: Medanta | D18: MEDANTA | E18: 1410 | F18: 26.9 | G18: =E18*F18 -> 37929 | H18: =1190-1122 -> 68 | I18: =G18+H18 -> 37997 | K18: 4683 | L18: 979 | M18: 552 | O18: =I18/K18 -> 8.1138159 | P18: =I18/L18 -> 38.812053 | Q18: =G18/M18 -> 68.711957
A20: x | B20: High | O20: =MAX(O14:O18) -> 13.79482 | P20: =MAX(P14:P18) -> 73.27183 | Q20: =MAX(Q14:Q18) -> 182.98496
B21: 75th Percentile | O21: =QUARTILE(O14:O18,3) -> 11.477961 | P21: =QUARTILE(P14:P18,3) -> 43.138913 | Q21: =QUARTILE(Q14:Q18,3) -> 68.711957
B22: Average | O22: =AVERAGE(O14:O18) -> 9.1816711 | P22: =AVERAGE(P14:P18) -> 44.348833 | Q22: =AVERAGE(Q14:Q18) -> 88.008217
B23: Median | O23: =MEDIAN(O14:O18) -> 8.1138159 | P23: =MEDIAN(P14:P18) -> 38.812053 | Q23: =MEDIAN(Q14:Q18) -> 66.712423
B24: 25th Percentile | O24: =QUARTILE(O14:O18,1) -> 7.5156217 | P24: =QUARTILE(P14:P18,1) -> 33.525809 | Q24: =QUARTILE(Q14:Q18,1) -> 63.998598
B25: Low | O25: =MIN(O14:O18) -> 5.006137 | P25: =MIN(P14:P18) -> 32.995561 | Q25: =MIN(Q14:Q18) -> 57.633149
A27: x | B27: Max Health | O27: EV/Revenue | P27: EV/EBITDA | Q27: P/E
B28: Implied Enterprise Value | O28: =K13*O23 -> 14767.145 | P28: =L13*P23 -> 21286.082 | Q28: =Q30-Q29 -> 17911.516
B29: Net Debt | O29: =H13 -> 870.7 | P29: =O29 -> 870.7 | Q29: =H13 -> 870.7
B30: Implied Market Value | O30: =O28-O29 -> 13896.445 | P30: =P28-P29 -> 20415.382 | Q30: =M13*Q23 -> 18782.216
B31: Shares Outstanding | O31: =F13 -> 10.155916 | P31: =O31 -> 10.155916 | Q31: =P31 -> 10.155916
A32: x | B32: Implied Value Per Share | O32: =O30/O31 -> 1368.3104 | P32: =P30/P31 -> 2010.1961 | Q32: =Q30/Q31 -> 1849.3867
O33: =IF(E13<O32,"Undervalued","Overvalued") -> Overvalued | P33: =IF($D$7<P32,"Undervalued","Overvalued") -> Undervalued | Q33: =IF($D$7<Q32,"Undervalued","Overvalued") -> Undervalued
B35: Interpretation

Sheet Risks
B4: R | C4: isks

Sheet Dupont
B4: R | C4: isks
B7: Return on Equity (ROE)
E8: 44651 | F8: 45016 | G8: 45382 | H8: 45747 | I8: 46112
B9: Net Profit | E9: ='H2'!E41 -> 138.68 | F9: ='H2'!F41 -> 212.38 | G9: ='H2'!G41 -> 218.29 | H9: ='H2'!H41 -> 244.22 | I9: ='H2'!I41 -> 281.54
B10: Average Shareholder Equity | E10: =SUM('Balance Sheet'!U4:U5) -> 592 | F10: =SUM('Balance Sheet'!V4:V5) -> 1060 | G10: =SUM('Balance Sheet'!W4:W5) -> 1259 | H10: =SUM('Balance Sheet'!X4:X5) -> 1469 | I10: =SUM('Balance Sheet'!Y4:Y5) -> 1649
B11: Return on Equity | E11: =E9/E10 -> 0.23425676 | F11: =F9/F10 -> 0.20035849 | G11: =G9/G10 -> 0.17338364 | H11: =H9/H10 -> 0.16624915 | I11: =I9/I10 -> 0.17073378
B13: ROE - Dupont Equation
E14: =E8 -> 44651 | F14: =F8 -> 45016 | G14: =G8 -> 45382 | H14: =H8 -> 45747 | I14: =I8 -> 46112
B15: =B9 -> Net Profit | E15: =E9 -> 138.68 | F15: =F9 -> 212.38 | G15: =G9 -> 218.29 | H15: =H9 -> 244.22 | I15: =I9 -> 281.54
B16: Revenue | E16: ='H2'!E9 -> 973.76 | F16: ='H2'!F9 -> 1173.57 | G16: ='H2'!G9 -> 1296.9 | H16: ='H2'!H9 -> 1515.87 | I16: ='H2'!I9 -> 1703.08
B17: Net Profit Margin | E17: =E15/E16 -> 0.14241702 | F17: =F15/F16 -> 0.18096918 | G17: =G15/G16 -> 0.16831676 | H17: =H15/H16 -> 0.1611088 | I17: =I15/I16 -> 0.16531226
B19: Revenue | E19: =E16 -> 973.76 | F19: =F16 -> 1173.57 | G19: =G16 -> 1296.9 | H19: =H16 -> 1515.87 | I19: =I16 -> 1703.08
B20: Average Total Asset | E20: {=SUM('Balance Sheet'!T38:U380/2)} -> 1188.5 | F20: {=SUM('Balance Sheet'!U38:V380/2)} -> 1533.5 | G20: {=SUM('Balance Sheet'!V38:W380/2)} -> 1970.5 | H20: {=SUM('Balance Sheet'!W38:X380/2)} -> 2273.5 | I20: {=SUM('Balance Sheet'!X38:Y380/2)} -> 2576
B21: Asset Turnover Ratio | E21: =E19/E20 -> 0.81931847 | F21: =F19/F20 -> 0.76528856 | G21: =G19/G20 -> 0.65815783 | H21: =H19/H20 -> 0.6667561 | I21: =I19/I20 -> 0.66113354
B23: =B20 -> Average Total Asset | E23: =E20 -> 1188.5 | F23: =F20 -> 1533.5 | G23: =G20 -> 1970.5 | H23: =H20 -> 2273.5 | I23: =I20 -> 2576
B24: =B10 -> Average Shareholder Equity | E24: =E10 -> 592 | F24: =F10 -> 1060 | G24: =G10 -> 1259 | H24: =H10 -> 1469 | I24: =I10 -> 1649
B25: Equity Multiplier (C) | E25: =E23/E24 -> 2.0076014 | F25: =F23/F24 -> 1.4466981 | G25: =G23/G24 -> 1.5651311 | H25: =H23/H24 -> 1.5476515 | I25: =I23/I24 -> 1.5621589
B27: Return on Equity (A*B*C) | E27: =E25*E21*E17 -> 0.23425676 | F27: =F25*F21*F17 -> 0.20035849 | G27: =G25*G21*G17 -> 0.17338364 | H27: =H25*H21*H17 -> 0.16624915 | I27: =I25*I21*I17 -> 0.17073378
B29: Return on Asset
E30: =E14 -> 44651 | F30: =F14 -> 45016 | G30: =G14 -> 45382 | H30: =H14 -> 45747 | I30: =I14 -> 46112
B31: Net Profit | E31: =E15 -> 138.68 | F31: =F15 -> 212.38 | G31: =G15 -> 218.29 | H31: =H15 -> 244.22 | I31: =I15 -> 281.54
B32: =B23 -> Average Total Asset | E32: =E20 -> 1188.5 | F32: =F20 -> 1533.5 | G32: =G20 -> 1970.5 | H32: =H20 -> 2273.5 | I32: =I20 -> 2576
B33: Return on Asset | E33: =E31/E32 -> 0.1166849 | F33: =F31/F32 -> 0.13849364 | G33: =G31/G32 -> 0.11077899 | H33: =H31/H32 -> 0.10742028 | I33: =I31/I32 -> 0.10929348
B35: ROA - Dupont Equation
E36: =E30 -> 44651 | F36: =F30 -> 45016 | G36: =G30 -> 45382 | H36: =H30 -> 45747 | I36: =I30 -> 46112
B37: =B31 -> Net Profit | E37: =E31 -> 138.68 | F37: =F31 -> 212.38 | G37: =G31 -> 218.29 | H37: =H31 -> 244.22 | I37: =I31 -> 281.54
B38: Revenue | E38: =E19 -> 973.76 | F38: =F19 -> 1173.57 | G38: =G19 -> 1296.9 | H38: =H19 -> 1515.87 | I38: =I19 -> 1703.08
B39: Net Profit Margin (A) | E39: =E37/E38 -> 0.14241702 | F39: =F37/F38 -> 0.18096918 | G39: =G37/G38 -> 0.16831676 | H39: =H37/H38 -> 0.1611088 | I39: =I37/I38 -> 0.16531226
B41: Revenue | E41: =E38 -> 973.76 | F41: =F38 -> 1173.57 | G41: =G38 -> 1296.9 | H41: =H38 -> 1515.87 | I41: =I38 -> 1703.08
B42: Average Total Asset | E42: =E32 -> 1188.5 | F42: =F32 -> 1533.5 | G42: =G32 -> 1970.5 | H42: =H32 -> 2273.5 | I42: =I32 -> 2576
B43: Asset Turnover Ratio (B) | E43: =E41/E42 -> 0.81931847 | F43: =F41/F42 -> 0.76528856 | G43: =G41/G42 -> 0.65815783 | H43: =H41/H42 -> 0.6667561 | I43: =I41/I42 -> 0.66113354
B45: Return on Asset (A*B) | E45: =E43*E39 -> 0.1166849 | F45: =F43*F39 -> 0.13849364 | G45: =G43*G39 -> 0.11077899 | H45: =H43*H39 -> 0.10742028 | I45: =I43*I39 -> 0.10929348
B47: Interpretation

Sheet Altman Z
B4: R | C4: isks
B7: Working Capital / Total Assets
E8: 44651 | F8: 45016 | G8: 45382 | H8: 45747 | I8: 46112
B9: Working Capital | E9: ='Data Sheet'!G65-'Data Sheet'!G60 -> 297.41 | F9: =SUM('Balance Sheet'!V32-'Balance Sheet'!V12) -> 619 | G9: =SUM('Balance Sheet'!W32-'Balance Sheet'!W12) -> 444 | H9: =SUM('Balance Sheet'!X32-'Balance Sheet'!X12) -> 235 | I9: =SUM('Balance Sheet'!Y32-'Balance Sheet'!Y12) -> 299
B10: Total Assets | E10: ='Balance Sheet'!U38 -> 1296 | F10: ='Balance Sheet'!V38 -> 1771 | G10: ='Balance Sheet'!W38 -> 2170 | H10: ='Balance Sheet'!X38 -> 2377 | I10: ='Balance Sheet'!Y38 -> 2775
B11: Working Capital / Total Assets (A) | E11: =E9/E10 -> 0.22948302 | F11: =F9/F10 -> 0.34952005 | G11: =G9/G10 -> 0.20460829 | H11: =H9/H10 -> 0.098864114 | I11: =I9/I10 -> 0.10774775
B13: Retained Earnings / Total Assets
E14: =E8 -> 44651 | F14: =F8 -> 45016 | G14: =G8 -> 45382 | H14: =H8 -> 45747 | I14: =I8 -> 46112
B15: Retained Earnings | E15: ='H2'!E52 -> 0.864364 | F15: ='H2'!F52 -> 0.85662492 | G15: ='H2'!G52 -> 0.86050667 | H15: ='H2'!H52 -> 0.87527639 | I15: ='H2'!I52 -> 0.8737302
B16: Total Assets | E16: =E10 -> 1296 | F16: =F10 -> 1771 | G16: =G10 -> 2170 | H16: =H10 -> 2377 | I16: =I10 -> 2775
B17: Retained Earnings / Total Assets (B) | E17: =E15/E16 -> 0.00066694753 | F17: =F15/F16 -> 0.00048369561 | G17: =G15/G16 -> 0.00039654685 | H17: =H15/H16 -> 0.00036822734 | I17: =I15/I16 -> 0.00031485773
B19: EBIT / Total Assets
B20: EBIT | E20: ='H2'!E32 -> 224.67 | F20: ='H2'!F32 -> 309.3 | G20: ='H2'!G32 -> 320.29 | H20: ='H2'!H32 -> 355.8 | I20: ='H2'!I32 -> 397.87
B21: Total Assets | E21: =E16 -> 1296 | F21: =F16 -> 1771 | G21: =G16 -> 2170 | H21: =H16 -> 2377 | I21: =I16 -> 2775
B22: EBIT/Total Assets (C) | E22: =E20/E21 -> 0.17335648 | F22: =F20/F21 -> 0.17464709 | G22: =G20/G21 -> 0.14759908 | H22: =H20/H21 -> 0.14968448 | I22: =I20/I21 -> 0.14337658
B24: Market Cap / Liabilities
B25: Market Cap | E25: =450.2*'Data Sheet'!G93 -> 4236.382 | F25: ='Data Sheet'!H90*'Data Sheet'!H93 -> 7414.575 | G25: ='Data Sheet'!I90*'Data Sheet'!I93 -> 13170.132 | H25: ='Data Sheet'!J90*'Data Sheet'!J93 -> 14241.272 | I25: =Profile!C43*('Data Sheet'!K70/10000000) -> 14622.487
B26: Long Term Liabilities | E26: ='Balance Sheet'!U6 -> 592 | F26: ='Balance Sheet'!V6 -> 570 | G26: ='Balance Sheet'!W6 -> 765 | H26: ='Balance Sheet'!X6 -> 764 | I26: ='Balance Sheet'!Y6 -> 891
B27: Market Cap / Liabilities (D) | E27: =E25/E26 -> 7.1560507 | F27: =IFERROR(F25/F26,0) -> 13.008026 | G27: =G25/G26 -> 17.215859 | H27: =H25/H26 -> 18.640408 | I27: =I25/I26 -> 16.411321
B29: Sales / Total Assets
E30: =E14 -> 44651 | F30: =F14 -> 45016 | G30: =G14 -> 45382 | H30: =H14 -> 45747 | I30: =I14 -> 46112
B31: Total Sales | E31: ='H2'!E9 -> 973.76 | F31: ='H2'!F9 -> 1173.57 | G31: ='H2'!G9 -> 1296.9 | H31: ='H2'!H9 -> 1515.87 | I31: ='H2'!I9 -> 1703.08
B32: Total Assets | E32: =E10 -> 1296 | F32: =F10 -> 1771 | G32: =G10 -> 2170 | H32: =H10 -> 2377 | I32: =I10 -> 2775
B33: Return on Asset (E) | E33: =E31/E32 -> 0.75135802 | F33: =F31/F32 -> 0.66265951 | G33: =G31/G32 -> 0.59764977 | H33: =H31/H32 -> 0.63772402 | I33: =I31/I32 -> 0.61372252
B35: Altman's Z Score
E36: =E30 -> 44651 | F36: =F30 -> 45016 | G36: =G30 -> 45382 | H36: =H30 -> 45747 | I36: =I30 -> 46112
B37: Final Score | E37: =(E11*1.2)+(E17*1.4)+(E22*3.3)+(E27*0.6)+(E33*1) -> 5.8933782 | F37: =(F11*1.2)+(F17*1.4)+(F22*3.3)+(F27*0.6)+(F33*1) -> 9.4639119 | G37: =(G11*1.2)+(G17*1.4)+(G22*3.3)+(G27*0.6)+(G33*1) -> 11.660328 | H37: =(H11*1.2)+(H17*1.4)+(H22*3.3)+(H27*0.6)+(H33*1) -> 12.43508 | I37: =(I11*1.2)+(I17*1.4)+(I22*3.3)+(I27*0.6)+(I33*1) -> 11.063396
B38: Financial Stability | E38: =IF(E37<1.81," Distressed",IF(E37>3,"Strong","Grey Zone")) -> Strong | F38: =IF(F37<1.81," Distressed",IF(F37>3,"Strong","Grey Zone")) -> Strong | G38: =IF(G37<1.81," Distressed",IF(G37>3,"Strong","Grey Zone")) -> Strong | H38: =IF(H37<1.81," Distressed",IF(H37>3,"Strong","Grey Zone")) -> Strong | I38: =IF(I37<1.81," Distressed",IF(I37>3,"Strong","Grey Zone")) -> Strong
B40: Interpretation

Sheet Monte Carlo
B4: R | C4: isks
B7: Date | C7: Price | D7: Return | E7: Sorted Return | G7: Replication | H7: Simulated Returns | J7: Calculation of Value at Risk - Apollo Tyres (Simulation)
B8: 44712 | C8: =Closing!Q2 -> 490.58237
B9: 44742 | C9: =Closing!Q3 -> 459.74826 | D9: =C9/C8-1 -> -0.062852048 | E9: 0.25014224 | G9: 1 | H9: =NORMINV(RAND(),N$10,N$11) -> 0.10881665 | J9: Historical Approach
B10: 44773 | C10: =Closing!Q4 -> 482.49149 | D10: =C10/C9-1 -> 0.049468866 | E10: 0.24887534 | G10: 2 | H10: =NORMINV(RAND(),N$10,N$11) -> -0.078434446 | J10: Mean | N10: =AVERAGE(E9:E59) -> 0.024543064
B11: 44804 | C11: =Closing!Q5 -> 602.57172 | D11: =C11/C10-1 -> 0.24887534 | E11: 0.15312364 | G11: 3 | H11: =NORMINV(RAND(),N$10,N$11) -> -0.014068853 | J11: Std Deviation | N11: =STDEV(E9:E59) -> 0.082906077
B12: 44834 | C12: =Closing!Q6 -> 624.55133 | D12: =C12/C11-1 -> 0.036476346 | E12: 0.14868374 | G12: 4 | H12: =NORMINV(RAND(),N$10,N$11) -> 0.10522255 | J12: Min | N12: =MIN(E9:E59) -> -0.13780305
B13: 44865 | C13: =Closing!Q7 -> 682.17029 | D13: =C13/C12-1 -> 0.09225656 | E13: 0.130768 | G13: 5 | H13: =NORMINV(RAND(),N$10,N$11) -> 0.038140484 | J13: Max | N13: =MAX(E9:E59) -> 0.25014224
B14: 44895 | C14: =Closing!Q8 -> 738.10614 | D14: =C14/C13-1 -> 0.081996905 | E14: 0.11594412 | G14: 6 | H14: =NORMINV(RAND(),N$10,N$11) -> -0.021834801 | J14: CMP | N14: =Profile!C43 -> 1439.8
B15: 44926 | C15: =Closing!Q9 -> 731.81952 | D15: =C15/C14-1 -> -0.0085172318 | E15: 0.11465184 | G15: 7 | H15: =NORMINV(RAND(),N$10,N$11) -> -0.053175723
B16: 44957 | C16: =Closing!Q10 -> 759.29254 | D16: =C16/C15-1 -> 0.037540707 | E16: 0.11157167 | G16: 8 | H16: =NORMINV(RAND(),N$10,N$11) -> 0.072727492 | J16: Monte Carlo Simulation
B17: 44985 | C17: =Closing!Q11 -> 733.15607 | D17: =C17/C16-1 -> -0.034422141 | E17: 0.10441806 | G17: 9 | H17: =NORMINV(RAND(),N$10,N$11) -> -0.04779308 | J17: Mean | N17: =AVERAGE(H9:H213) -> 0.031976675
B18: 45016 | C18: =Closing!Q12 -> 723.20642 | D18: =C18/C17-1 -> -0.01357098 | E18: 0.10221196 | G18: 10 | H18: =NORMINV(RAND(),N$10,N$11) -> 0.076266082 | J18: Std Deviation | N18: =STDEV(H9:H213) -> 0.079829111
B19: 45046 | C19: =Closing!Q13 -> 783.44879 | D19: =C19/C18-1 -> 0.083298999 | E19: 0.09225656 | G19: 11 | H19: =NORMINV(RAND(),N$10,N$11) -> -0.06635921 | J19: Min | N19: =MIN(H9:H213) -> -0.14279936
B20: 45077 | C20: =Closing!Q14 -> 979.42242 | D20: =C20/C19-1 -> 0.25014224 | E20: 0.083298999 | G20: 12 | H20: =NORMINV(RAND(),N$10,N$11) -> 0.11563032 | J20: Max | N20: =MAX(H9:H213) -> 0.23239674
B21: 45107 | C21: =Closing!Q15 -> 954.43396 | D21: =C21/C20-1 -> -0.02551347 | E21: 0.081996905 | G21: 13 | H21: =NORMINV(RAND(),N$10,N$11) -> 0.066149042 | J21: CMP | N21: =N14 -> 1439.8
B22: 45138 | C22: =Closing!Q16 -> 1096.3428 | D22: =C22/C21-1 -> 0.14868374 | E22: 0.081166874 | G22: 14 | H22: =NORMINV(RAND(),N$10,N$11) -> 0.15472472
B23: 45169 | C23: =Closing!Q17 -> 1052.1017 | D23: =C23/C22-1 -> -0.040353337 | E23: 0.076691647 | G23: 15 | H23: =NORMINV(RAND(),N$10,N$11) -> 0.034229683 | J23: Percentile | L23: VAR % | M23: Stock Price | N23: VAR (INR)
B24: 45199 | C24: =Closing!Q18 -> 1021.2175 | D24: =C24/C23-1 -> -0.029354725 | E24: 0.070026493 | G24: 16 | H24: =NORMINV(RAND(),N$10,N$11) -> 0.11576871 | J24: 0.05 | L24: =PERCENTILE($H$9:$H$50008,J24) -> -0.10261676 | M24: =L24*(1-$N$21) -> 147.64499 | N24: =$N$21-M24 -> 1292.155
B25: 45230 | C25: =Closing!Q19 -> 1055.7761 | D25: =C25/C24-1 -> 0.03384058 | E25: 0.059843464 | G25: 17 | H25: =NORMINV(RAND(),N$10,N$11) -> -0.0057811614 | J25: 0.01 | L25: =PERCENTILE($H$9:$H$50008,J25) -> -0.14024925 | M25: =L25*(1-$N$21) -> 201.79062 | N25: =$N$21-M25 -> 1238.0094
B26: 45260 | C26: =Closing!Q20 -> 1065.8558 | D26: =C26/C25-1 -> 0.0095472058 | E26: 0.049468866 | G26: 18 | H26: =NORMINV(RAND(),N$10,N$11) -> -0.083587351 | J26: 0.005 | L26: =PERCENTILE($H$9:$H$50008,J26) -> -0.15142393 | M26: =L26*(1-$N$21) -> 217.86875 | N26: =$N$21-M26 -> 1221.9312
B27: 45291 | C27: =Closing!Q21 -> 1184.7751 | D27: =C27/C26-1 -> 0.11157167 | E27: 0.045338747 | G27: 19 | H27: =NORMINV(RAND(),N$10,N$11) -> -0.027215075
B28: 45322 | C28: =Closing!Q22 -> 1209.1549 | D28: =C28/C27-1 -> 0.020577542 | E28: 0.037540707 | G28: 20 | H28: =NORMINV(RAND(),N$10,N$11) -> 0.18465263
B29: 45351 | C29: =Closing!Q23 -> 1347.7867 | D29: =C29/C28-1 -> 0.11465184 | E29: 0.036476346 | G29: 21 | H29: =NORMINV(RAND(),N$10,N$11) -> -0.077555706
B30: 45382 | C30: =Closing!Q24 -> 1288.5505 | D30: =C30/C29-1 -> -0.043950726 | E30: 0.03384058 | G30: 22 | H30: =NORMINV(RAND(),N$10,N$11) -> -0.063189085
B31: 45412 | C31: =Closing!Q25 -> 1365.6619 | D31: =C31/C30-1 -> 0.059843464 | E31: 0.024559747 | G31: 23 | H31: =NORMINV(RAND(),N$10,N$11) -> 0.11118776
B32: 45443 | C32: =Closing!Q26 -> 1291.6786 | D32: =C32/C31-1 -> -0.054173934 | E32: 0.020577542 | G32: 24 | H32: =NORMINV(RAND(),N$10,N$11) -> 0.11713608
B33: 45473 | C33: =Closing!Q27 -> 1237.2091 | D33: =C33/C32-1 -> -0.042169533 | E33: 0.015053919 | G33: 25 | H33: =NORMINV(RAND(),N$10,N$11) -> -0.051286228
B34: 45504 | C34: =Closing!Q28 -> 1179.4225 | D34: =C34/C33-1 -> -0.046707239 | E34: 0.0098819749 | G34: 26 | H34: =NORMINV(RAND(),N$10,N$11) -> 0.0034811798
B35: 45535 | C35: =Closing!Q29 -> 1262.0133 | D35: =C35/C34-1 -> 0.070026493 | E35: 0.0095472058 | G35: 27 | H35: =NORMINV(RAND(),N$10,N$11) -> 0.062572531
B36: 45565 | C36: =Closing!Q30 -> 1393.7903 | D36: =C36/C35-1 -> 0.10441806 | E36: -0.0085172318 | G36: 28 | H36: =NORMINV(RAND(),N$10,N$11) -> -0.029283679
B37: 45596 | C37: =Closing!Q31 -> 1607.2125 | D37: =C37/C36-1 -> 0.15312364 | E37: -0.013217428 | G37: 29 | H37: =NORMINV(RAND(),N$10,N$11) -> 0.021725812
B38: 45626 | C38: =Closing!Q32 -> 1582.5199 | D38: =C38/C37-1 -> -0.015363635 | E38: -0.01357098 | G38: 30 | H38: =NORMINV(RAND(),N$10,N$11) -> -0.092671454
... B59: 46265 | C59: =Closing!Q53 -> 1439.8 | D59: =C59/C58-1 -> -0.056116412 | E59: -0.13780305 | G59: 51 | H59: =NORMINV(RAND(),N$10,N$11) -> -0.027875322
B60: - | C60: - | D60: - | E60: - | F60: - | G60: 52 | H60: =NORMINV(RAND(),N$10,N$11) -> -0.023030346
G61: 53 | H61: =NORMINV(RAND(),N$10,N$11) -> 0.12076544
G62: 54 | H62: =NORMINV(RAND(),N$10,N$11) -> 0.13255204
G63: 55 | H63: =NORMINV(RAND(),N$10,N$11) -> 0.054015149
G64: 56 | H64: =NORMINV(RAND(),N$10,N$11) -> 0.07255848
G65: 57 | H65: =NORMINV(RAND(),N$10,N$11) -> -0.038546162
...

Sheet Conclusion
B4: C | C4: onclusion
B7: RATING | D7: CMP | F7: TARGET | H7: UPSIDE/DOWNSIDE | J7: HORIZON
N8: Why Rainbow Childrens Medicare Ltd.
B12: Investment Rationale
N21: Key Risks
N32: SPECIAL THANKS TO
N33: Dr. Anju Virmani

Sheet Data Sheet
A1: COMPANY NAME | B1: RAINBOW CHILDRENS MEDICARE LTD | E1: =IF(B2<>B3, "A NEW VERSION OF THE WORKSHEET IS AVAILABLE", "")
A2: LATEST VERSION | B2: 2.1 | E2: PLEASE DO NOT MAKE ANY CHANGES TO THIS SHEET
A3: CURRENT VERSION | B3: 2.1
A5: META
A6: Number of shares | B6: =IF(B9>0, B9/B8, 0) -> 10.156663
A7: Face Value | B7: 10
A8: Current Price | B8: 1453.5
A9: Market Capitalization | B9: 14762.71
A15: PROFIT & LOSS
A16: Report Date | B16: 42825 | C16: 43190 | D16: 43555 | E16: 43921 | F16: 44286 | G16: 44651 | H16: 45016 | I16: 45382 | J16: 45747 | K16: 46112
A17: Sales | B17: 321.29 | C17: 401.83 | D17: 542.79 | E17: 719.39 | F17: 650.05 | G17: 973.76 | H17: 1173.57 | I17: 1296.9 | J17: 1515.87 | K17: 1703.08
A18: Raw Material Cost | B18: 51.62 | C18: 59.99 | D18: 80.21 | E18: 105.31 | F18: 103.26 | G18: 194.73 | H18: 158.28 | I18: 165.28 | J18: 194.92 | K18: 227.03
A19: Change in Inventory
A20: Power and Fuel | B20: 8.27 | C20: 9.33 | D20: 12.35 | E20: 14.86 | F20: 13.84 | G20: 16.81 | H20: 21.23 | I20: 26.61 | J20: 27.72 | K20: 28.85
A21: Other Mfr. Exp | B21: 10.95 | C21: 14.71 | D21: 45.83 | E21: 65.58 | F21: 56.7 | G21: 65.6 | H21: 86.85 | I21: 95.72 | J21: 115.32 | K21: 126.46
A22: Employee Cost | B22: 69.22 | C22: 88.24 | D22: 85.8 | E22: 109.01 | F22: 102.14 | G22: 116.37 | H22: 144.56 | I22: 176.71 | J22: 206.82 | K22: 234.11
A23: Selling and admin | B23: 35.55 | C23: 46.36 | D23: 163.36 | E23: 216.75 | F23: 202.75 | G23: 266.44 | H23: 350.18 | I23: 395.45 | J23: 469.57 | K23: 525.36
A24: Other Expenses | B24: 90.71 | C24: 113.79 | D24: 3.79 | E24: 7.2 | F24: 6.22 | G24: 5.88 | H24: 12.9 | I24: 4.76 | J24: 7.28 | K24: 12.83
A25: Other Income | B25: 11.07 | C25: 9.6 | D25: 8.35 | E25: 10.35 | F25: 10.26 | G25: 18.85 | H25: 30.87 | I25: 37.06 | J25: 51.01 | K25: 42.25
A26: Depreciation | B26: 21.89 | C26: 28.08 | D26: 60.32 | E26: 69.41 | F26: 73.34 | G26: 83.26 | H26: 90.27 | I26: 112.08 | J26: 138.44 | K26: 150.57
A27: Interest | B27: 2.9 | C27: 4.27 | D27: 41.96 | E27: 48.26 | F27: 46.37 | G27: 56.17 | H27: 58.39 | I27: 62.53 | J27: 76.81 | K27: 81.89
A28: Profit before tax | B28: 41.25 | C28: 46.66 | D28: 57.52 | E28: 93.36 | F28: 55.69 | G28: 187.35 | H28: 281.78 | I28: 294.82 | J28: 330 | K28: 358.23
A29: Tax | B29: 9.9 | C29: 10.39 | D29: 12.93 | E29: 38.02 | F29: 16.13 | G29: 48.67 | H29: 69.4 | I29: 76.53 | J29: 85.78 | K29: 76.69
A30: Net profit | B30: 31.35 | C30: 36.27 | D30: 44.59 | E30: 55.73 | F30: 40.02 | G30: 138.27 | H30: 210.83 | I30: 217 | J30: 243.42 | K30: 278.32
A31: Dividend Amount | B31: 2.32 | C31: 4.4 | D31: 4.4 | E31: 8.79 | G31: 18.81 | H31: 30.45 | I31: 30.45 | J31: 30.46 | K31: 35.55
A40: Quarters
A41: Report Date | B41: 45382 | C41: 45473 | D41: 45565 | E41: 45657 | F41: 45747 | G41: 45838 | H41: 45930 | I41: 46022 | J41: 46112 | K41: 46203
A42: Sales | B42: 341.1 | C42: 330.22 | D42: 417.46 | E42: 398.08 | F42: 370.11 | G42: 352.93 | H42: 444.8 | I42: 445.45 | J42: 459.9 | K42: 469.99
A43: Expenses | B43: 235.56 | C43: 236.49 | D43: 270.38 | E43: 263.72 | F43: 255.39 | G43: 249.31 | H43: 295.94 | I43: 298.47 | J43: 315.19 | K43: 335.34
A44: Other Income | B44: 12.78 | C44: 11.93 | D44: 11.27 | E44: 13.27 | F44: 14.53 | G44: 20.02 | H44: 8.2 | I44: 10.51 | J44: 3.52 | K44: 12.71
A45: Depreciation | B45: 32.3 | C45: 34.14 | D45: 34.9 | E45: 35.23 | F45: 34.16 | G45: 34.19 | H45: 35.84 | I45: 39.6 | J45: 40.94 | K45: 42.2
A46: Interest | B46: 16.85 | C46: 18.16 | D46: 18.1 | E46: 18.07 | F46: 18.12 | G46: 18.08 | H46: 18.85 | I46: 20.2 | J46: 20.5 | K46: 21.21
A47: Profit before tax | B47: 69.17 | C47: 53.36 | D47: 105.35 | E47: 94.33 | F47: 76.97 | G47: 71.37 | H47: 102.37 | I47: 97.69 | J47: 86.79 | K47: 83.95
A48: Tax | B48: 18.11 | C48: 13.62 | D48: 26.34 | E48: 25.39 | F48: 20.42 | G48: 17.57 | H48: 26.74 | I48: 23.8 | J48: 8.57 | K48: 21.41
A49: Net profit | B49: 50.97 | C49: 39.53 | D49: 78.87 | E49: 68.69 | F49: 56.34 | G49: 53.5 | H49: 75.25 | I49: 72.53 | J49: 77.04 | K49: 60.57
A50: Operating Profit | B50: 105.54 | C50: 93.73 | D50: 147.08 | E50: 134.36 | F50: 114.72 | G50: 103.62 | H50: 148.86 | I50: 146.98 | J50: 144.71 | K50: 134.65
A55: BALANCE SHEET
A56: Report Date | B56: 42825 | C56: 43190 | D56: 43555 | E56: 43921 | F56: 44286 | G56: 44651 | H56: 45016 | I56: 45382 | J56: 45747 | K56: 46112
A57: Equity Share Capital | B57: 9.28 | C57: 43.96 | D57: 43.96 | E57: 43.96 | F57: 43.96 | G57: 94.05 | H57: 101.5 | I57: 101.5 | J57: 101.55 | K57: 101.56
