Workbook
Name UPDATE: 'Data Sheet'!$E$1
Name UPDATE: #REF!

Sheet Data Sheet
A1: COMPANY NAME | B1: TATA CONSUMER PRODUCTS LTD | E1: =IF(B2<>B3, "A NEW VERSION OF THE WORKSHEET IS AVAILABLE", "")
A2: LATEST VERSION | B2: 2.1 | E2: PLEASE DO NOT MAKE ANY CHANGES TO THIS SHEET
A3: CURRENT VERSION | B3: 2.1
A5: META
A6: Number of shares | B6: =IF(B9>0, B9/B8, 0) -> 98.95619
A7: Face Value | B7: 1
A8: Current Price | B8: 1250.4
A9: Market Capitalization | B9: 123734.82
A15: PROFIT & LOSS
A16: Report Date | B16: 42825 | C16: 43190 | D16: 43555 | E16: 43921 | F16: 44286 | G16: 44651 | H16: 45016 | I16: 45382 | J16: 45747 | K16: 46112
A17: Sales | B17: 6779.55 | C17: 6815.35 | D17: 7251.5 | E17: 9637.42 | F17: 11602.03 | G17: 12425.37 | H17: 13783.16 | I17: 15205.85 | J17: 17618.3 | K17: 20290.43
A18: Raw Material Cost | B18: 3165.65 | C18: 3746.11 | D18: 4022.05 | E18: 5402.9 | F18: 6367.79 | G18: 6323.22 | H18: 7107.06 | I18: 7364.06 | J18: 8986.68 | K18: 11896.39
A19: Change in Inventory | B19: 0.69 | C19: 46.8 | D19: 14.41 | E19: -7.78 | F19: 149.54 | G19: 39.78 | H19: 273.88 | I19: 121.6 | J19: 362.49 | K19: 40.75
A20: Power and Fuel | B20: 83.19 | C20: 87.07 | D20: 89.28 | E20: 103.84 | F20: 97.36 | G20: 123.9 | H20: 149.43 | I20: 156.9 | J20: 156.21
A21: Other Mfr. Exp | B21: 597.61 | C21: 194.69 | D21: 209.59 | E21: 238.47 | F21: 941.75 | G21: 1139.59 | H21: 1578.2 | I21: 1696.28 | J21: 1882.25
A22: Employee Cost | B22: 834.95 | C22: 821.37 | D22: 806.3 | E22: 884.8 | F22: 970.23 | G22: 1048 | H22: 1120.36 | I22: 1258.59 | J22: 1430.1 | K22: 1661
A23: Selling and admin | B23: 926.92 | C23: 857.64 | D23: 968.23 | E23: 1278.16 | F23: 1421.46 | G23: 1691.83 | H23: 1785.26 | I23: 1927.15 | J23: 2253.37
A24: Other Expenses | B24: 380.79 | C24: 316.36 | D24: 384.55 | E24: 429.32 | F24: 409.22 | G24: 419.83 | H24: 460.26 | I24: 640.37 | J24: 792.83 | K24: 3981.99
A25: Other Income | B25: 88.4 | C25: 73.02 | D25: 123.84 | E25: -163.2 | F25: 90.73 | G25: 88 | H25: 328.33 | I25: -81.42 | J25: 188.14 | K25: 144.69
A26: Depreciation | B26: 126.04 | C26: 116.04 | D26: 122.57 | E26: 241.71 | F26: 254.74 | G26: 278.01 | H26: 304.08 | I26: 377.15 | J26: 600.74 | K26: 626.68
A27: Interest | B27: 91.53 | C27: 42.76 | D27: 52.47 | E27: 77.86 | F27: 68.69 | G27: 72.78 | H27: 87.16 | I27: 129.81 | J27: 290.2 | K27: 137.03
A28: Profit before tax | B28: 661.96 | C28: 753.13 | D28: 734.71 | E28: 809.38 | F28: 1311.06 | G28: 1455.99 | H28: 1793.56 | I28: 1695.72 | J28: 1776.55 | K28: 2172.78
A29: Tax | B29: 198.31 | C29: 185.87 | D29: 260.88 | E29: 274.19 | F29: 317.27 | G29: 377.04 | H29: 447.04 | I29: 394.73 | J29: 396.24 | K29: 535.28
A30: Net profit | B30: 389.44 | C30: 495.56 | D30: 408.19 | E30: 459.76 | F30: 856.69 | G30: 935.78 | H30: 1203.77 | I30: 1150.33 | J30: 1278.47 | K30: 1542.3
A31: Dividend Amount | B31: 148.31 | C31: 148.31 | D31: 157.78 | E31: 248.83 | F31: 373.25 | G31: 557.57 | H31: 785 | I31: 738.42 | J31: 816.34 | K31: 989.6
A40: Quarters
A41: Report Date | B41: 45291 | C41: 45382 | D41: 45473 | E41: 45565 | F41: 45657 | G41: 45747 | H41: 45838 | I41: 45930 | J41: 46022 | K41: 46112
A42: Sales | B42: 3803.92 | C42: 3926.94 | D42: 4352.07 | E42: 4214.45 | F42: 4443.56 | G42: 4608.22 | H42: 4778.91 | I42: 4965.9 | J42: 5112 | K42: 5433.62
A43: Expenses | B43: 3231.54 | C43: 3297.34 | D43: 3684.69 | E43: 3588.16 | F43: 3878.83 | G43: 3987.27 | H43: 4171.97 | I43: 4294.12 | J43: 4391.33 | K43: 4641.21
A44: Other Income | B44: -31.94 | C44: -177.35 | D44: 22.07 | E44: 18.8 | F44: 45.44 | G44: 101.83 | H44: 41.17 | I44: 38.01 | J44: 10.15 | K44: 55.36
A45: Depreciation | B45: 85.51 | C45: 115.76 | D45: 148 | E45: 149.33 | F45: 150.32 | G45: 153.09 | H45: 148.93 | I45: 153.28 | J45: 159.29 | K45: 165.18
A46: Interest | B46: 33.19 | C46: 42.83 | D46: 93.6 | E46: 98.69 | F46: 57.92 | G46: 39.99 | H46: 33.76 | I46: 33.23 | J46: 31.62 | K46: 38.42
A47: Profit before tax | B47: 421.74 | C47: 293.66 | D47: 447.85 | E47: 397.07 | F47: 401.93 | G47: 529.7 | H47: 465.42 | I47: 523.28 | J47: 539.91 | K47: 644.17
A48: Tax | B48: 106.21 | C48: 25.95 | D48: 133.7 | E48: 37.73 | F48: 102.18 | G48: 122.63 | H48: 118.98 | I48: 126.23 | J48: 137.12 | K48: 152.95
A49: Net profit | B49: 278.87 | C49: 216.63 | D49: 290.32 | E49: 364.42 | F49: 278.88 | G49: 344.85 | H49: 334.15 | I49: 404.46 | J49: 384.61 | K49: 419.08
A50: Operating Profit | B50: 572.38 | C50: 629.6 | D50: 667.38 | E50: 626.29 | F50: 564.73 | G50: 620.95 | H50: 606.94 | I50: 671.78 | J50: 720.67 | K50: 792.41
A55: BALANCE SHEET
A56: Report Date | B56: 42825 | C56: 43190 | D56: 43555 | E56: 43921 | F56: 44286 | G56: 44651 | H56: 45016 | I56: 45382 | J56: 45747 | K56: 46112
A57: Equity Share Capital | B57: 63.11 | C57: 63.11 | D57: 63.11 | E57: 92.16 | F57: 92.16 | G57: 92.16 | H57: 92.9 | I57: 95.28 | J57: 98.95 | K57: 98.96
A58: Reserves | B58: 6202.39 | C58: 6968.49 | D58: 7268.58 | E58: 13722.7 | F58: 14442.35 | G58: 15049.78 | H58: 16183.81 | I58: 15961.51 | J58: 19902.13 | K58: 21688.57
...

Sheet Income Statement
B2: TATA Consumers.
B3: Income Statement (₹ Cr) | C3: 2021 | D3: =C3+1 -> 2022 | E3: =D3+1 -> 2023 | F3: =E3+1 -> 2024 | G3: =F3+1 -> 2025 | H3: =G3+1 -> 2026 | I3: =H3+1 -> 2027 | J3: =I3+1 -> 2028 | K3: =J3+1 -> 2029
A4: x | B4: Sales | C4: ='Data Sheet'!F17 -> 11602.03 | D4: ='Data Sheet'!G17 -> 12425.37 | E4: ='Data Sheet'!H17 -> 13783.16 | F4: ='Data Sheet'!I17 -> 15205.85 | G4: ='Data Sheet'!J17 -> 17618.3 | H4: =G4*(1+H5) -> 19557.868 | I4: =H4*(1+I5) -> 21710.959 | J4: =I4*(1+J5) -> 24101.08 | K4: =J4*(1+K5) -> 26754.326
B5: Sales Growth % | D5: =D4/C4-1 -> 0.070965167 | E5: =E4/D4-1 -> 0.10927562 | F5: =F4/E4-1 -> 0.10321944 | G5: =G4/F4-1 -> 0.15865276 | H5: =((G4/C4)^(1/4)-1) -> 0.11008825 | I5: =H5 -> 0.11008825 | J5: =I5 -> 0.11008825 | K5: =J5 -> 0.11008825
A7: x | B7: COGS
B8: ='Data Sheet'!A18 -> Raw Material Cost | C8: ='Data Sheet'!F18 -> 6367.79 | D8: ='Data Sheet'!G18 -> 6323.22 | E8: ='Data Sheet'!H18 -> 7107.06 | F8: ='Data Sheet'!I18 -> 7364.06 | G8: ='Data Sheet'!J18 -> 8986.68
B9: ='Data Sheet'!A19 -> Change in Inventory | C9: ='Data Sheet'!F19 -> 149.54 | D9: ='Data Sheet'!G19 -> 39.78 | E9: ='Data Sheet'!H19 -> 273.88 | F9: ='Data Sheet'!I19 -> 121.6 | G9: ='Data Sheet'!J19 -> 362.49
B10: ='Data Sheet'!A20 -> Power and Fuel | C10: ='Data Sheet'!F20 -> 97.36 | D10: ='Data Sheet'!G20 -> 123.9 | E10: ='Data Sheet'!H20 -> 149.43 | F10: ='Data Sheet'!I20 -> 156.9 | G10: ='Data Sheet'!J20 -> 156.21
B11: ='Data Sheet'!A21 -> Other Mfr. Exp | C11: ='Data Sheet'!F21 -> 941.75 | D11: ='Data Sheet'!G21 -> 1139.59 | E11: ='Data Sheet'!H21 -> 1578.2 | F11: ='Data Sheet'!I21 -> 1696.28 | G11: ='Data Sheet'!J21 -> 1882.25
B13: Total COGS | C13: =IF(C9<0,SUM(C8:C11),SUM(C11,C10,C8)-C9) -> 7257.36 | D13: =IF(D9<0,SUM(D8:D11),SUM(D11,D10,D8)-D9) -> 7546.93 | E13: =IF(E9<0,SUM(E8:E11),SUM(E11,E10,E8)-E9) -> 8560.81 | F13: =IF(F9<0,SUM(F8:F11),SUM(F11,F10,F8)-F9) -> 9095.64 | G13: =IF(G9<0,SUM(G8:G11),SUM(G11,G10,G8)-G9) -> 10662.65 | H13: =H4*H14 -> 11836.482 | I13: =I4*I14 -> 13139.54 | J13: =J4*J14 -> 14586.049 | K13: =K4*K14 -> 16191.801
B14: COGS % of Sales | C14: =C13/C4 -> 0.62552502 | D14: =D13/D4 -> 0.60738071 | E14: =E13/E4 -> 0.62110648 | F14: =F13/F4 -> 0.59816715 | G14: =G13/G4 -> 0.60520311 | H14: =G14 -> 0.60520311 | I14: =H14 -> 0.60520311 | J14: =I14 -> 0.60520311 | K14: =J14 -> 0.60520311
A16: x | B16: Gross Profit | C16: =C4-C13 -> 4344.67 | D16: =D4-D13 -> 4878.44 | E16: =E4-E13 -> 5222.35 | F16: =F4-F13 -> 6110.21 | G16: =G4-G13 -> 6955.65 | H16: =H4-H13 -> 7721.3853 | I16: =I4-I13 -> 8571.4191 | J16: =J4-J13 -> 9515.0316 | K16: =K4-K13 -> 10562.525
B17: Gross Margin % Sales | C17: =C16/C4 -> 0.37447498 | D17: =D16/D4 -> 0.39261929 | E17: =E16/E4 -> 0.37889352 | F17: =F16/F4 -> 0.40183285 | G17: =G16/G4 -> 0.39479689 | H17: =H16/H4 -> 0.39479689 | I17: =I16/I4 -> 0.39479689 | J17: =J16/J4 -> 0.39479689 | K17: =K16/K4 -> 0.39479689
B18: Operating Expenses/SG&A
B19: ='Data Sheet'!A22 -> Employee Cost | C19: ='Data Sheet'!B22 -> 834.95 | D19: ='Data Sheet'!C22 -> 821.37 | E19: ='Data Sheet'!D22 -> 806.3 | F19: ='Data Sheet'!E22 -> 884.8 | G19: ='Data Sheet'!F22 -> 970.23
B20: ='Data Sheet'!A23 -> Selling and admin | C20: ='Data Sheet'!B23 -> 926.92 | D20: ='Data Sheet'!C23 -> 857.64 | E20: ='Data Sheet'!D23 -> 968.23 | F20: ='Data Sheet'!E23 -> 1278.16 | G20: ='Data Sheet'!F23 -> 1421.46
B21: ='Data Sheet'!A24 -> Other Expenses | C21: ='Data Sheet'!B24 -> 380.79 | D21: ='Data Sheet'!C24 -> 316.36 | E21: ='Data Sheet'!D24 -> 384.55 | F21: ='Data Sheet'!E24 -> 429.32 | G21: ='Data Sheet'!F24 -> 409.22
B22: Total OpEx | C22: =SUM(C19:C21) -> 2142.66 | D22: =SUM(D19:D21) -> 1995.37 | E22: =SUM(E19:E21) -> 2159.08 | F22: =SUM(F19:F21) -> 2592.28 | G22: =SUM(G19:G21) -> 2800.91 | H22: =H4*H23 -> 3109.2573 | I22: =I4*I23 -> 3451.5499 | J22: =J4*J23 -> 3831.525 | K22: =K4*K23 -> 4253.3309
B23: OpEx % Sales | C23: =C22/C4 -> 0.18467975 | D23: =D22/D4 -> 0.16058838 | E23: =E22/E4 -> 0.15664623 | F23: =F22/F4 -> 0.17047912 | G23: =G22/G4 -> 0.15897731 | H23: =G23 -> 0.15897731 | I23: =H23 -> 0.15897731 | J23: =I23 -> 0.15897731 | K23: =J23 -> 0.15897731
A24: x | B24: EBITDA | C24: =C16-C22 -> 2202.01 | D24: =D16-D22 -> 2883.07 | E24: =E16-E22 -> 3063.27 | F24: =F16-F22 -> 3517.93 | G24: =G16-G22 -> 4154.74 | H24: =H16-H22 -> 4612.128 | I24: =I16-I22 -> 5119.8691 | J24: =J16-J22 -> 5683.5065 | K24: =K16-K22 -> 6309.1938
B25: EBITDA Margin % Sales | C25: =C24/C4 -> 0.18979523 | D25: =D24/D4 -> 0.23203092 | E25: =E24/E4 -> 0.22224729 | F25: =F24/F4 -> 0.23135372 | G25: =G24/G4 -> 0.23581957 | H25: =H24/H4 -> 0.23581957 | I25: =I24/I4 -> 0.23581957 | J25: =J24/J4 -> 0.23581957 | K25: =K24/K4 -> 0.23581957
B26: D&A | C26: ='Data Sheet'!F26 -> 254.74 | D26: ='Data Sheet'!G26 -> 278.01 | E26: ='Data Sheet'!H26 -> 304.08 | F26: ='Data Sheet'!I26 -> 377.15 | G26: ='Data Sheet'!J26 -> 600.74 | H26: =H4*H27 -> 666.87441 | I26: =I4*I27 -> 740.28945 | J26: =J4*J27 -> 821.78661 | K26: =K4*K27 -> 912.25566
B27: D&A as % Sales | C27: =C26/C4 -> 0.021956502 | D27: =D26/D4 -> 0.022374384 | E27: =E26/E4 -> 0.022061704 | F27: =F26/F4 -> 0.024802954 | G27: =G26/G4 -> 0.034097501 | H27: =G27 -> 0.034097501 | I27: =H27 -> 0.034097501 | J27: =I27 -> 0.034097501 | K27: =J27 -> 0.034097501
A28: x | B28: EBIT | C28: =C24-C26 -> 1947.27 | D28: =D24-D26 -> 2605.06 | E28: =E24-E26 -> 2759.19 | F28: =F24-F26 -> 3140.78 | G28: =G24-G26 -> 3554 | H28: =H4*H29 -> 3945.2536 | I28: =I4*I29 -> 4379.5797 | J28: =J4*J29 -> 4861.7199 | K28: =K4*K29 -> 5396.9381
B29: EBIT Margin % Sales | C29: =C28/C4 -> 0.16783873 | D29: =D28/D4 -> 0.20965653 | E29: =E28/E4 -> 0.20018559 | F29: =F28/F4 -> 0.20655077 | G29: =G28/G4 -> 0.20172207 | H29: =G29 -> 0.20172207 | I29: =H29 -> 0.20172207 | J29: =I29 -> 0.20172207 | K29: =J29 -> 0.20172207
B30: Interest | C30: ='Data Sheet'!F27 -> 68.69 | D30: ='Data Sheet'!G27 -> 72.78 | E30: ='Data Sheet'!H27 -> 87.16 | F30: ='Data Sheet'!I27 -> 129.81 | G30: ='Data Sheet'!J27 -> 290.2 | H30: =H4*H31 -> 322.14761 | I30: =I4*I31 -> 357.61227 | J30: =J4*J31 -> 396.98118 | K30: =K4*K31 -> 440.68414
B31: Interest % Sales | C31: =C30/C4 -> 0.0059205156 | D31: =D30/D4 -> 0.0058573708 | E31: =E30/E4 -> 0.0063236587 | F31: =F30/F4 -> 0.008536846 | G31: =G30/G4 -> 0.01647151 | H31: =G31 -> 0.01647151 | I31: =H31 -> 0.01647151 | J31: =I31 -> 0.01647151 | K31: =J31 -> 0.01647151
B32: EBT | C32: =C28-C30 -> 1878.58 | D32: =D28-D30 -> 2532.28 | E32: =E28-E30 -> 2672.03 | F32: =F28-F30 -> 3010.97 | G32: =G28-G30 -> 3263.8 | H32: =H4*H33 -> 3623.106 | I32: =I4*I33 -> 4021.9674 | J32: =J4*J33 -> 4464.7387 | K32: =K4*K33 -> 4956.254
B33: EBT % Sales | C33: =C32/C4 -> 0.16191822 | D33: =D32/D4 -> 0.20379916 | E33: =E32/E4 -> 0.19386193 | F33: =F32/F4 -> 0.19801392 | G33: =G32/G4 -> 0.18525056 | H33: =G33 -> 0.18525056 | I33: =H33 -> 0.18525056 | J33: =I33 -> 0.18525056 | K33: =J33 -> 0.18525056
B34: Tax | C34: ='Data Sheet'!F29 -> 317.27 | D34: ='Data Sheet'!G29 -> 377.04 | E34: ='Data Sheet'!H29 -> 447.04 | F34: ='Data Sheet'!I29 -> 394.73 | G34: ='Data Sheet'!J29 -> 396.24 | H34: =H32*H35 -> 439.86137 | I34: =I32*I35 -> 488.28493 | J34: =J32*J35 -> 542.03936 | K34: =K32*K35 -> 601.71153
B35: Tax % EBT | C35: =C34/C32 -> 0.1688882 | D35: =D34/D32 -> 0.14889349 | E35: =E34/E32 -> 0.16730351 | F35: =F34/F32 -> 0.13109729 | G35: =G34/G32 -> 0.1214045 | H35: =G35 -> 0.1214045 | I35: =H35 -> 0.1214045 | J35: =I35 -> 0.1214045 | K35: =J35 -> 0.1214045
A36: x | B36: Net Income | C36: =C32-C34 -> 1561.31 | D36: =D32-D34 -> 2155.24 | E36: =E32-E34 -> 2224.99 | F36: =F32-F34 -> 2616.24 | G36: =G32-G34 -> 2867.56 | H36: =G36*(1+H37) -> 3334.285 | I36: =H36*(1+I37) -> 3876.9742 | J36: =I36*(1+J37) -> 4507.9918 | K36: =J36*(1+K37) -> 5241.7139
B37: Net Income % Sales | C37: =C36/C4 -> 0.13457214 | D37: =D36/D4 -> 0.17345479 | E37: =E36/E4 -> 0.16142815 | F37: =F36/F4 -> 0.17205483 | G37: =G36/G4 -> 0.16276031 | H37: =G37 -> 0.16276031 | I37: =H37 -> 0.16276031 | J37: =I37 -> 0.16276031 | K37: =J37 -> 0.16276031

Sheet Balance Sheet
B2: Tata Consumers
B3: Balance Sheet (₹ Cr) | C3: 2021 | D3: =C3+1 -> 2022 | E3: =D3+1 -> 2023 | F3: =E3+1 -> 2024 | G3: =F3+1 -> 2025 | H3: =G3+1 -> 2026 | I3: =H3+1 -> 2027 | J3: =I3+1 -> 2028 | K3: =J3+1 -> 2029
B4: Equity Share Capital | C4: ='Data Sheet'!F57 -> 92.16 | D4: ='Data Sheet'!G57 -> 92.16 | E4: ='Data Sheet'!H57 -> 92.9 | F4: ='Data Sheet'!I57 -> 95.28 | G4: ='Data Sheet'!J57 -> 98.95 | H4: =G4 -> 98.95 | I4: =H4 -> 98.95 | J4: =I4 -> 98.95 | K4: =J4 -> 98.95
B5: Reserves | C5: ='Data Sheet'!F58 -> 14442.35 | D5: ='Data Sheet'!G58 -> 15049.78 | E5: ='Data Sheet'!H58 -> 16183.81 | F5: ='Data Sheet'!I58 -> 15961.51 | G5: ='Data Sheet'!J58 -> 19902.13 | H5: =G5 -> 19902.13 | I5: =H5 -> 19902.13 | J5: =I5 -> 19902.13 | K5: =J5 -> 19902.13
B6: Borrowings | C6: ='Data Sheet'!F59 -> 1633.55 | D6: ='Data Sheet'!G59 -> 1412.01 | E6: ='Data Sheet'!H59 -> 1600.04 | F6: ='Data Sheet'!I59 -> 3477.22 | G6: ='Data Sheet'!J59 -> 2392.68 | H6: =G6 -> 2392.68 | I6: =H6 -> 2392.68 | J6: =I6 -> 2392.68 | K6: =J6 -> 2392.68
B7: Other Liabilities | C7: ='Data Sheet'!F60 -> 4049.76 | D7: ='Data Sheet'!G60 -> 4520.92 | E7: ='Data Sheet'!H60 -> 4885.74 | F7: ='Data Sheet'!I60 -> 8344.78 | G7: ='Data Sheet'!J60 -> 9436.86 | H7: =G7 -> 9436.86 | I7: =H7 -> 9436.86 | J7: =I7 -> 9436.86 | K7: =J7 -> 9436.86
B8: Total Liabilities | C8: =SUM(C4:C7) -> 20217.82 | D8: 10460.76 | E8: 10880.68 | F8: 18473.04 | G8: 20217.82 | H8: =SUM(H4:H7) -> 31830.62 | I8: =SUM(I4:I7) -> 31830.62 | J8: =SUM(J4:J7) -> 31830.62 | K8: =SUM(K4:K7) -> 31830.62
B10: Fixed Assets Net Block | C10: ='Data Sheet'!F62 -> 12023.13 | D10: ='Data Sheet'!G62 -> 12599.35 | E10: ='Data Sheet'!H62 -> 13070.04 | F10: ='Data Sheet'!I62 -> 19357.9 | G10: ='Data Sheet'!J62 -> 21476.84 | H10: =G10 -> 21476.84 | I10: =H10 -> 21476.84 | J10: =I10 -> 21476.84 | K10: =J10 -> 21476.84
B11: Capital Work in Progress | C11: ='Data Sheet'!F63 -> 112.85 | D11: ='Data Sheet'!G63 -> 246.97 | E11: ='Data Sheet'!H63 -> 294.9 | F11: ='Data Sheet'!I63 -> 189.6 | G11: ='Data Sheet'!J63 -> 218.1 | H11: =G11 -> 218.1 | I11: =H11 -> 218.1 | J11: =I11 -> 218.1 | K11: =J11 -> 218.1
B12: Investments | C12: ='Data Sheet'!F64 -> 805.89 | D12: ='Data Sheet'!G64 -> 797.28 | E12: ='Data Sheet'!H64 -> 1432.97 | F12: ='Data Sheet'!I64 -> 870.55 | G12: ='Data Sheet'!J64 -> 968.67 | H12: =G12 -> 968.67 | I12: =H12 -> 968.67 | J12: =I12 -> 968.67 | K12: =J12 -> 968.67
B13: Other Assets | C13: ='Data Sheet'!F65-SUM(C16:C18) -> 1190.59 | D13: ='Data Sheet'!G65-SUM(D16:D18) -> 1729.72 | E13: ='Data Sheet'!H65-SUM(E16:E18) -> 1667.64 | F13: ='Data Sheet'!I65-SUM(F16:F18) -> 1340.15 | G13: ='Data Sheet'!J65-SUM(G16:G18) -> 1879.45 | H13: =G13 -> 1879.45 | I13: =H13 -> 1879.45 | J13: =I13 -> 1879.45 | K13: =J13 -> 1879.45
B14: Total Non Current Assets | C14: =SUM(C10:C13) -> 14132.46 | D14: ='Data Sheet'!G66 -> 21074.87 | E14: ='Data Sheet'!H66 -> 22762.49 | F14: ='Data Sheet'!I66 -> 27878.79 | G14: ='Data Sheet'!J66 -> 31830.62 | H14: =SUM(H10:H13) -> 24543.06 | I14: =SUM(I10:I13) -> 24543.06 | J14: =SUM(J10:J13) -> 24543.06 | K14: =SUM(K10:K13) -> 24543.06
B16: Receivables | C16: ='Data Sheet'!F67 -> 761.32 | D16: ='Data Sheet'!G67 -> 835.15 | E16: ='Data Sheet'!H67 -> 798.33 | F16: ='Data Sheet'!I67 -> 896.75 | G16: ='Data Sheet'!J67 -> 869.79 | H16: =G16 -> 869.79 | I16: =H16 -> 869.79 | J16: =I16 -> 869.79 | K16: =J16 -> 869.79
B17: Inventory | C17: ='Data Sheet'!F68 -> 2249.16 | D17: ='Data Sheet'!G68 -> 2266.51 | E17: ='Data Sheet'!H68 -> 2701.67 | F17: ='Data Sheet'!I68 -> 2769.35 | G17: ='Data Sheet'!J68 -> 3599.91 | H17: =G17 -> 3599.91 | I17: =H17 -> 3599.91 | J17: =I17 -> 3599.91 | K17: =J17 -> 3599.91
B18: Cash & Bank | C18: ='Data Sheet'!F69 -> 3074.88 | D18: ='Data Sheet'!G69 -> 2599.89 | E18: ='Data Sheet'!H69 -> 2796.94 | F18: ='Data Sheet'!I69 -> 2454.49 | G18: ='Data Sheet'!J69 -> 2817.86 | H18: ='Cash Flow Statement'!H44 -> 1786.2172 | I18: ='Cash Flow Statement'!I44 -> 1423.9005 | J18: ='Cash Flow Statement'!J44 -> 953.18744 | K18: ='Cash Flow Statement'!K44 -> 350.02826
B19: Total Current Assets | C19: =SUM(C16:C18) -> 6085.36 | D19: =SUM(D16:D18) -> 5701.55 | E19: =SUM(E16:E18) -> 6296.94 | F19: =SUM(F16:F18) -> 6120.59 | G19: =SUM(G16:G18) -> 7287.56 | H19: =SUM(H16:H18) -> 6255.9172 | I19: =SUM(I16:I18) -> 5893.6005 | J19: =SUM(J16:J18) -> 5422.8874 | K19: =SUM(K16:K18) -> 4819.7283
B20: Total Assets | C20: =C14+C19 -> 20217.82 | D20: =D14+D19 -> 26776.42 | E20: =E14+E19 -> 29059.43 | F20: =F14+F19 -> 33999.38 | G20: =G14+G19 -> 39118.18 | H20: =H14+H19 -> 30798.977 | I20: =I14+I19 -> 30436.66 | J20: =J14+J19 -> 29965.947 | K20: =K14+K19 -> 29362.788
C24: 631129729 | D24: 631129729 | E24: 631129729 | F24: 921551715 | G24: 921551715 | H24: 921551715 | I24: 929011650 | J24: 952834816 | K24: 989498558
B25: New Bonus Shares
B26: Face value | C26: 1 | D26: 1 | E26: 1 | F26: 1 | G26: 1 | H26: 1 | I26: 1 | J26: 1 | K26: 1

Sheet Cash Flow Statement
B2: Tata Consumers
B3: Balance Sheet (₹ Cr) | C3: 2021 | D3: =C3+1 -> 2022 | E3: =D3+1 -> 2023 | F3: =E3+1 -> 2024 | G3: =F3+1 -> 2025 | H3: =G3+1 -> 2026 | I3: =H3+1 -> 2027 | J3: =I3+1 -> 2028 | K3: =J3+1 -> 2029
B4: Operating Activity
B5: Profit from operations | C5: =Sheet2!C4 -> 1579 | D5: =Sheet2!D4 -> 1749 | E5: =Sheet2!E4 -> 1875 | F5: =Sheet2!F4 -> 2323 | G5: =Sheet2!G4 -> 2514
B6: Receivables | C6: =Sheet2!C5 -> 186 | D6: =Sheet2!D5 -> -149 | E6: =Sheet2!E5 -> -36 | F6: =Sheet2!F5 -> -45 | G6: =Sheet2!G5 -> 36
B7: Inventory | C7: =Sheet2!C6 -> -533 | D7: =Sheet2!D6 -> -1 | E7: =Sheet2!E6 -> -368 | F7: =Sheet2!F6 -> -3 | G7: =Sheet2!G6 -> -734
B8: Payables | C8: =Sheet2!C7 -> 531 | D8: 152 | E8: 379 | F8: 60 | G8: 704
B9: Other WC items | C9: =Sheet2!C8 -> 0 | D9: =Sheet2!D8 -> 0 | E9: =Sheet2!E8 -> 0 | F9: =Sheet2!F8 -> 0 | G9: =Sheet2!G8 -> 0
B10: Working capital changes | C10: =Sheet2!C9 -> 183 | D10: =Sheet2!D9 -> 2 | E10: =Sheet2!E9 -> -25 | F10: =Sheet2!F9 -> 11 | G10: =Sheet2!G9 -> 5 | H10: =G10*(1+$L$10) -> 7.0759823 | I10: =H10*(1+$L$10) -> 10.013905 | J10: =I10*(1+$L$10) -> 14.171643 | K10: =J10*(1+$L$10) -> 20.055659 | L10: =((G10/E10)^(1/3)+1) -> 0.41519645
B11: Direct taxes | C11: =Sheet2!C10 -> -106 | D11: =Sheet2!D10 -> -235 | E11: =Sheet2!E10 -> -389 | F11: =Sheet2!F10 -> -398 | G11: =Sheet2!G10 -> -462
B12: Other operating items | C12: =Sheet2!C11 -> 0 | D12: =Sheet2!D11 -> 0 | E12: =Sheet2!E11 -> 0 | F12: =Sheet2!F11 -> 0 | G12: =Sheet2!G11 -> 0
B13: Cash from Operating Activity | C13: =SUM(C5:C12) -> 1840 | D13: =SUM(D5:D12) -> 1518 | E13: =SUM(E5:E12) -> 1436 | F13: =SUM(F5:F12) -> 1948 | G13: =SUM(G5:G12) -> 2063 | H13: =G13*($L$13+1) -> 2184.789 | I13: =H13*($L$13+1) -> 2313.7678 | J13: =I13*($L$13+1) -> 2450.3609 | K13: =J13*($L$13+1) -> 2595.0177 | L13: =G13/F13-1 -> 0.059034908
B15: Investing Activity
B16: Fixed assets purchased | C16: =Sheet2!C13 -> -211 | D16: =Sheet2!D13 -> -273 | E16: =Sheet2!E13 -> -312 | F16: =Sheet2!F13 -> -335 | G16: =Sheet2!G13 -> -460
B17: Fixed assets sold | C17: =Sheet2!C14 -> 32 | D17: =Sheet2!D14 -> 27 | E17: =Sheet2!E14 -> 172 | F17: =Sheet2!F14 -> 24 | G17: =Sheet2!G14 -> 45
B18: Investments purchased | C18: =Sheet2!C15 -> 0 | D18: =Sheet2!D15 -> 0 | E18: =Sheet2!E15 -> -533 | F18: =Sheet2!F15 -> 0 | G18: =Sheet2!G15 -> -29
B19: Investments sold | C19: =Sheet2!C16 -> 523 | D19: =Sheet2!D16 -> 136 | E19: =Sheet2!E16 -> 4 | F19: =Sheet2!F16 -> 710 | G19: =Sheet2!G16 -> 0
B20: Investment income | C20: =Sheet2!C17 -> 0 | D20: =Sheet2!D17 -> 0 | E20: =Sheet2!E17 -> 0 | F20: =Sheet2!F17 -> 0 | G20: =Sheet2!G17 -> 0
B21: Interest received | C21: =Sheet2!C18 -> 68 | D21: =Sheet2!D18 -> 75 | E21: =Sheet2!E18 -> 109 | F21: =Sheet2!F18 -> 187 | G21: =Sheet2!G18 -> 111
B22: Dividends received | C22: =Sheet2!C19 -> 5 | D22: =Sheet2!D19 -> 13 | E22: =Sheet2!E19 -> 13 | F22: =Sheet2!F19 -> 4 | G22: =Sheet2!G19 -> 7
B23: Invest in subsidiaries | C23: =Sheet2!C20 -> 0 | D23: =Sheet2!D20 -> 0 | E23: =Sheet2!E20 -> 0 | F23: =Sheet2!F20 -> 0 | G23: =Sheet2!G20 -> 0
B24: Investment in group cos | C24: =Sheet2!C21 -> -112 | D24: =Sheet2!D21 -> -236 | E24: =Sheet2!E21 -> -150 | F24: =Sheet2!F21 -> -25 | G24: =Sheet2!G21 -> -125
B25: Redemp n Canc of Shares | C25: =Sheet2!C22 -> 57 | D25: =Sheet2!D22 -> 11 | E25: =Sheet2!E22 -> 9 | F25: =Sheet2!F22 -> 0 | G25: =Sheet2!G22 -> 0
B26: Acquisition of companies | C26: =Sheet2!C23 -> -169 | D26: =Sheet2!D23 -> -511 | E26: =Sheet2!E23 -> -55 | F26: =Sheet2!F23 -> -3859 | G26: =Sheet2!G23 -> -1809
B27: Inter corporate deposits | C27: =Sheet2!C24 -> -73 | D27: =Sheet2!D24 -> -499 | E27: =Sheet2!E24 -> 70 | F27: =Sheet2!F24 -> 232 | G27: =Sheet2!G24 -> -144
B28: Other investing items | C28: =Sheet2!C25 -> -467 | D28: =Sheet2!D25 -> -61 | E28: =Sheet2!E25 -> -160 | F28: =Sheet2!F25 -> 1152 | G28: =Sheet2!G25 -> 99
B29: Cash From Investing Activity | C29: =SUM(C16:C28) -> -347 | D29: =SUM(D16:D28) -> -1318 | E29: =SUM(E16:E28) -> -833 | F29: =SUM(F16:F28) -> -1910 | G29: =SUM(G16:G28) -> -2305 | H29: =G29*(1+$L$29) -> -2781.6885 | I29: =H29*(1+$L$29) -> -3356.9591 | J29: =I29*(1+$L$29) -> -4051.1994 | K29: =J29*(1+$L$29) -> -4889.0129 | L29: =G29/F29-1 -> 0.20680628
B31: Financing Activity
B32: Proceeds from shares | C32: =Sheet2!C27 -> 0 | D32: =Sheet2!D27 -> 0 | E32: =Sheet2!E27 -> 0 | F32: =Sheet2!F27 -> 0 | G32: =Sheet2!G27 -> 2981
B33: Redemption of debentures | C33: =Sheet2!C28 -> 0 | D33: =Sheet2!D28 -> 0 | E33: =Sheet2!E28 -> 0 | F33: =Sheet2!F28 -> 0 | G33: =Sheet2!G28 -> 0
B34: Proceeds from borrowings | C34: =Sheet2!C29 -> 12 | D34: =Sheet2!D29 -> 0 | E34: =Sheet2!E29 -> 53 | F34: =Sheet2!F29 -> 1327 | G34: =Sheet2!G29 -> 60
B35: Repayment of borrowings | C35: =Sheet2!C30 -> -69 | D35: =Sheet2!D30 -> -495 | E35: =Sheet2!E30 -> -56 | F35: =Sheet2!F30 -> -73 | G35: =Sheet2!G30 -> -1511
B36: Interest paid fin | C36: =Sheet2!C31 -> -65 | D36: =Sheet2!D31 -> -63 | E36: =Sheet2!E31 -> -82 | F36: =Sheet2!F31 -> -118 | G36: =Sheet2!G31 -> -261
B37: Dividends paid | C37: =Sheet2!C32 -> -267 | D37: =Sheet2!D32 -> -398 | E37: =Sheet2!E32 -> -573 | F37: =Sheet2!F32 -> -809 | G37: =Sheet2!G32 -> -741
B38: Financial liabilities | C38: =Sheet2!C33 -> -45 | D38: =Sheet2!D33 -> -53 | E38: =Sheet2!E33 -> -56 | F38: =Sheet2!F33 -> -71 | G38: =Sheet2!G33 -> -75
B39: Other financing items | C39: =Sheet2!C34 -> 9 | D39: =Sheet2!D34 -> 13 | E39: =Sheet2!E34 -> 0 | F39: =Sheet2!F34 -> 0 | G39: =Sheet2!G34 -> 0
B40: Net Cash Flow | C40: =Sheet2!C35 -> 884 | D40: =Sheet2!D35 -> -796 | E40: =Sheet2!E35 -> -87 | F40: =Sheet2!F35 -> 281 | G40: =Sheet2!G35 -> 206
B41: Free Cash Flow | C41: =Sheet2!C36 -> 1477 | D41: =Sheet2!D36 -> 1270 | E41: =Sheet2!E36 -> 1321 | F41: =Sheet2!F36 -> 1626 | G41: =Sheet2!G36 -> 1643
B42: Cash From Financing Activity | C42: =SUM(C32:C41) -> 1936 | D42: =SUM(D32:D41) -> -522 | E42: =SUM(E32:E41) -> 520 | F42: =SUM(F32:F41) -> 2163 | G42: =SUM(G32:G41) -> 2302 | H42: =G42*(1+$L$42) -> 2383.1167 | I42: =H42*(1+$L$42) -> 2467.0918 | J42: =I42*(1+$L$42) -> 2554.0259 | K42: =J42*(1+$L$42) -> 2644.0234 | L42: =((G42/C42)^(1/5)-1) -> 0.035237495
B44: Net Cash Flow | C44: =C13+C29+C42 -> 3429 | D44: =D13+D29+D42 -> -322 | E44: =E13+E29+E42 -> 1123 | F44: =F13+F29+F42 -> 2201 | G44: =G13+G29+G42 -> 2060 | H44: =H13+H29+H42 -> 1786.2172 | I44: =I13+I29+I42 -> 1423.9005 | J44: =J13+J29+J42 -> 953.18744 | K44: =K13+K29+K42 -> 350.02826

Sheet Key Metrics
B2: Key Metrics & Ratios | C2: 2024 | D2: =C2+1 -> 2025 | E2: =D2+1 -> 2026 | F2: =E2+1 -> 2027 | G2: =F2+1 -> 2028 | H2: =G2+1 -> 2029 | I2: =H2+1 -> 2030 | J2: =I2+1 -> 2031 | K2: =J2+1 -> 2032 | L2: =K2+1 -> 2033
B3: PROFITABILITY RATIOS
B4: Gross Margin % | C4: ='Income Statement'!F17 -> 0.40183285 | D4: ='Income Statement'!G17 -> 0.39479689 | E4: ='Income Statement'!H17 -> 0.39479689
B5: EBITDA Margin % | C5: ='Income Statement'!F25 -> 0.23135372 | D5: ='Income Statement'!G25 -> 0.23581957 | E5: ='Income Statement'!H25 -> 0.23581957
B6: EBIT Margin % | C6: ='Income Statement'!F29 -> 0.20655077 | D6: ='Income Statement'!G29 -> 0.20172207 | E6: ='Income Statement'!H29 -> 0.20172207
B7: Net Margin % | C7: ='Income Statement'!F37 -> 0.17205483 | D7: ='Income Statement'!G37 -> 0.16276031 | E7: ='Income Statement'!H37 -> 0.16276031
B8: ROE (Return on Equity)
B9: ROA (Return on Assets)
B11: LIQUIDITY RATIOS
B12: Current Ratio
B13: Quick Ratio
B15: LEVERAGE RATIOS
B16: Debt-to-Equity
B17: Interest Coverage
B19: GROWTH METRICS
B20: Revenue Growth %
B21: EBITDA Growth %
B22: Net Income Growth %

Sheet DCF
B2: TATA Consumers.
B3: Income Statement (₹ Cr) | C3: 2021 | D3: =C3+1 -> 2022 | E3: =D3+1 -> 2023 | F3: =E3+1 -> 2024 | G3: =F3+1 -> 2025 | H3: =G3+1 -> 2026 | I3: =H3+1 -> 2027 | J3: =I3+1 -> 2028 | K3: =J3+1 -> 2029
H4: 1 | I4: 2 | J4: 3 | K4: 4
B5: ='Income Statement'!B28 -> EBIT | C5: ='Income Statement'!C28 -> 1947.27 | D5: ='Income Statement'!D28 -> 2605.06 | E5: ='Income Statement'!E28 -> 2759.19 | F5: ='Income Statement'!F28 -> 3140.78 | G5: ='Income Statement'!G28 -> 3554 | H5: ='Income Statement'!H28 -> 3945.2536 | I5: ='Income Statement'!I28 -> 4379.5797 | ... K5: ='Income Statement'!K28 -> 5396.9381
A6: + | B6: ='Income Statement'!B26 -> D&A | C6: ='Income Statement'!C26 -> 254.74 | D6: ='Income Statement'!D26 -> 278.01 | E6: ='Income Statement'!E26 -> 304.08 | F6: ='Income Statement'!F26 -> 377.15 | G6: ='Income Statement'!G26 -> 600.74 | H6: ='Income Statement'!H26 -> 666.87441 | I6: ='Income Statement'!I26 -> 740.28945 | ... K6: ='Income Statement'!K26 -> 912.25566
A7: - | B7: ='Income Statement'!B34 -> Tax | C7: ='Income Statement'!C34 -> 317.27 | D7: ='Income Statement'!D34 -> 377.04 | E7: ='Income Statement'!E34 -> 447.04 | F7: ='Income Statement'!F34 -> 394.73 | G7: ='Income Statement'!G34 -> 396.24 | H7: ='Income Statement'!H34 -> 439.86137 | I7: ='Income Statement'!I34 -> 488.28493 | ... K7: ='Income Statement'!K34 -> 601.71153
A8: - | B8: Capex | C8: =-('Cash Flow Statement'!C16) -> 211 | D8: =-('Cash Flow Statement'!D16) -> 273 | E8: =-('Cash Flow Statement'!E16) -> 312 | F8: =-('Cash Flow Statement'!F16) -> 335 | G8: =-('Cash Flow Statement'!G16) -> 460 | H8: =G8*(1+$L$8) -> 568.56872 | I8: =H8*(1+$L$8) -> 702.76172 | J8: =I8*(1+$L$8) -> 868.6268 | K8: =J8*(1+$L$8) -> 1073.6392 | L8: =(G8/C8-1)/5 -> 0.23601896
A9: - | B9: Change in Working Capital | C9: ='Cash Flow Statement'!C10 -> 183 | D9: ='Cash Flow Statement'!D10 -> 2 | E9: ='Cash Flow Statement'!E10 -> -25 | F9: ='Cash Flow Statement'!F10 -> 11 | G9: ='Cash Flow Statement'!G10 -> 5 | H9: ='Cash Flow Statement'!H10 -> 7.0759823 | I9: ='Cash Flow Statement'!I10 -> 10.013905 | J9: ='Cash Flow Statement'!J10 -> 14.171643 | K9: ='Cash Flow Statement'!K10 -> 20.055659
B10: Unlevered Free Cash Flow | C10: =C5+C6-C7-C8-C9 -> 1490.74 | D10: =D5+D6-D7-D8-D9 -> 2231.03 | E10: =E5+E6-E7-E8-E9 -> 2329.23 | F10: =F5+F6-F7-F8-F9 -> 2777.2 | G10: =G5+G6-G7-G8-G9 -> 3293.5 | H10: =H5+H6-H7-H8-H9 -> 3596.622 | I10: =I5+I6-I7-I8-I9 -> 3918.8086 | J10: =J5+J6-J7-J8-J9 -> 4258.6687 | K10: =K5+K6-K7-K8-K9 -> 4613.7874
B11: PV of FCF | H11: =H10/(1+$D$42)^H4 -> 3279.1225 | I11: =I10/(1+$D$42)^I4 -> 3257.4649 | J11: =J10/(1+$D$42)^J4 -> 3227.4714 | K11: =K10/(1+$D$42)^K4 -> 3187.9314
B14: Terminal Growth | K14: =((K10/H10)^(1/4)-1) -> 0.064242742
B15: Terminal Value | K15: =K10*(1+K14)/(D42-K14) -> 150703.52
B16: PV of TV | K16: =K15/(1+D42)^K4 -> 104129.74
B17: EV | K17: =SUM(H10:K10,K16) -> 120517.62
A18: - | B18: Cash | K18: ='Balance Sheet'!K18 -> 350.02826
A19: + | B19: Debt | K19: ='Balance Sheet'!H6 -> 2392.68
B20: Equity Value | K20: =K17-K18+K19 -> 122560.28
B21: Shares | K21: ='Balance Sheet'!K4 -> 98.95
B22: Current share price | K22: 1236
B23: Implied Share Price | K23: =K20/K21 -> 1238.6081
B24: Implied Share Price is | K24: =K23/K22-1 -> 0.0021101448
B25: positive/(negative) than current
B27: Debt | D27: ='Balance Sheet'!K6 -> 2392.68
B28: % Debt | D28: =D27/D40 -> 0.019188278
B29: Cost of Debt | D29: 0.02
B30: Tax Rate | D30: ='Income Statement'!H35 -> 0.1214045
B32: Equity Value | D32: ='Balance Sheet'!G4*K22 -> 122302.2
B33: % Equity | D33: =D32/SUM(D27,D32) -> 0.98081172
B34: Cost of Equity | D34: =D35+D36*(D38) -> 0.098375
B35: Risk Free Rate | D35: 0.0635
B36: Beta | D36: 0.75
B37: TATA CONS. Return | D37: 0.11
B38: Market Risk Premium | D38: =D37-D35 -> 0.0465
B40: Debt + Equity | D40: =SUM(D27,D32) -> 124694.88
B42: WACC | D42: =(D34*D33)+(D29*D28)*(1-D30) -> 0.096824528

Sheet Sheet2
C2: 44256 | D2: 44621 | E2: 44986 | F2: 45352 | G2: 45717 | H2: 46082
B3: Operating Activity
B4: Profit from operations | C4: 1579 | D4: 1749 | E4: 1875 | F4: 2323 | G4: 2514 | H4: 2840
B5: Receivables | C5: 186 | D5: -149 | E5: -36 | F5: -45 | G5: 36 | H5: -291
B6: Inventory | C6: -533 | D6: -1 | E6: -368 | F6: -3 | G6: -734 | H6: 200
B7: Payables | C7: 531 | D7: 152 | E7: 379 | F7: 60 | G7: 704 | H7: 0
B8: Other WC items | C8: 0 | D8: 0 | E8: 0 | F8: 0 | G8: 0 | H8: 236
B9: Working capital changes | C9: 183 | D9: 2 | E9: -25 | F9: 11 | G9: 5 | H9: 145
B10: Direct taxes | C10: -106 | D10: -235 | E10: -389 | F10: -398 | G10: -462 | H10: -563
B11: Other operating items | C11: 0 | D11: 0 | E11: 0 | F11: 0 | G11: 0 | H11: 0
B12: Cash from Investing Activity - | C12: -346 | D12: -1317 | E12: -834 | F12: -1911 | G12: -2303 | H12: -1398
B13: Fixed assets purchased | C13: -211 | D13: -273 | E13: -312 | F13: -335 | G13: -460 | H13: -449
B14: Fixed assets sold | C14: 32 | D14: 27 | E14: 172 | F14: 24 | G14: 45 | H14: 42
B15: Investments purchased | C15: 0 | D15: 0 | E15: -533 | F15: 0 | G15: -29 | H15: -547
... B37: CFO/OP | C37: 1.14 | D37: 1.02 | E37: 1 | F37: 1.02 | G37: 1.02 | H37: 1.07
